Workbook

Sheet Read Me
A1: Mountain West Handicapping Tracker
A2: 2026 Season
A4: How this workbook is meant to be used
A5: This workbook is the review/tracking cockpit -- the model itself runs in Python (see the
A6: attack plan and the src/ scripts). Each week, paste that week's model output into the blue
A7: cells on the Weekly Slate tab; everything else on that tab recalculates automatically.
A9: Color legend
A10: Blue text = cells you fill in by hand (model output, market lines, bet results)
A11: Black text = formulas -- don't type over these, they recalculate from the blue cells
A12: Yellow fill = key assumptions on the Settings tab (edit these once, not weekly)
A14: Tabs
A15: Settings = bankroll, edge thresholds, and other assumptions used across the workbook
... A22: paper-trading and bankroll discipline before staking real money.

Sheet Settings
A1: Settings & Assumptions
A3: Assumption | B3: Value | C3: Notes
A4: Starting bankroll (units) | B4: 50 | C4: Example: 100 units. 1 unit = whatever flat stake you choose in real currency.
A5: Spread edge threshold (pts) | B5: 2 | C5: Minimum |model line - market line| before a spread is flagged as a lean.
A6: Total edge threshold (pts) | B6: 2 | C6: Minimum |model total - market total| before a total is flagged as a lean.
A7: Standard vig odds (American) | B7: -110 | C7: Reference only -- breakeven win rate at -110 is 52.4%.

Sheet Weekly Slate
A1: Week | B1: Date | C1: Away Team | D1: Home Team | E1: Model Line (Home) | F1: Market Line (Home) | G1: Spread Edge (pts) | H1: Spread Lean | I1: Model Total | J1: Market Total | K1: Total Edge (pts) | L1: Total Lean | M1: Suggested Bet (Spread) | N1: Suggested Bet (Total) | O1: Qualitative Notes | P1: Final Decision | R1: MW WEST Teams
A2: 2 | B2: 2026-09-12 | C2: UNLV | D2: North Texas | E2: -3.9 | F2: 3.5 | G2: =F2-E2 -> 7.4 | H2: =IF(G2=0,"Pick'em",IF(G2>0,"Home","Away")) -> Home | I2: 58.2 | J2: 56.8 | K2: =I2-J2 -> 1.4 | L2: =IF(K2=0,"Push",IF(K2>0,"Over","Under")) -> Over | M2: =IF(ABS(G2)>=Settings!$B$5,H2,IF(F2=0,"Pick'em",IF(F2<0,"Home (auto)","Away (auto)"))) -> Home | N2: =IF(ABS(K2)>=Settings!$B$6,L2,IF(K2=0,"Push",L2&" (auto)")) -> Over (auto)
A3: 2 | B3: 2026-09-12 | C3: Northern Colorado | D3: Wyoming | E3: -17.1 | G3: =F3-E3 -> 17.1 | H3: =IF(G3=0,"Pick'em",IF(G3>0,"Home","Away")) -> Home | I3: 55.2 | K3: =I3-J3 -> 55.2 | L3: =IF(K3=0,"Push",IF(K3>0,"Over","Under")) -> Over | M3: =IF(ABS(G3)>=Settings!$B$5,H3,IF(F3=0,"Pick'em",IF(F3<0,"Home (auto)","Away (auto)"))) -> Home | N3: =IF(ABS(K3)>=Settings!$B$6,L3,IF(K3=0,"Push",L3&" (auto)")) -> Over
A4: 2 | B4: 2026-09-12 | C4: Mercyhurst | D4: New Mexico | E4: -17.1 | G4: =F4-E4 -> 17.1 | H4: =IF(G4=0,"Pick'em",IF(G4>0,"Home","Away")) -> Home | I4: 54.1 | K4: =I4-J4 -> 54.1 | L4: =IF(K4=0,"Push",IF(K4>0,"Over","Under")) -> Over | M4: =IF(ABS(G4)>=Settings!$B$5,H4,IF(F4=0,"Pick'em",IF(F4<0,"Home (auto)","Away (auto)"))) -> Home | N4: =IF(ABS(K4)>=Settings!$B$6,L4,IF(K4=0,"Push",L4&" (auto)")) -> Over
A5: 2 | B5: 2026-09-12 | C5: Illinois State | D5: Northern Illinois | E5: -16 | G5: =F5-E5 -> 16 | H5: =IF(G5=0,"Pick'em",IF(G5>0,"Home","Away")) -> Home | I5: 54.9 | K5: =I5-J5 -> 54.9 | L5: =IF(K5=0,"Push",IF(K5>0,"Over","Under")) -> Over | M5: =IF(ABS(G5)>=Settings!$B$5,H5,IF(F5=0,"Pick'em",IF(F5<0,"Home (auto)","Away (auto)"))) -> Home | N5: =IF(ABS(K5)>=Settings!$B$6,L5,IF(K5=0,"Push",L5&" (auto)")) -> Over | R5: Air Force
A6: 2 | B6: 2026-09-13 | C6: Texas Southern | D6: UTEP | E6: -16.1 | G6: =F6-E6 -> 16.1 | H6: =IF(G6=0,"Pick'em",IF(G6>0,"Home","Away")) -> Home | I6: 55.2 | K6: =I6-J6 -> 55.2 | L6: =IF(K6=0,"Push",IF(K6>0,"Over","Under")) -> Over | M6: =IF(ABS(G6)>=Settings!$B$5,H6,IF(F6=0,"Pick'em",IF(F6<0,"Home (auto)","Away (auto)"))) -> Home | N6: =IF(ABS(K6)>=Settings!$B$6,L6,IF(K6=0,"Push",L6&" (auto)")) -> Over | R6: Hawai'i
A7: 2 | B7: 2026-09-13 | C7: Cal Poly | D7: San José State | E7: -21 | G7: =F7-E7 -> 21 | H7: =IF(G7=0,"Pick'em",IF(G7>0,"Home","Away")) -> Home | I7: 55.2 | K7: =I7-J7 -> 55.2 | L7: =IF(K7=0,"Push",IF(K7>0,"Over","Under")) -> Over | M7: =IF(ABS(G7)>=Settings!$B$5,H7,IF(F7=0,"Pick'em",IF(F7<0,"Home (auto)","Away (auto)"))) -> Home | N7: =IF(ABS(K7)>=Settings!$B$6,L7,IF(K7=0,"Push",L7&" (auto)")) -> Over | R7: Nevada
A8: 2 | B8: 2026-09-13 | C8: North Dakota State | D8: Air Force | E8: 16.9 | F8: 2.5 | G8: =F8-E8 -> -14.4 | H8: =IF(G8=0,"Pick'em",IF(G8>0,"Home","Away")) -> Away | I8: 53.3 | J8: 47.5 | K8: =I8-J8 -> 5.8 | L8: =IF(K8=0,"Push",IF(K8>0,"Over","Under")) -> Over | M8: =IF(ABS(G8)>=Settings!$B$5,H8,IF(F8=0,"Pick'em",IF(F8<0,"Home (auto)","Away (auto)"))) -> Away | N8: =IF(ABS(K8)>=Settings!$B$6,L8,IF(K8=0,"Push",L8&" (auto)")) -> Over | R8: New Mexico
A9: 2 | B9: 2026-09-13 | C9: Montana State | D9: Nevada | E9: -17.2 | G9: =F9-E9 -> 17.2 | H9: =IF(G9=0,"Pick'em",IF(G9>0,"Home","Away")) -> Home | I9: 55.3 | K9: =I9-J9 -> 55.3 | L9: =IF(K9=0,"Push",IF(K9>0,"Over","Under")) -> Over | M9: =IF(ABS(G9)>=Settings!$B$5,H9,IF(F9=0,"Pick'em",IF(F9<0,"Home (auto)","Away (auto)"))) -> Home | N9: =IF(ABS(K9)>=Settings!$B$6,L9,IF(K9=0,"Push",L9&" (auto)")) -> Over | R9: North Dakota State
A10: 2 | B10: 2026-09-13 | C10: New Mexico State | D10: Hawai'i | E10: -14.2 | F10: -8.5 | G10: =F10-E10 -> 5.7 | H10: =IF(G10=0,"Pick'em",IF(G10>0,"Home","Away")) -> Home | I10: 55.6 | J10: 50.5 | K10: =I10-J10 -> 5.1 | L10: =IF(K10=0,"Push",IF(K10>0,"Over","Under")) -> Over | M10: =IF(ABS(G10)>=Settings!$B$5,H10,IF(F10=0,"Pick'em",IF(F10<0,"Home (auto)","Away (auto)"))) -> Home | N10: =IF(ABS(K10)>=Settings!$B$6,L10,IF(K10=0,"Push",L10&" (auto)")) -> Over | R10: Northern Illinois
G11: =F11-E11 -> 0 | H11: =IF(G11=0,"Pick'em",IF(G11>0,"Home","Away")) -> Pick'em | K11: =I11-J11 -> 0 | L11: =IF(K11=0,"Push",IF(K11>0,"Over","Under")) -> Push | M11: =IF(ABS(G11)>=Settings!$B$5,H11,IF(F11=0,"Pick'em",IF(F11<0,"Home (auto)","Away (auto)"))) -> Pick'em | N11: =IF(ABS(K11)>=Settings!$B$6,L11,IF(K11=0,"Push",L11&" (auto)")) -> Push | R11: San José State
G12: =F12-E12 -> 0 | H12: =IF(G12=0,"Pick'em",IF(G12>0,"Home","Away")) -> Pick'em | K12: =I12-J12 -> 0 | L12: =IF(K12=0,"Push",IF(K12>0,"Over","Under")) -> Push | M12: =IF(ABS(G12)>=Settings!$B$5,H12,IF(F12=0,"Pick'em",IF(F12<0,"Home (auto)","Away (auto)"))) -> Pick'em | N12: =IF(ABS(K12)>=Settings!$B$6,L12,IF(K12=0,"Push",L12&" (auto)")) -> Push | R12: UNLV
G13: =F13-E13 -> 0 | H13: =IF(G13=0,"Pick'em",IF(G13>0,"Home","Away")) -> Pick'em | K13: =I13-J13 -> 0 | L13: =IF(K13=0,"Push",IF(K13>0,"Over","Under")) -> Push | M13: =IF(ABS(G13)>=Settings!$B$5,H13,IF(F13=0,"Pick'em",IF(F13<0,"Home (auto)","Away (auto)"))) -> Pick'em | N13: =IF(ABS(K13)>=Settings!$B$6,L13,IF(K13=0,"Push",L13&" (auto)")) -> Push
G14: =F14-E14 -> 0 | H14: =IF(G14=0,"Pick'em",IF(G14>0,"Home","Away")) -> Pick'em | K14: =I14-J14 -> 0 | L14: =IF(K14=0,"Push",IF(K14>0,"Over","Under")) -> Push | M14: =IF(ABS(G14)>=Settings!$B$5,H14,IF(F14=0,"Pick'em",IF(F14<0,"Home (auto)","Away (auto)"))) -> Pick'em | N14: =IF(ABS(K14)>=Settings!$B$6,L14,IF(K14=0,"Push",L14&" (auto)")) -> Push

Sheet Bet Log
A1: Date | B1: Week | C1: Matchup | D1: Bet Type | E1: Side | F1: Line Taken | G1: Odds (American) | H1: Stake (units) | I1: Closing Line | J1: CLV (pts) | K1: Result | L1: Units Won/Lost | M1: Running Bankroll
A2: 2026-08-29 | B2: 1 | C2: Jacksonville State @ North Dakota State | D2: Spread | E2: North Dakota State | F2: -7.5 | G2: 100 | H2: 1 | I2: -7 | J2: =IF(I2="","",I2-F2) -> 0.5 | K2: W | L2: =IF(K2="W",IF(G2<0,H2*100/ABS(G2),H2*G2/100),IF(K2="L",-H2,0)) -> 1 | M2: =Settings!$B$4+SUM(L$2:L2) -> 51
A3: 2026-08-29 | B3: 1 | C3: Jacksonville State @ North Dakota State | D3: Moneyline | E3: North Dakota State | G3: -285 | H3: 5 | J3: =IF(I3="","",I3-F3) | K3: W | L3: =IF(K3="W",IF(G3<0,H3*100/ABS(G3),H3*G3/100),IF(K3="L",-H3,0)) -> 1.754386 | M3: =Settings!$B$4+SUM(L$2:L3) -> 52.754386
A4: 2026-08-29 | B4: 1 | C4: Memphis @ UNLV | D4: Moneyline | E4: UNLV | G4: -178 | H4: 5 | J4: =IF(I4="","",I4-F5) | K4: L | L4: =IF(K4="W",IF(G4<0,H4*100/ABS(G4),H4*G4/100),IF(K4="L",-H4,0)) -> -5 | M4: =Settings!$B$4+SUM(L$2:L4) -> 47.754386
A5: 2026-08-29 | B5: 1 | C5: Jacksonville State @ North Dakota State,Memphis @ UNLV | D5: ML Parlay | E5: North Dakota State / UNLV | G5: 110 | H5: 3 | J5: =IF(I5="","",I5-#REF!) | K5: L | L5: =IF(K5="W",IF(G5<0,H5*100/ABS(G5),H5*G5/100),IF(K5="L",-H5,0)) -> -3 | M5: =Settings!$B$4+SUM(L$2:L5) -> 44.754386
A6: 2026-09-04 | B6: 1 | C6: San José State @ Eastern Michigan | D6: Spread | E6: Eastern Michigan | F6: -3.5 | G6: -110 | H6: 2 | J6: =IF(I6="","",I6-F6) | K6: L | L6: =IF(K6="W",IF(G6<0,H6*100/ABS(G6),H6*G6/100),IF(K6="L",-H6,0)) -> -2 | M6: =Settings!$B$4+SUM(L$2:L6) -> 42.754386
A7: 2026-09-05 | B7: 1 | C7: San José State @ Eastern Michigan, Wyoming at Colorado State | D7: ML Parlay | E7: Eastern Michigan, Colorado State | G7: 149 | H7: 2 | J7: =IF(I7="","",I7-F7) | K7: L | L7: =IF(K7="W",IF(G7<0,H7*100/ABS(G7),H7*G7/100),IF(K7="L",-H7,0)) -> -2 | M7: =Settings!$B$4+SUM(L$2:L7) -> 40.754386
A8: 2026-09-05 | B8: 1 | C8: Wyoming @ Colorado State | D8: Spread | E8: Colorado State | F8: -2.5 | G8: -110 | H8: 2 | I8: -3 | J8: =IF(I8="","",I8-F8) -> -0.5 | K8: W | L8: =IF(K8="W",IF(G8<0,H8*100/ABS(G8),H8*G8/100),IF(K8="L",-H8,0)) -> 1.8181818 | M8: =Settings!$B$4+SUM(L$2:L8) -> 42.572568
A9: 2026-09-05 | B9: 1 | C9: Wyoming @ Colorado State | D9: Moneyline | E9: Colorado State | G9: -145 | H9: 2 | J9: =IF(I9="","",I9-F9) | K9: W | L9: =IF(K9="W",IF(G9<0,H9*100/ABS(G9),H9*G9/100),IF(K9="L",-H9,0)) -> 1.3793103 | M9: =Settings!$B$4+SUM(L$2:L9) -> 43.951878
A10: 2026-09-05 | B10: 1 | C10: Central Michigan @ New Mexico | D10: Spread | E10: New Mexico | F10: -12.5 | G10: -110 | H10: 5 | I10: -10 | J10: =IF(I10="","",I10-F10) -> 2.5 | K10: W | L10: =IF(K10="W",IF(G10<0,H10*100/ABS(G10),H10*G10/100),IF(K10="L",-H10,0)) -> 4.5454545 | M10: =Settings!$B$4+SUM(L$2:L10) -> 48.497333
A11: 2026-09-07 | B11: 1 | C11: SMU @ Florida State | D11: Spread | E11: SMU | F11: -2.5 | G11: -122 | H11: 2 | K11: W | L11: =IF(K11="W",IF(G11<0,H11*100/ABS(G11),H11*G11/100),IF(K11="L",-H11,0)) -> 1.6393443 | M11: =Settings!$B$4+SUM(L$2:L11) -> 50.136677
A12: 2026-09-07 | B12: 1 | C12: SMU @ Florida State | D12: Spread | E12: Florida State | F12: 10.5 | G12: -118 | H12: 3 | K12: W | L12: =IF(K12="W",IF(G12<0,H12*100/ABS(G12),H12*G12/100),IF(K12="L",-H12,0)) -> 2.5423729 | M12: =Settings!$B$4+SUM(L$2:L12) -> 52.67905
A13: 2026-09-07 | B13: 1 | C13: SMU @ Florida State | D13: Moneyline | E13: Florida State | G13: 265 | H13: 1 | K13: L | L13: =IF(K13="W",IF(G13<0,H13*100/ABS(G13),H13*G13/100),IF(K13="L",-H13,0)) -> -1 | M13: =Settings!$B$4+SUM(L$2:L13) -> 51.67905
A14: 2026-09-06 | B14: 1 | C14: Louisville @ Ole Miss | D14: Spread | E14: Louisville | F14: 6.5 | G14: -108 | H14: 3 | K14: W | L14: =IF(K14="W",IF(G14<0,H14*100/ABS(G14),H14*G14/100),IF(K14="L",-H14,0)) -> 2.7777778 | M14: =Settings!$B$4+SUM(L$2:L14) -> 54.456828
A15: 2026-09-06 | B15: 1 | C15: Louisville @ Ole Miss | D15: Spread | E15: Louisville | F15: 7.5 | G15: 114 | H15: 3 | K15: W | L15: =IF(K15="W",IF(G15<0,H15*100/ABS(G15),H15*G15/100),IF(K15="L",-H15,0)) -> 3.42 | M15: =Settings!$B$4+SUM(L$2:L15) -> 57.876828
A16: 2026-09-06 | B16: 1 | C16: Wisconsin @ Notre Dame | D16: Spread | E16: Wisconsin | F16: 14.5 | G16: -132 | H16: 3 | J16: =IF(I16="","",I16-F16) | K16: L | L16: =IF(K16="W",IF(G16<0,H16*100/ABS(G16),H16*G16/100),IF(K16="L",-H16,0)) -> -3 | M16: =Settings!$B$4+SUM(L$2:L16) -> 54.876828
A17: 2026-09-05 | B17: 1 | C17: Clemson @ LSU | D17: Spread | E17: Clemson | F17: 28.5 | G17: -138 | H17: 7.5 | J17: =IF(I17="","",I17-F17) | K17: L | L17: =IF(K17="W",IF(G17<0,H17*100/ABS(G17),H17*G17/100),IF(K17="L",-H17,0)) -> -7.5 | M17: =Settings!$B$4+SUM(L$2:L17) -> 47.376828
A18: 2026-09-05 | B18: 1 | C18: Clemson @ LSU | D18: Spread | E18: Clemson | F18: 10.5 | G18: -118 | H18: 2.5 | J18: =IF(I18="","",I18-F29) | K18: L | L18: =IF(K18="W",IF(G29<0,H29*100/ABS(G29),H29*G29/100),IF(K18="L",-H29,0)) -> -1 | M18: =Settings!$B$4+SUM(L$2:L18) -> 46.376828
A19: 2026-09-05 | B19: 1 | C19: Western Michigan @ Michigan | D19: Moneyline | E19: Michigan | G19: 146 | H19: 11.5 | J19: =IF(I19="","",I19-F30) | K19: W | L19: =IF(K19="W",IF(G30<0,H30*100/ABS(G30),H30*G30/100),IF(K19="L",-H30,0)) -> 2.2321429 | M19: =Settings!$B$4+SUM(L$2:L19) -> 48.60897
A20: 2026-09-05 | B20: 1 | C20: Boise State @ Oregon | D20: Spread | E20: Boise State | F20: 6.5 | G20: 108 | H20: 3 | J20: =IF(I20="","",I20-F31) | K20: L | L20: =IF(K20="W",IF(G31<0,H31*100/ABS(G31),H31*G31/100),IF(K20="L",-H31,0)) -> -2.5 | M20: =Settings!$B$4+SUM(L$2:L20) -> 46.10897
A21: 2026-09-05 | B21: 1 | C21: Tarleton State @ Bowling Green | D21: Moneyline | E21: Bowling Green | G21: 200 | H21: 3 | J21: =IF(I21="","",I21-F32) | K21: L | L21: =IF(K21="W",IF(G32<0,H32*100/ABS(G32),H32*G32/100),IF(K21="L",-H32,0)) -> -1 | M21: =Settings!$B$4+SUM(L$2:L21) -> 45.10897
A22: 2026-09-04 | B22: 1 | C22: Miami @ Stanford | D22: Spread | E22: Miami | F22: -36.5 | G22: 100 | H22: 2.5 | J22: =IF(I22="","",I22-F33) | K22: W | L22: =IF(K22="W",IF(G33<0,H33*100/ABS(G33),H33*G33/100),IF(K22="L",-H33,0)) -> 0.90909091 | M22: =Settings!$B$4+SUM(L$2:L22) -> 46.018061
A23: 2026-09-04 | B23: 1 | C23: Fresno State @ USC | D23: Total | F23: 39.5 | G23: -102 | H23: 5 | J23: =IF(I23="","",I23-F23) | K23: L | L23: =IF(K23="W",IF(G23<0,H23*100/ABS(G23),H23*G23/100),IF(K23="L",-H23,0)) -> -5 | M23: =Settings!$B$4+SUM(L$2:L23) -> 41.018061
A24: 2026-09-04 | B24: 1 | C24: Toledo @ MSU | D24: Spread | E24: Michigan | F24: -12.5 | G24: -114 | H24: 3.5 | J24: =IF(I24="","",I24-F24) | K24: L | L24: =IF(K24="W",IF(G24<0,H24*100/ABS(G24),H24*G24/100),IF(K24="L",-H24,0)) -> -3.5 | M24: =Settings!$B$4+SUM(L$2:L24) -> 37.518061
A25: 2026-09-04 | B25: 1 | C25: UTEP @ Oklahoma | D25: Total | F25: 51.5 | G25: -128 | H25: 2.5 | J25: =IF(I25="","",I25-F25) | K25: L | L25: =IF(K25="W",IF(G25<0,H25*100/ABS(G25),H25*G25/100),IF(K25="L",-H25,0)) -> -2.5 | M25: =Settings!$B$4+SUM(L$2:L25) -> 35.018061
A26: 2026-09-04 | B26: 1 | C26: San Jose State @ Eastern Michigan | D26: Moneyline | E26: Eastern Michigan | G26: -146 | H26: 2 | J26: =IF(I26="","",I26-F26) | K26: L | L26: =IF(K26="W",IF(G26<0,H26*100/ABS(G26),H26*G26/100),IF(K26="L",-H26,0)) -> -2 | M26: =Settings!$B$4+SUM(L$2:L26) -> 33.018061
A27: 2026-09-04 | B27: 1 | C27: UAB @ Illinois | D27: Spread | E27: UAB | F27: 17.5 | G27: -106 | H27: 2.75 | J27: =IF(I27="","",I27-F27) | K27: L | L27: =IF(K27="W",IF(G27<0,H27*100/ABS(G27),H27*G27/100),IF(K27="L",-H27,0)) -> -2.75 | M27: =Settings!$B$4+SUM(L$2:L27) -> 30.268061
A28: 2026-09-04 | B28: 1 | C28: UAB @ Illinois | D28: Spread | E28: UAB | F28: 25.5 | G28: 320 | H28: 2 | J28: =IF(I28="","",I28-#REF!) | K28: W | L28: =IF(K28="W",IF(G28<0,H28*100/ABS(G28),H28*G28/100),IF(K28="L",-H28,0)) -> 6.4 | M28: =Settings!$B$4+SUM(L$2:L28) -> 36.668061
A29: 2026-09-12 | B29: 2 | C29: UNLV @ North Texas | D29: Spread | E29: North Texas | F29: 3.5 | G29: -114 | H29: 1 | J29: =IF(I29="","",I29-#REF!) | K29: W | L29: =IF(K29="W",IF(G29<0,H29*100/ABS(G29),H29*G29/100),IF(K29="L",-H29,0)) -> 0.87719298 | M29: =Settings!$B$4+SUM(L$2:L29) -> 37.545254
A30: 2026-09-12 | B30: 2 | C30: North Dakota State @ Airforce | D30: Spread | E30: North Dakota State | F30: -2.5 | G30: -112 | H30: 2.5 | J30: =IF(I30="","",I30-#REF!) | K30: W | L30: =IF(K30="W",IF(G30<0,H30*100/ABS(G30),H30*G30/100),IF(K30="L",-H30,0)) -> 2.2321429 | M30: =Settings!$B$4+SUM(L$2:L30) -> 39.777397
A31: 2026-09-12 | B31: 2 | C31: North Dakota State @ Airforce | D31: Moneyline | E31: North Dakota State | G31: -134 | H31: 2.5 | J31: =IF(I31="","",I31-#REF!) | K31: W | L31: =IF(K31="W",IF(G31<0,H31*100/ABS(G31),H31*G31/100),IF(K31="L",-H31,0)) -> 1.8656716 | M31: =Settings!$B$4+SUM(L$2:L31) -> 41.643069
A32: 2026-09-12 | B32: 2 | C32: New Mexico State @ Hawaii | D32: Moneyline | E32: Hawaii | G32: -330 | H32: 1 | J32: =IF(I32="","",I32-#REF!) | K32: W | L32: =IF(K32="W",IF(G32<0,H32*100/ABS(G32),H32*G32/100),IF(K32="L",-H32,0)) -> 0.3030303 | M32: =Settings!$B$4+SUM(L$2:L32) -> 41.946099
A33: 2026-09-12 | B33: 2 | C33: Maryland @ Uconn | D33: Spread | E33: Uconn | F33: -12.5 | G33: -110 | H33: 1 | K33: L | L33: =IF(K33="W",IF(G33<0,H33*100/ABS(G33),H33*G33/100),IF(K33="L",-H33,0)) -> -1 | M33: =Settings!$B$4+SUM(L$2:L33) -> 40.946099
A34: 2026-09-12 | B34: 2 | C34: Ohio State @ Texas | D34: Moneyline | E34: Texas | G34: 500 | H34: 40 | J34: =IF(I34="","",I34-F34) | K34: W | L34: =IF(K34="W",IF(G34<0,H34*100/ABS(G34),H34*G34/100),IF(K34="L",-H34,0)) -> 200 | M34: =Settings!$B$4+SUM(L$2:L34) -> 240.9461
J35: =IF(I35="","",I35-F35) | L35: =IF(K35="W",IF(G35<0,H35*100/ABS(G35),H35*G35/100),IF(K35="L",-H35,0)) -> 0 | M35: =Settings!$B$4+SUM(L$2:L35) -> 240.9461
L36: =IF(K36="W",IF(G36<0,H36*100/ABS(G36),H36*G36/100),IF(K36="L",-H36,0)) -> 0 | M36: =Settings!$B$4+SUM(L$2:L36) -> 240.9461
L37: =IF(K37="W",IF(G37<0,H37*100/ABS(G37),H37*G37/100),IF(K37="L",-H37,0)) -> 0 | M37: =Settings!$B$4+SUM(L$2:L37) -> 240.9461
L38: =IF(K38="W",IF(G38<0,H38*100/ABS(G38),H38*G38/100),IF(K38="L",-H38,0)) -> 0 | M38: =Settings!$B$4+SUM(L$2:L38) -> 240.9461
L39: =IF(K39="W",IF(G39<0,H39*100/ABS(G39),H39*G39/100),IF(K39="L",-H39,0)) -> 0 | M39: =Settings!$B$4+SUM(L$2:L39) -> 240.9461
L40: =IF(K40="W",IF(G40<0,H40*100/ABS(G40),H40*G40/100),IF(K40="L",-H40,0)) -> 0 | M40: =Settings!$B$4+SUM(L$2:L40) -> 240.9461
...

Sheet Team Profiles
A1: Team | B1: Prior Conference | C1: Joined 2026 | D1: Model Power Rating | E1: SP+ Rating | F1: Off PPA | G1: Def PPA | H1: Talent Rank | I1: Notes
A2: North Dakota State | B2: FCS (Missouri Valley Football Conference) | C2: Y | D2: 1738.7 | E2: -1.8 | F2: 0.23890242 | G2: -0.31310412 | H2: 117 | I2: Full MW history available. Option offense; home elevation ~6,621 ft.
A3: UNLV | B3: Mountain West | C3: N | D3: 1613.1 | E3: 3.6 | F3: 0.12002614 | G3: 0.089285135 | H3: 63 | I3: Full history. Travel distance/time-zone is a real situational factor for every road game.
A4: New Mexico | B4: Mountain West | C4: N | D4: 1569 | E4: 0 | F4: 0.21871077 | G4: -0.052181958 | H4: 87 | I4: Full history available.
A5: Hawai'i | B5: Mountain West | C5: N | D5: 1491.7 | E5: -2.6 | F5: -0.006779902 | G5: 0.24684334 | H5: 124 | I5: Full history. Home elevation ~5,000+ ft.
A6: Air Force | B6: Mountain West | C6: N | D6: 1499.4 | E6: -3.2 | F6: 0.39889458 | G6: -0.24811856 | H6: 141 | I6: Zero FBS history — historically dominant FCS program. Pull its FCS-era schedule separately (see pull_ndsu_games() in pull_games.py) since a plain division='fbs' query will not surface it before 2026. Likely market-mispricing candidate in year one since books/public have thin FBS-level reference data on it.
A7: Wyoming | B7: Mountain West | C7: N | D7: 1396.8 | E7: -10.8 | F7: -0.025107699 | G7: 0.30124182 | H7: 114 | I7: No MW history; bring its full MAC-era game log (already FBS, so it's in a plain division='fbs' pull).
A8: Northern Illinois | B8: MAC | C8: Y | D8: 1412.1 | E8: -17.2 | F8: -0.33173207 | G8: 0.061317393 | H8: 82 | I8: Full history available. Watch for 'San Jose State' (no accent) in some sources — same team.
A9: San José State | B9: Mountain West | C9: N | D9: 1432.7 | E9: -15.7 | F9: 0.16544541 | G9: 0.19261278 | H9: 129 | I9: Full history available.
A10: Nevada | B10: Mountain West | C10: N | D10: 1439.9 | E10: -11.7 | F10: 0.55627885 | G10: 0.065622886 | H10: 98 | I10: No MW history; bring its full C-USA-era game log (already FBS).
A11: UTEP | B11: Conference USA | C11: Y | D11: 1344.5 | E11: -19.3 | F11: -0.25135141 | G11: 0.38719058 | H11: 92 | I11: Full history. Home elevation ~7,220 ft — coldest, highest venue in the league.

Sheet Model Comparison
A1: Ridge vs. XGBoost vs. Dub Gamma -- Model Comparison
A2: Informational only. Ridge is still the live model everywhere else in this workbook and on the website -- XGBoost and the Dub Gamma Model are candidates being evaluated here, not replacements. Gamma has no rating (and so no prediction) for any season before it was seeded -- its columns read "n/a" for older games.
A4: All-Time (every season in the backtest)
A5: Model | B5: Games Graded | C5: Picks Graded | D5: Wins | E5: Losses | F5: Pushes | G5: ATS Win % | H5: ROI (flat stake) | I5: Real Edge Bets | J5: Real Edge Win % | K5: Tightest Of The Three (CLV) | L5: CLV Pts (cum.)
A6: Ridge (live model) -- all FBS | B6: 8531 | C6: 8457 | D6: 4224 | E6: 4233 | F6: 69 | G6: 50.0% | H6: -4.7% | I6: 6684 | J6: 49.7% | K6: 4036/8531 (47%) | L6: +5676.1
A7: Ridge (live model) -- MW-involved | B7: 969 | C7: 957 | D7: 474 | E7: 483 | F7: 12 | G7: 49.5% | H7: -5.4% | I7: 776 | J7: 49.4% | K7: 454/969 (47%) | L7: +600.8
A8: XGBoost (candidate) -- all FBS | B8: 8531 | C8: 8460 | D8: 4270 | E8: 4190 | F8: 69 | G8: 50.5% | H8: -3.6% | I8: 6625 | J8: 50.5% | K8: 4478/8531 (52%) | L8: +758.6
A9: XGBoost (candidate) -- MW-involved | B9: 969 | C9: 957 | D9: 485 | E9: 472 | F9: 12 | G9: 50.7% | H9: -3.2% | I9: 740 | J9: 51.5% | K9: 512/969 (53%) | L9: +895.5
A10: Dub Gamma Model (candidate) -- all FBS | B10: 8531 | C10: 97 | D10: 52 | E10: 45 | F10: 1 | G10: 53.6% | H10: +2.3% | I10: 91 | J10: 53.3% | K10: 17/98 (17%) | L10: -1491.4
A11: Dub Gamma Model (candidate) -- MW-involved | B11: 969 | C11: 13 | D11: 12 | E11: 1 | F11: 0 | G11: 92.3% | H11: +76.2% | I11: 12 | J11: 91.7% | K11: 3/13 (23%) | L11: -36.7
A13: 2026 Season Only
A14: Model | B14: Games Graded | C14: Picks Graded | D14: Wins | E14: Losses | F14: Pushes | G14: ATS Win % | H14: ROI (flat stake) | I14: Real Edge Bets | J14: Real Edge Win % | K14: Tightest Of The Three (CLV) | L14: CLV Pts (cum.)
A15: Ridge (live model) -- all FBS | B15: 98 | C15: 97 | D15: 41 | E15: 56 | F15: 1 | G15: 42.3% | H15: -19.3% | I15: 88 | J15: 40.2% | K15: 34/98 (35%) | L15: -418.9
A16: Ridge (live model) -- MW-involved | B16: 13 | C16: 13 | D16: 5 | E16: 8 | F16: 0 | G16: 38.5% | H16: -26.6% | I16: 11 | J16: 36.4% | K16: 4/13 (31%) | L16: +11.2
A17: XGBoost (candidate) -- all FBS | B17: 98 | C17: 97 | D17: 43 | E17: 54 | F17: 1 | G17: 44.3% | H17: -15.4% | I17: 82 | J17: 40.7% | K17: 47/98 (48%) | L17: -151.0
A18: XGBoost (candidate) -- MW-involved | B18: 13 | C18: 13 | D18: 5 | E18: 8 | F18: 0 | G18: 38.5% | H18: -26.6% | I18: 9 | J18: 22.2% | K18: 6/13 (46%) | L18: -13.3
A19: Dub Gamma Model (candidate) -- all FBS | B19: 98 | C19: 97 | D19: 52 | E19: 45 | F19: 1 | G19: 53.6% | H19: +2.3% | I19: 91 | J19: 53.3% | K19: 17/98 (17%) | L19: -1491.4
A20: Dub Gamma Model (candidate) -- MW-involved | B20: 13 | C20: 13 | D20: 12 | E20: 1 | F20: 0 | G20: 92.3% | H20: +76.2% | I20: 12 | J20: 91.7% | K20: 3/13 (23%) | L20: -36.7
A22: Ridge and XGBoost agree on which side to lean in 77.4% of all graded games. Gamma agrees with Ridge in 68.4% of games it has a rating for.
A24: Upcoming Games -- Ridge vs. XGBoost vs. Dub Gamma (Not Yet Graded)
A25: Week | B25: Matchup | C25: Market Line (Home) | D25: Ridge Line | E25: XGBoost Line | F25: Gamma Line | G25: Ridge Lean | H25: XGBoost Lean | I25: Gamma Lean | J25: Ridge/XGBoost Agree? | K25: Tightest (Live)*
A26: 2 | B26: UNLV @ North Texas | C26: +3.5 | D26: -3.9 | E26: +2.6 | F26: -5.3 | G26: Home | H26: Away (auto) | I26: Home | J26: No | K26: XGBoost
A27: 2 | B27: Northern Colorado @ Wyoming | C27: -- | D27: -17.1 | E27: -21.5 | F27: +11.3 | G27: n/a | H27: n/a | I27: n/a | J27: n/a | K27: n/a
A28: 2 | B28: Mercyhurst @ New Mexico | C28: -- | D28: -17.1 | E28: -27.1 | F28: -6.7 | G28: n/a | H28: n/a | I28: n/a | J28: n/a | K28: n/a
A29: 2 | B29: Illinois State @ Northern Illinois | C29: -- | D29: -16.0 | E29: -17.9 | F29: +15.6 | G29: n/a | H29: n/a | I29: n/a | J29: n/a | K29: n/a
A30: 2 | B30: Texas Southern @ UTEP | C30: -- | D30: -16.1 | E30: -21.4 | F30: +19.1 | G30: n/a | H30: n/a | I30: n/a | J30: n/a | K30: n/a
A31: 2 | B31: Cal Poly @ San José State | C31: -- | D31: -21.0 | E31: -30.0 | F31: +8.1 | G31: n/a | H31: n/a | I31: n/a | J31: n/a | K31: n/a
A32: 2 | B32: North Dakota State @ Air Force | C32: +2.5 | D32: +16.9 | E32: +15.3 | F32: +17.9 | G32: Away | H32: Away | I32: Away | J32: Yes | K32: XGBoost
A33: 2 | B33: Montana State @ Nevada | C33: -- | D33: -17.2 | E33: -12.7 | F33: +5.3 | G33: n/a | H33: n/a | I33: n/a | J33: n/a | K33: n/a
A34: 2 | B34: New Mexico State @ Hawai'i | C34: -8.5 | D34: -14.2 | E34: -13.2 | F34: -7.6 | G34: Home | H34: Home | I34: Home (auto) | J34: Yes | K34: Gamma
A35: * Tightest (Live) compares each model's line to TODAY's still-moving market line, not a final closing line -- it will keep changing until kickoff. See the graded Game-by-Game table below for the real, closing-line version of this comparison.
A38: 2026 Mountain West Games -- Game by Game
A39: Week | B39: Matchup | C39: Final Score | D39: Vegas Spread (Home) | E39: Actual Margin (Home) | F39: Ridge Line | G39: Ridge Edge | H39: Ridge Lean | I39: Ridge Result | J39: XGBoost Line | K39: XGBoost Edge | L39: XGBoost Lean | M39: XGBoost Result | N39: Gamma Line | O39: Gamma Edge | P39: Gamma Lean | Q39: Gamma Result | R39: Ridge/XGBoost Agree? | S39: Gamma Agrees (w/ Ridge)? | T39: Tightest CLV Line | U39: Ridge CLV Pts (Cum.) | V39: XGBoost CLV Pts (Cum.) | W39: Gamma CLV Pts (Cum.)
A40: 1 | B40: Duquesne @ Air Force | C40: 0-34 | D40: -30.0 | E40: +34.0 | F40: -17.0 | G40: -13.0 | H40: Away | I40: Loss | J40: -28.3 | K40: -1.7 | L40: Home | M40: Win (no real edge) | N40: +2.3 | O40: -32.3 | P40: Away | Q40: Loss (seed week) | R40: No | S40: Yes | T40: XGBoost | U40: -13.0 | V40: -1.7 | W40: -32.3
A41: 1 | B41: Wyoming @ Colorado State | C41: 13-35 | D41: -2.8 | E41: +22.0 | F41: -7.8 | G41: +5.1 | H41: Home | I41: Win | J41: -2.5 | K41: -0.2 | L41: Home | M41: Win (no real edge) | N41: -6.4 | O41: +3.7 | P41: Home | Q41: Win (seed week) | R41: Yes | S41: Yes | T41: XGBoost | U41: -7.9 | V41: -1.9 | W41: -28.7
A42: 1 | B42: San José State @ Eastern Michigan | C42: 27-21 | D42: -1.5 | E42: -6.0 | F42: -15.8 | G42: +14.3 | H42: Home | I42: Loss | J42: -10.5 | K42: +9.0 | L42: Home | M42: Loss | N42: +0.5 | O42: -2.0 | P42: Away | Q42: Win (seed week) | R42: Yes | S42: No | T42: Gamma | U42: +6.4 | V42: +7.2 | W42: -30.7
A43: 1 | B43: UNLV @ Hawai'i | C43: 21-6 | D43: +2.8 | E43: -15.0 | F43: +2.9 | G43: -0.1 | H43: Away | I43: Win (no real edge) | J43: -1.8 | K43: +4.6 | L43: Home | M43: Loss | N43: +4.4 | O43: -1.6 | P43: Away | Q43: Win (no real edge) (seed week) | R43: No | S43: Yes | T43: Ridge | U43: +6.2 | V43: +11.8 | W43: -32.3
A44: 1 | B44: Northern Illinois @ Iowa | C44: 0-40 | D44: -31.8 | E44: +40.0 | F44: -28.3 | G44: -3.5 | H44: Away | I44: Loss | J44: -25.4 | K44: -6.4 | L44: Away | M44: Loss | N44: -41.0 | O44: +9.2 | P44: Home | Q44: Win (seed week) | R44: Yes | S44: No | T44: Ridge | U44: +2.8 | V44: +5.4 | W44: -23.1
A45: 1 | B45: Western Kentucky @ Nevada | C45: 14-49 | D45: +0.2 | E45: +35.0 | F45: +3.3 | G45: -3.0 | H45: Away | I45: Loss | J45: +7.3 | K45: -7.1 | L45: Away | M45: Loss | N45: -2.5 | O45: +2.7 | P45: Home | Q45: Win (seed week) | R45: Yes | S45: No | T45: Gamma | U45: -0.3 | V45: -1.7 | W45: -20.4
A46: 1 | B46: Central Michigan @ New Mexico | C46: 7-38 | D46: -11.2 | E46: +31.0 | F46: -17.5 | G46: +6.2 | H46: Home | I46: Win | J46: -11.6 | K46: +0.3 | L46: Home | M46: Win (no real edge) | N46: -15.6 | O46: +4.3 | P46: Home | Q46: Win (seed week) | R46: Yes | S46: Yes | T46: XGBoost | U46: +5.9 | V46: -1.4 | W46: -16.0
...
