Workbook

Sheet Read Me
A1: Mountain West Handicapping Tracker
A2: 2026 Season
A4: How this workbook is meant to be used
A5: This workbook is the review/tracking cockpit -- the model itself runs in Python (see the
A6: attack plan and the src/ scripts). Each week, paste that week's model output into the blue
A7: cells on the Weekly Slate tab; everything else on that tab recalculates automatically.
A9: Color legend
A10: Blue text = cells you fill in by hand (model output, market lines, bet results)
A11: Black text = formulas -- don't type over these, they recalculate from the blue cells
A12: Yellow fill = key assumptions on the Settings tab (edit these once, not weekly)
A14: Tabs
A15: Settings = bankroll, edge thresholds, and other assumptions used across the workbook
... A22: paper-trading and bankroll discipline before staking real money.

Sheet Settings
A1: Settings & Assumptions
A3: Assumption | B3: Value | C3: Notes
A4: Starting bankroll (units) | B4: 50 | C4: Example: 100 units. 1 unit = whatever flat stake you choose in real currency.
A5: Spread edge threshold (pts) | B5: 2 | C5: Minimum |model line - market line| before a spread is flagged as a lean.
A6: Total edge threshold (pts) | B6: 2 | C6: Minimum |model total - market total| before a total is flagged as a lean.
A7: Standard vig odds (American) | B7: -110 | C7: Reference only -- breakeven win rate at -110 is 52.4%.

Sheet Weekly Slate
A1: Week | B1: Date | C1: Away Team | D1: Home Team | E1: Model Line (Home) | F1: Market Line (Home) | G1: Spread Edge (pts) | H1: Spread Lean | I1: Model Total | J1: Market Total | K1: Total Edge (pts) | L1: Total Lean | M1: Suggested Bet (Spread) | N1: Suggested Bet (Total) | O1: Qualitative Notes | P1: Final Decision | R1: MW WEST Teams
A2: 9 | B2: 2026-10-31 | C2: UConn | D2: Air Force | E2: -5.2 | F2: -3 | G2: =F2-E2 | H2: =IF(G2=0,"Pick'em",IF(G2>0,"Home","Away")) | I2: 53.2 | J2: 53.5 | K2: =I2-J2 | L2: =IF(K2=0,"Push",IF(K2>0,"Over","Under")) | M2: =IF(ABS(G2)>=Settings!$B$5,H2,IF(F2=0,"Pick'em",IF(F2<0,"Home (auto)","Away (auto)"))) | N2: =IF(ABS(K2)>=Settings!$B$6,L2,IF(K2=0,"Push",L2&" (auto)"))
A3: 9 | B3: 2026-10-31 | C3: UTEP | D3: North Dakota State | E3: -36 | F3: -26.5 | G3: =F3-E3 | H3: =IF(G3=0,"Pick'em",IF(G3>0,"Home","Away")) | I3: 43.3 | J3: 44.5 | K3: =I3-J3 | L3: =IF(K3=0,"Push",IF(K3>0,"Over","Under")) | M3: =IF(ABS(G3)>=Settings!$B$5,H3,IF(F3=0,"Pick'em",IF(F3<0,"Home (auto)","Away (auto)"))) | N3: =IF(ABS(K3)>=Settings!$B$6,L3,IF(K3=0,"Push",L3&" (auto)"))
A4: 9 | B4: 2026-10-31 | C4: New Mexico | D4: San José State | E4: 14.9 | F4: 14.5 | G4: =F4-E4 | H4: =IF(G4=0,"Pick'em",IF(G4>0,"Home","Away")) | I4: 45.6 | J4: 41.5 | K4: =I4-J4 | L4: =IF(K4=0,"Push",IF(K4>0,"Over","Under")) | M4: =IF(ABS(G4)>=Settings!$B$5,H4,IF(F4=0,"Pick'em",IF(F4<0,"Home (auto)","Away (auto)"))) | N4: =IF(ABS(K4)>=Settings!$B$6,L4,IF(K4=0,"Push",L4&" (auto)"))
A5: 9 | B5: 2026-10-31 | C5: Nevada | D5: UCLA | E5: -21.2 | F5: -22.5 | G5: =F5-E5 | H5: =IF(G5=0,"Pick'em",IF(G5>0,"Home","Away")) | I5: 43.5 | J5: 44.5 | K5: =I5-J5 | L5: =IF(K5=0,"Push",IF(K5>0,"Over","Under")) | M5: =IF(ABS(G5)>=Settings!$B$5,H5,IF(F5=0,"Pick'em",IF(F5<0,"Home (auto)","Away (auto)"))) | N5: =IF(ABS(K5)>=Settings!$B$6,L5,IF(K5=0,"Push",L5&" (auto)")) | R5: Air Force
A6: 9 | B6: 2026-11-01 | C6: Northern Illinois | D6: UNLV | E6: -27.9 | F6: -24.5 | G6: =F6-E6 | H6: =IF(G6=0,"Pick'em",IF(G6>0,"Home","Away")) | I6: 44.4 | J6: 52.5 | K6: =I6-J6 | L6: =IF(K6=0,"Push",IF(K6>0,"Over","Under")) | M6: =IF(ABS(G6)>=Settings!$B$5,H6,IF(F6=0,"Pick'em",IF(F6<0,"Home (auto)","Away (auto)"))) | N6: =IF(ABS(K6)>=Settings!$B$6,L6,IF(K6=0,"Push",L6&" (auto)")) | R6: Hawai'i
A7: 8 | B7: 2026-10-24 | C7: San José State | D7: Nevada | E7: -7.6 | F7: -6.8 | G7: =F7-E7 | H7: =IF(G7=0,"Pick'em",IF(G7>0,"Home","Away")) | I7: 46.8 | J7: 46.5 | K7: =I7-J7 | L7: =IF(K7=0,"Push",IF(K7>0,"Over","Under")) | M7: =IF(ABS(G7)>=Settings!$B$5,H7,IF(F7=0,"Pick'em",IF(F7<0,"Home (auto)","Away (auto)"))) | N7: =IF(ABS(K7)>=Settings!$B$6,L7,IF(K7=0,"Push",L7&" (auto)")) | R7: Nevada
A8: 8 | B8: 2026-10-24 | C8: Hawai'i | D8: Northern Illinois | E8: 6.1 | F8: 4 | G8: =F8-E8 | H8: =IF(G8=0,"Pick'em",IF(G8>0,"Home","Away")) | I8: 43.8 | J8: 47.5 | K8: =I8-J8 | L8: =IF(K8=0,"Push",IF(K8>0,"Over","Under")) | M8: =IF(ABS(G8)>=Settings!$B$5,H8,IF(F8=0,"Pick'em",IF(F8<0,"Home (auto)","Away (auto)"))) | N8: =IF(ABS(K8)>=Settings!$B$6,L8,IF(K8=0,"Push",L8&" (auto)")) | R8: New Mexico
A9: 8 | B9: 2026-10-24 | C9: Air Force | D9: Wyoming | E9: 7.4 | F9: 5.5 | G9: =F9-E9 | H9: =IF(G9=0,"Pick'em",IF(G9>0,"Home","Away")) | I9: 47.7 | J9: 46.5 | K9: =I9-J9 | L9: =IF(K9=0,"Push",IF(K9>0,"Over","Under")) | M9: =IF(ABS(G9)>=Settings!$B$5,H9,IF(F9=0,"Pick'em",IF(F9<0,"Home (auto)","Away (auto)"))) | N9: =IF(ABS(K9)>=Settings!$B$6,L9,IF(K9=0,"Push",L9&" (auto)")) | R9: North Dakota State
A10: 8 | B10: 2026-10-25 | C10: North Dakota State | D10: New Mexico | E10: -2.4 | F10: -4.5 | G10: =F10-E10 | H10: =IF(G10=0,"Pick'em",IF(G10>0,"Home","Away")) | I10: 42.5 | J10: 40.5 | K10: =I10-J10 | L10: =IF(K10=0,"Push",IF(K10>0,"Over","Under")) | M10: =IF(ABS(G10)>=Settings!$B$5,H10,IF(F10=0,"Pick'em",IF(F10<0,"Home (auto)","Away (auto)"))) | N10: =IF(ABS(K10)>=Settings!$B$6,L10,IF(K10=0,"Push",L10&" (auto)")) | R10: Northern Illinois
A11: 7 | B11: 2026-10-17 | C11: UNLV | D11: Air Force | E11: 0.2 | F11: 1.2 | G11: =F11-E11 | H11: =IF(G11=0,"Pick'em",IF(G11>0,"Home","Away")) | I11: 47.2 | J11: 48.5 | K11: =I11-J11 | L11: =IF(K11=0,"Push",IF(K11>0,"Over","Under")) | M11: =IF(ABS(G11)>=Settings!$B$5,H11,IF(F11=0,"Pick'em",IF(F11<0,"Home (auto)","Away (auto)"))) | N11: =IF(ABS(K11)>=Settings!$B$6,L11,IF(K11=0,"Push",L11&" (auto)")) | R11: San José State
A12: 7 | B12: 2026-10-17 | C12: Nevada | D12: North Dakota State | E12: -24.6 | F12: -14.8 | G12: =F12-E12 | H12: =IF(G12=0,"Pick'em",IF(G12>0,"Home","Away")) | I12: 45.1 | J12: 42.5 | K12: =I12-J12 | L12: =IF(K12=0,"Push",IF(K12>0,"Over","Under")) | M12: =IF(ABS(G12)>=Settings!$B$5,H12,IF(F12=0,"Pick'em",IF(F12<0,"Home (auto)","Away (auto)"))) | N12: =IF(ABS(K12)>=Settings!$B$6,L12,IF(K12=0,"Push",L12&" (auto)")) | R12: UNLV
A13: 7 | B13: 2026-10-17 | C13: Northern Illinois | D13: Wyoming | E13: -11.2 | F13: -7.8 | G13: =F13-E13 | H13: =IF(G13=0,"Pick'em",IF(G13>0,"Home","Away")) | I13: 40.3 | J13: 40.5 | K13: =I13-J13 | L13: =IF(K13=0,"Push",IF(K13>0,"Over","Under")) | M13: =IF(ABS(G13)>=Settings!$B$5,H13,IF(F13=0,"Pick'em",IF(F13<0,"Home (auto)","Away (auto)"))) | N13: =IF(ABS(K13)>=Settings!$B$6,L13,IF(K13=0,"Push",L13&" (auto)"))
A14: 7 | B14: 2026-10-18 | C14: New Mexico | D14: Hawai'i | E14: 18.5 | F14: 15.5 | G14: =F14-E14 | H14: =IF(G14=0,"Pick'em",IF(G14>0,"Home","Away")) | I14: 45.4 | J14: 44.5 | K14: =I14-J14 | L14: =IF(K14=0,"Push",IF(K14>0,"Over","Under")) | M14: =IF(ABS(G14)>=Settings!$B$5,H14,IF(F14=0,"Pick'em",IF(F14<0,"Home (auto)","Away (auto)"))) | N14: =IF(ABS(K14)>=Settings!$B$6,L14,IF(K14=0,"Push",L14&" (auto)"))
A15: 7 | B15: 2026-10-18 | C15: San José State | D15: UTEP | E15: 8.8 | F15: 7.2 | G15: =F15-E15 | H15: =IF(G15=0,"Pick'em",IF(G15>0,"Home","Away")) | I15: 46.5 | J15: 46.8 | K15: =I15-J15 | L15: =IF(K15=0,"Push",IF(K15>0,"Over","Under")) | M15: =IF(ABS(G15)>=Settings!$B$5,H15,IF(F15=0,"Pick'em",IF(F15<0,"Home (auto)","Away (auto)"))) | N15: =IF(ABS(K15)>=Settings!$B$6,L15,IF(K15=0,"Push",L15&" (auto)"))
A16: 6 | B16: 2026-10-10 | C16: Air Force | D16: Northern Illinois | E16: 14.9 | F16: 7.5 | G16: =F16-E16 | H16: =IF(G16=0,"Pick'em",IF(G16>0,"Home","Away")) | I16: 41.2 | J16: 46.8 | K16: =I16-J16 | L16: =IF(K16=0,"Push",IF(K16>0,"Over","Under")) | M16: =IF(ABS(G16)>=Settings!$B$5,H16,IF(F16=0,"Pick'em",IF(F16<0,"Home (auto)","Away (auto)"))) | N16: =IF(ABS(K16)>=Settings!$B$6,L16,IF(K16=0,"Push",L16&" (auto)"))
A17: 6 | B17: 2026-10-10 | C17: Wyoming | D17: San José State | E17: -4.4 | F17: -4.5 | G17: =F17-E17 | H17: =IF(G17=0,"Pick'em",IF(G17>0,"Home","Away")) | I17: 45.6 | J17: 42.5 | K17: =I17-J17 | L17: =IF(K17=0,"Push",IF(K17>0,"Over","Under")) | M17: =IF(ABS(G17)>=Settings!$B$5,H17,IF(F17=0,"Pick'em",IF(F17<0,"Home (auto)","Away (auto)"))) | N17: =IF(ABS(K17)>=Settings!$B$6,L17,IF(K17=0,"Push",L17&" (auto)"))
A18: 6 | B18: 2026-10-10 | C18: North Dakota State | D18: UNLV | E18: 11.7 | F18: 3 | G18: =F18-E18 | H18: =IF(G18=0,"Pick'em",IF(G18>0,"Home","Away")) | I18: 43.9 | J18: 47.5 | K18: =I18-J18 | L18: =IF(K18=0,"Push",IF(K18>0,"Over","Under")) | M18: =IF(ABS(G18)>=Settings!$B$5,H18,IF(F18=0,"Pick'em",IF(F18<0,"Home (auto)","Away (auto)"))) | N18: =IF(ABS(K18)>=Settings!$B$6,L18,IF(K18=0,"Push",L18&" (auto)"))
A19: 6 | B19: 2026-10-10 | C19: Nevada | D19: UTEP | E19: 9.8 | F19: 9.8 | G19: =F19-E19 | H19: =IF(G19=0,"Pick'em",IF(G19>0,"Home","Away")) | I19: 45 | J19: 49.5 | K19: =I19-J19 | L19: =IF(K19=0,"Push",IF(K19>0,"Over","Under")) | M19: =IF(ABS(G19)>=Settings!$B$5,H19,IF(F19=0,"Pick'em",IF(F19<0,"Home (auto)","Away (auto)"))) | N19: =IF(ABS(K19)>=Settings!$B$6,L19,IF(K19=0,"Push",L19&" (auto)"))
A20: 6 | B20: 2026-10-11 | C20: Hawai'i | D20: Arizona State | E20: -14.4 | F20: -20.8 | G20: =F20-E20 | H20: =IF(G20=0,"Pick'em",IF(G20>0,"Home","Away")) | I20: 47.8 | J20: 50.5 | K20: =I20-J20 | L20: =IF(K20=0,"Push",IF(K20>0,"Over","Under")) | M20: =IF(ABS(G20)>=Settings!$B$5,H20,IF(F20=0,"Pick'em",IF(F20<0,"Home (auto)","Away (auto)"))) | N20: =IF(ABS(K20)>=Settings!$B$6,L20,IF(K20=0,"Push",L20&" (auto)"))
A21: 5 | B21: 2026-10-03 | C21: Navy | D21: Air Force | E21: 5 | F21: -2.8 | G21: =F21-E21 | H21: =IF(G21=0,"Pick'em",IF(G21>0,"Home","Away")) | I21: 55.1 | J21: 45.2 | K21: =I21-J21 | L21: =IF(K21=0,"Push",IF(K21>0,"Over","Under")) | M21: =IF(ABS(G21)>=Settings!$B$5,H21,IF(F21=0,"Pick'em",IF(F21<0,"Home (auto)","Away (auto)"))) | N21: =IF(ABS(K21)>=Settings!$B$6,L21,IF(K21=0,"Push",L21&" (auto)"))
A22: 5 | B22: 2026-10-03 | C22: UTEP | D22: New Mexico | E22: -32.3 | F22: -23.2 | G22: =F22-E22 | H22: =IF(G22=0,"Pick'em",IF(G22>0,"Home","Away")) | I22: 43.7 | J22: 47.8 | K22: =I22-J22 | L22: =IF(K22=0,"Push",IF(K22>0,"Over","Under")) | M22: =IF(ABS(G22)>=Settings!$B$5,H22,IF(F22=0,"Pick'em",IF(F22<0,"Home (auto)","Away (auto)"))) | N22: =IF(ABS(K22)>=Settings!$B$6,L22,IF(K22=0,"Push",L22&" (auto)"))
A23: 5 | B23: 2026-10-03 | C23: Wyoming | D23: North Dakota State | E23: -30.4 | F23: -17.2 | G23: =F23-E23 | H23: =IF(G23=0,"Pick'em",IF(G23>0,"Home","Away")) | I23: 46.7 | J23: 44.5 | K23: =I23-J23 | L23: =IF(K23=0,"Push",IF(K23>0,"Over","Under")) | M23: =IF(ABS(G23)>=Settings!$B$5,H23,IF(F23=0,"Pick'em",IF(F23<0,"Home (auto)","Away (auto)"))) | N23: =IF(ABS(K23)>=Settings!$B$6,L23,IF(K23=0,"Push",L23&" (auto)"))
A24: 5 | B24: 2026-10-03 | C24: California | D24: UNLV | E24: -5.9 | F24: -1.8 | G24: =F24-E24 | H24: =IF(G24=0,"Pick'em",IF(G24>0,"Home","Away")) | I24: 45.6 | J24: 52.2 | K24: =I24-J24 | L24: =IF(K24=0,"Push",IF(K24>0,"Over","Under")) | M24: =IF(ABS(G24)>=Settings!$B$5,H24,IF(F24=0,"Pick'em",IF(F24<0,"Home (auto)","Away (auto)"))) | N24: =IF(ABS(K24)>=Settings!$B$6,L24,IF(K24=0,"Push",L24&" (auto)"))
A25: 5 | B25: 2026-10-04 | C25: San José State | D25: Hawai'i | E25: -6.9 | F25: -2.8 | G25: =F25-E25 | H25: =IF(G25=0,"Pick'em",IF(G25>0,"Home","Away")) | I25: 48.5 | J25: 51.2 | K25: =I25-J25 | L25: =IF(K25=0,"Push",IF(K25>0,"Over","Under")) | M25: =IF(ABS(G25)>=Settings!$B$5,H25,IF(F25=0,"Pick'em",IF(F25<0,"Home (auto)","Away (auto)"))) | N25: =IF(ABS(K25)>=Settings!$B$6,L25,IF(K25=0,"Push",L25&" (auto)"))

Sheet Bet Log
A1: Date | B1: Week | C1: Matchup | D1: Bet Type | E1: Side | F1: Line Taken | G1: Odds (American) | H1: Stake (units) | I1: Closing Line | J1: CLV (pts) | K1: Result | L1: Units Won/Lost | M1: Running Bankroll
A2: 2026-08-29 | B2: 1 | C2: Jacksonville State @ North Dakota State | D2: Spread | E2: North Dakota State | F2: -7.5 | G2: 100 | H2: 1 | I2: -7 | J2: =IF(I2="","",I2-F2) | K2: W | L2: =IF(K2="W",IF(G2<0,H2*100/ABS(G2),H2*G2/100),IF(K2="L",-H2,0)) | M2: =Settings!$B$4+SUM(L$2:L2)
A3: 2026-08-29 | B3: 1 | C3: Jacksonville State @ North Dakota State | D3: Moneyline | E3: North Dakota State | G3: -285 | H3: 5 | J3: =IF(I3="","",I3-F3) | K3: W | L3: =IF(K3="W",IF(G3<0,H3*100/ABS(G3),H3*G3/100),IF(K3="L",-H3,0)) | M3: =Settings!$B$4+SUM(L$2:L3)
A4: 2026-08-29 | B4: 1 | C4: Memphis @ UNLV | D4: Moneyline | E4: UNLV | G4: -178 | H4: 5 | J4: =IF(I4="","",I4-F4) | K4: L | L4: =IF(K4="W",IF(G4<0,H4*100/ABS(G4),H4*G4/100),IF(K4="L",-H4,0)) | M4: =Settings!$B$4+SUM(L$2:L4)
A5: 2026-08-29 | B5: 1 | C5: Jacksonville State @ North Dakota State,Memphis @ UNLV | D5: ML Parlay | E5: North Dakota State / UNLV | G5: 110 | H5: 3 | J5: =IF(I5="","",I5-F5) | K5: L | L5: =IF(K5="W",IF(G5<0,H5*100/ABS(G5),H5*G5/100),IF(K5="L",-H5,0)) | M5: =Settings!$B$4+SUM(L$2:L5)
A6: 2026-09-04 | B6: 1 | C6: San José State @ Eastern Michigan | D6: Spread | E6: Eastern Michigan | F6: -3.5 | G6: -110 | H6: 2 | I6: -1.5 | J6: =IF(I6="","",I6-F6) | K6: L | L6: =IF(K6="W",IF(G6<0,H6*100/ABS(G6),H6*G6/100),IF(K6="L",-H6,0)) | M6: =Settings!$B$4+SUM(L$2:L6)
A7: 2026-09-05 | B7: 1 | C7: San José State @ Eastern Michigan, Wyoming at Colorado State | D7: ML Parlay | E7: Eastern Michigan, Colorado State | G7: 149 | H7: 2 | J7: =IF(I7="","",I7-F7) | K7: L | L7: =IF(K7="W",IF(G7<0,H7*100/ABS(G7),H7*G7/100),IF(K7="L",-H7,0)) | M7: =Settings!$B$4+SUM(L$2:L7)
A8: 2026-09-05 | B8: 1 | C8: Wyoming @ Colorado State | D8: Spread | E8: Colorado State | F8: -2.5 | G8: -110 | H8: 2 | I8: -3 | J8: =IF(I8="","",I8-F8) | K8: W | L8: =IF(K8="W",IF(G8<0,H8*100/ABS(G8),H8*G8/100),IF(K8="L",-H8,0)) | M8: =Settings!$B$4+SUM(L$2:L8)
A9: 2026-09-05 | B9: 1 | C9: Wyoming @ Colorado State | D9: Moneyline | E9: Colorado State | G9: -145 | H9: 2 | J9: =IF(I9="","",I9-F9) | K9: W | L9: =IF(K9="W",IF(G9<0,H9*100/ABS(G9),H9*G9/100),IF(K9="L",-H9,0)) | M9: =Settings!$B$4+SUM(L$2:L9)
A10: 2026-09-05 | B10: 1 | C10: Central Michigan @ New Mexico | D10: Spread | E10: New Mexico | F10: -12.5 | G10: -110 | H10: 5 | I10: -10 | J10: =IF(I10="","",I10-F10) | K10: W | L10: =IF(K10="W",IF(G10<0,H10*100/ABS(G10),H10*G10/100),IF(K10="L",-H10,0)) | M10: =Settings!$B$4+SUM(L$2:L10)
A11: 2026-09-07 | B11: 1 | C11: SMU @ Florida State | D11: Spread | E11: SMU | F11: -2.5 | G11: -122 | H11: 2 | I11: -3 | J11: =IF(I11="","",I11-F11) | K11: W | L11: =IF(K11="W",IF(G11<0,H11*100/ABS(G11),H11*G11/100),IF(K11="L",-H11,0)) | M11: =Settings!$B$4+SUM(L$2:L11)
A12: 2026-09-07 | B12: 1 | C12: SMU @ Florida State | D12: Spread | E12: Florida State | F12: 10.5 | G12: -118 | H12: 3 | I12: 3 | J12: =IF(I12="","",I12-F12) | K12: W | L12: =IF(K12="W",IF(G12<0,H12*100/ABS(G12),H12*G12/100),IF(K12="L",-H12,0)) | M12: =Settings!$B$4+SUM(L$2:L12)
A13: 2026-09-07 | B13: 1 | C13: SMU @ Florida State | D13: Moneyline | E13: Florida State | G13: 265 | H13: 1 | J13: =IF(I13="","",I13-F13) | K13: L | L13: =IF(K13="W",IF(G13<0,H13*100/ABS(G13),H13*G13/100),IF(K13="L",-H13,0)) | M13: =Settings!$B$4+SUM(L$2:L13)
A14: 2026-09-06 | B14: 1 | C14: Louisville @ Ole Miss | D14: Spread | E14: Louisville | F14: 6.5 | G14: -108 | H14: 3 | I14: 6.5 | J14: =IF(I14="","",I14-F14) | K14: W | L14: =IF(K14="W",IF(G14<0,H14*100/ABS(G14),H14*G14/100),IF(K14="L",-H14,0)) | M14: =Settings!$B$4+SUM(L$2:L14)
A15: 2026-09-06 | B15: 1 | C15: Louisville @ Ole Miss | D15: Spread | E15: Louisville | F15: 7.5 | G15: 114 | H15: 3 | I15: 6.5 | J15: =IF(I15="","",I15-F15) | K15: W | L15: =IF(K15="W",IF(G15<0,H15*100/ABS(G15),H15*G15/100),IF(K15="L",-H15,0)) | M15: =Settings!$B$4+SUM(L$2:L15)
A16: 2026-09-06 | B16: 1 | C16: Wisconsin @ Notre Dame | D16: Spread | E16: Wisconsin | F16: 14.5 | G16: -132 | H16: 3 | I16: 21 | J16: =IF(I16="","",I16-F16) | K16: L | L16: =IF(K16="W",IF(G16<0,H16*100/ABS(G16),H16*G16/100),IF(K16="L",-H16,0)) | M16: =Settings!$B$4+SUM(L$2:L16)
A17: 2026-09-05 | B17: 1 | C17: Clemson @ LSU | D17: Spread | E17: Clemson | F17: 28.5 | G17: -138 | H17: 7.5 | I17: 10 | J17: =IF(I17="","",I17-F17) | K17: L | L17: =IF(K17="W",IF(G17<0,H17*100/ABS(G17),H17*G17/100),IF(K17="L",-H17,0)) | M17: =Settings!$B$4+SUM(L$2:L17)
A18: 2026-09-05 | B18: 1 | C18: Clemson @ LSU | D18: Spread | E18: Clemson | F18: 10.5 | G18: -118 | H18: 2.5 | I18: 10 | J18: =IF(I18="","",I18-F18) | K18: L | L18: =IF(K18="W",IF(G18<0,H18*100/ABS(G18),H18*G18/100),IF(K18="L",-H18,0)) | M18: =Settings!$B$4+SUM(L$2:L18)
A19: 2026-09-05 | B19: 1 | C19: Western Michigan @ Michigan | D19: Moneyline | E19: Michigan | G19: 146 | H19: 11.5 | J19: =IF(I19="","",I19-F19) | K19: W | L19: =IF(K19="W",IF(G19<0,H19*100/ABS(G19),H19*G19/100),IF(K19="L",-H19,0)) | M19: =Settings!$B$4+SUM(L$2:L19)
A20: 2026-09-05 | B20: 1 | C20: Boise State @ Oregon | D20: Spread | E20: Boise State | F20: 6.5 | G20: 108 | H20: 3 | I20: 25 | J20: =IF(I20="","",I20-F20) | K20: L | L20: =IF(K20="W",IF(G20<0,H20*100/ABS(G20),H20*G20/100),IF(K20="L",-H20,0)) | M20: =Settings!$B$4+SUM(L$2:L20)
A21: 2026-09-05 | B21: 1 | C21: Tarleton State @ Bowling Green | D21: Moneyline | E21: Bowling Green | G21: 200 | H21: 3 | J21: =IF(I21="","",I21-F21) | K21: L | L21: =IF(K21="W",IF(G21<0,H21*100/ABS(G21),H21*G21/100),IF(K21="L",-H21,0)) | M21: =Settings!$B$4+SUM(L$2:L21)
A22: 2026-09-04 | B22: 1 | C22: Miami @ Stanford | D22: Spread | E22: Miami | F22: -36.5 | G22: 100 | H22: 2.5 | I22: -24.5 | J22: =IF(I22="","",I22-F22) | K22: W | L22: =IF(K22="W",IF(G22<0,H22*100/ABS(G22),H22*G22/100),IF(K22="L",-H22,0)) | M22: =Settings!$B$4+SUM(L$2:L22)
A23: 2026-09-04 | B23: 1 | C23: Fresno State @ USC | D23: Total | F23: 39.5 | G23: -102 | H23: 5 | J23: =IF(I23="","",I23-F23) | K23: L | L23: =IF(K23="W",IF(G23<0,H23*100/ABS(G23),H23*G23/100),IF(K23="L",-H23,0)) | M23: =Settings!$B$4+SUM(L$2:L23)
A24: 2026-09-04 | B24: 1 | C24: Toledo @ MSU | D24: Spread | E24: Michigan | F24: -12.5 | G24: -114 | H24: 3.5 | J24: =IF(I24="","",I24-F24) | K24: L | L24: =IF(K24="W",IF(G24<0,H24*100/ABS(G24),H24*G24/100),IF(K24="L",-H24,0)) | M24: =Settings!$B$4+SUM(L$2:L24)
A25: 2026-09-04 | B25: 1 | C25: UTEP @ Oklahoma | D25: Total | F25: 51.5 | G25: -128 | H25: 2.5 | J25: =IF(I25="","",I25-F25) | K25: L | L25: =IF(K25="W",IF(G25<0,H25*100/ABS(G25),H25*G25/100),IF(K25="L",-H25,0)) | M25: =Settings!$B$4+SUM(L$2:L25)
A26: 2026-09-04 | B26: 1 | C26: San Jose State @ Eastern Michigan | D26: Moneyline | E26: Eastern Michigan | G26: -146 | H26: 2 | J26: =IF(I26="","",I26-F26) | K26: L | L26: =IF(K26="W",IF(G26<0,H26*100/ABS(G26),H26*G26/100),IF(K26="L",-H26,0)) | M26: =Settings!$B$4+SUM(L$2:L26)
A27: 2026-09-04 | B27: 1 | C27: UAB @ Illinois | D27: Spread | E27: UAB | F27: 17.5 | G27: -106 | H27: 2.75 | I27: 26 | J27: =IF(I27="","",I27-F27) | K27: L | L27: =IF(K27="W",IF(G27<0,H27*100/ABS(G27),H27*G27/100),IF(K27="L",-H27,0)) | M27: =Settings!$B$4+SUM(L$2:L27)
A28: 2026-09-04 | B28: 1 | C28: UAB @ Illinois | D28: Spread | E28: UAB | F28: 25.5 | G28: 320 | H28: 2 | I28: 26 | J28: =IF(I28="","",I28-F28) | K28: W | L28: =IF(K28="W",IF(G28<0,H28*100/ABS(G28),H28*G28/100),IF(K28="L",-H28,0)) | M28: =Settings!$B$4+SUM(L$2:L28)
A29: 2026-09-12 | B29: 2 | C29: UNLV @ North Texas | D29: Spread | E29: North Texas | F29: 3.5 | G29: -114 | H29: 1 | I29: 3.5 | J29: =IF(I29="","",I29-F29) | K29: W | L29: =IF(K29="W",IF(G29<0,H29*100/ABS(G29),H29*G29/100),IF(K29="L",-H29,0)) | M29: =Settings!$B$4+SUM(L$2:L29)
A30: 2026-09-13 | B30: 2 | C30: North Dakota State @ Airforce | D30: Spread | E30: North Dakota State | F30: -2.5 | G30: -112 | H30: 2.5 | I30: 2.5 | J30: =IF(I30="","",I30-F30) | K30: W | L30: =IF(K30="W",IF(G30<0,H30*100/ABS(G30),H30*G30/100),IF(K30="L",-H30,0)) | M30: =Settings!$B$4+SUM(L$2:L30)
A31: 2026-09-13 | B31: 2 | C31: North Dakota State @ Airforce | D31: Moneyline | E31: North Dakota State | G31: -134 | H31: 2.5 | J31: =IF(I31="","",I31-F31) | K31: W | L31: =IF(K31="W",IF(G31<0,H31*100/ABS(G31),H31*G31/100),IF(K31="L",-H31,0)) | M31: =Settings!$B$4+SUM(L$2:L31)
A32: 2026-09-13 | B32: 2 | C32: New Mexico State @ Hawaii | D32: Moneyline | E32: Hawaii | G32: -330 | H32: 1 | J32: =IF(I32="","",I32-F32) | K32: W | L32: =IF(K32="W",IF(G32<0,H32*100/ABS(G32),H32*G32/100),IF(K32="L",-H32,0)) | M32: =Settings!$B$4+SUM(L$2:L32)
A33: 2026-09-12 | B33: 2 | C33: Maryland @ Uconn | D33: Spread | E33: Uconn | F33: 12.5 | G33: -110 | H33: 1 | I33: 13.5 | J33: =IF(I33="","",I33-F33) | K33: L | L33: =IF(K33="W",IF(G33<0,H33*100/ABS(G33),H33*G33/100),IF(K33="L",-H33,0)) | M33: =Settings!$B$4+SUM(L$2:L33)
A34: 2026-09-12 | B34: 2 | C34: Ohio State @ Texas | D34: Moneyline | E34: Texas | G34: 500 | H34: 40 | J34: =IF(I34="","",I34-F34) | K34: W | L34: =IF(K34="W",IF(G34<0,H34*100/ABS(G34),H34*G34/100),IF(K34="L",-H34,0)) | M34: =Settings!$B$4+SUM(L$2:L34)
A35: 2026-09-19 | B35: 3 | C35: Wyoming @ Central Michigan | D35: Spread | E35: Central Michigan | F35: -1.5 | G35: -110 | H35: 1 | I35: -2.5 | J35: =IF(I35="","",I35-F35) | K35: W | L35: =IF(K35="W",IF(G35<0,H35*100/ABS(G35),H35*G35/100),IF(K35="L",-H35,0)) | M35: =Settings!$B$4+SUM(L$2:L35)
A36: 2026-09-19 | B36: 3 | C36: Wyoming @ Central Michigan | D36: Moneyline | E36: Central Michigan | F36: -0.5 | G36: -114 | H36: 1 | J36: =IF(I36="","",I36-F36) | K36: W | L36: =IF(K36="W",IF(G36<0,H36*100/ABS(G36),H36*G36/100),IF(K36="L",-H36,0)) | M36: =Settings!$B$4+SUM(L$2:L36)
A37: 2026-09-19 | B37: 3 | C37: Sacramento State @ North Dakota State | D37: Spread | E37: North Dakota State | F37: -27.5 | G37: -115 | H37: 2 | I37: -27.5 | J37: =IF(I37="","",I37-F37) | K37: L | L37: =IF(K37="W",IF(G37<0,H37*100/ABS(G37),H37*G37/100),IF(K37="L",-H37,0)) | M37: =Settings!$B$4+SUM(L$2:L37)
A38: 2026-09-19 | B38: 3 | C38: SMU @ Louisville | D38: Moneyline | E38: SMU | G38: 134 | H38: 1 | J38: =IF(I38="","",I38-F38) | K38: L | L38: =IF(K38="W",IF(G38<0,H38*100/ABS(G38),H38*G38/100),IF(K38="L",-H38,0)) | M38: =Settings!$B$4+SUM(L$2:L38)
A39: 2026-09-19 | B39: 3 | C39: LSU @ Ole Miss | D39: Moneyline | E39: LSU | G39: 350 | H39: 36 | J39: =IF(I39="","",I39-F39) | K39: L | L39: =IF(K39="W",IF(G39<0,H39*100/ABS(G39),H39*G39/100),IF(K39="L",-H39,0)) | M39: =Settings!$B$4+SUM(L$2:L39)
A40: 2026-09-19 | B40: 3 | C40: Wyoming @ Central Michigan | D40: Spread | E40: Central Michigan | F40: -1.5 | G40: -114 | H40: 2.6 | I40: -2.5 | J40: =IF(I40="","",I40-F40) | K40: W | L40: =IF(K40="W",IF(G40<0,H40*100/ABS(G40),H40*G40/100),IF(K40="L",-H40,0)) | M40: =Settings!$B$4+SUM(L$2:L40)
...

Sheet Team Profiles
A1: Team | B1: Prior Conference | C1: Joined 2026 | D1: Model Power Rating | E1: SP+ Rating | F1: Off PPA | G1: Def PPA | H1: Talent Rank | I1: Notes
A2: North Dakota State | B2: FCS (Missouri Valley Football Conference) | C2: Y | D2: 1726.7 | E2: 9.5 | F2: 0.090495252 | G2: -0.12112384 | H2: 117 | I2: Full MW history available. Option offense; home elevation ~6,621 ft.
A3: UNLV | B3: Mountain West | C3: N | D3: 1613.9 | E3: -3.4 | F3: 0.076724594 | G3: 0.069890451 | H3: 63 | I3: Full history. Travel distance/time-zone is a real situational factor for every road game.
A4: New Mexico | B4: Mountain West | C4: N | D4: 1644.3 | E4: 10.6 | F4: 0.14392698 | G4: -0.1580846 | H4: 87 | I4: Full history available.
A5: Hawai'i | B5: Mountain West | C5: N | D5: 1454.8 | E5: -12.6 | F5: 0.057704936 | G5: 0.1751327 | H5: 124 | I5: Full history. Home elevation ~5,000+ ft.
A6: Air Force | B6: Mountain West | C6: N | D6: 1539.2 | E6: 1.5 | F6: 0.21881209 | G6: 0.064322119 | H6: 141 | I6: Zero FBS history — historically dominant FCS program. Pull its FCS-era schedule separately (see pull_ndsu_games() in pull_games.py) since a plain division='fbs' query will not surface it before 2026. Likely market-mispricing candidate in year one since books/public have thin FBS-level reference data on it.
A7: Wyoming | B7: Mountain West | C7: N | D7: 1487.6 | E7: -9.3 | F7: 0.12584558 | G7: 0.12928652 | H7: 114 | I7: No MW history; bring its full MAC-era game log (already FBS, so it's in a plain division='fbs' pull).
A8: Northern Illinois | B8: MAC | C8: Y | D8: 1294.5 | E8: -25 | F8: -0.053656068 | G8: 0.24673033 | H8: 82 | I8: Full history available. Watch for 'San Jose State' (no accent) in some sources — same team.
A9: San José State | B9: Mountain West | C9: N | D9: 1427 | E9: -9.3 | F9: 0.098488187 | G9: 0.065723405 | H9: 129 | I9: Full history available.
A10: Nevada | B10: Mountain West | C10: N | D10: 1433.1 | E10: -4.6 | F10: 0.071141873 | G10: 0.09697439 | H10: 98 | I10: No MW history; bring its full C-USA-era game log (already FBS).
A11: UTEP | B11: Conference USA | C11: Y | D11: 1280.7 | E11: -24.6 | F11: -0.10790222 | G11: 0.2499178 | H11: 92 | I11: Full history. Home elevation ~7,220 ft — coldest, highest venue in the league.

Sheet Power Ratings
A1: Team | B1: Week 1 | C1: Week 2 | D1: Week 3 | E1: Week 4 | F1: Week 5 | G1: Week 6 | H1: Week 7 | I1: Week 8 | V1: Matchup Spread Calculator
A2: Ohio State | B2: 93.4 | C2: 92.4 | D2: 90.8 | E2: 91.1 | F2: 91.6 | G2: 91.1 | H2: 92.1 | I2: 92.1
A3: Indiana | B3: 97 | C3: 94.1 | D3: 93.1 | E3: 91.6 | F3: 90.4 | G3: 89 | H3: 88 | I3: 87.1 | V3: Home Team | W3: Delaware
A4: Miami | B4: 89.9 | C4: 87.5 | D4: 86.1 | E4: 85.7 | F4: 86.7 | G4: 86.8 | H4: 85.7 | I4: 86.6 | V4: Away Team | W4: Liberty
A5: Georgia | B5: 83.5 | C5: 83.6 | D5: 84.7 | E5: 86.9 | F5: 87.6 | G5: 87.6 | H5: 85.7 | I5: 85.7 | V5: Neutral Site? (Y/N) | W5: N
A6: Notre Dame | B6: 88.5 | C6: 87.1 | D6: 86.8 | E6: 86.5 | F6: 85.1 | G6: 85.4 | H6: 84 | I6: 84
A7: Ole Miss | B7: 84.9 | C7: 83.6 | D7: 84.1 | E7: 80.5 | F7: 80.5 | G7: 82.2 | H7: 84.6 | I7: 83.7 | V7: HFA (model constant) | W7: 2.7
A8: Texas | B8: 85.1 | C8: 86 | D8: 86.4 | E8: 85.9 | F8: 85.9 | G8: 84.7 | H8: 82.6 | I8: 83.6
A9: Alabama | B9: 80.9 | C9: 82.3 | D9: 82.2 | E9: 83.3 | F9: 85 | G9: 85 | H9: 82.7 | I9: 83.3 | V9: Predicted Spread (Home) | W9: =IF(OR(W3="",W4=""),"",INDEX($I$2:$I$139,MATCH(W4,$A$2:$A$139,0))-INDEX($I$2:$I$139,MATCH(W3,$A$2:$A$139,0))-IF(UPPER(W5)="Y",0,W7))
A10: LSU | B10: 79.1 | C10: 79.8 | D10: 79.4 | E10: 82.2 | F10: 80.4 | G10: 79.5 | H10: 80.8 | I10: 82.4 | V10: (negative = home team favored, e.g. "Home -6.5")
A11: Utah | B11: 81.6 | C11: 83 | D11: 83.7 | E11: 83.7 | F11: 83.7 | G11: 83.3 | H11: 81.3 | I11: 81
A12: Texas Tech | B12: 87.3 | C12: 85.1 | D12: 83.9 | E12: 82.6 | F12: 82.5 | G12: 82.5 | H12: 83.7 | I12: 80.7
A13: Arizona | B13: 73.4 | C13: 72.8 | D13: 72.4 | E13: 72.6 | F13: 75.6 | G13: 76.8 | H13: 76.8 | I13: 79.2
A14: Oregon | B14: 86.9 | C14: 82.6 | D14: 81.2 | E14: 81.9 | F14: 81.9 | G14: 81.1 | H14: 81.2 | I14: 79.1
A15: Tennessee | B15: 76.8 | C15: 77.9 | D15: 78.4 | E15: 78.9 | F15: 79.2 | G15: 78.4 | H15: 80.7 | I15: 79
A16: South Carolina | B16: 75.1 | C16: 75.7 | D16: 75.1 | E16: 74 | F16: 74.2 | G16: 77.1 | H16: 77.1 | I16: 78.8
A17: Iowa | B17: 81.2 | C17: 80.2 | D17: 79 | E17: 78.7 | F17: 78.3 | G17: 79.7 | H17: 79.7 | I17: 78.2
A18: BYU | B18: 78.3 | C18: 78.9 | D18: 78.1 | E18: 78.1 | F18: 77.7 | G18: 78.5 | H18: 79.9 | I18: 77.6
A19: Texas A&M | B19: 82.8 | C19: 84.2 | D19: 81.6 | E19: 78.8 | F19: 80.6 | G19: 78.2 | H19: 77.8 | I19: 77.1
A20: Wake Forest | B20: 71 | C20: 69.8 | D20: 71.3 | E20: 72.1 | F20: 73.8 | G20: 75.6 | H20: 76.7 | I20: 76.7
A21: Nebraska | B21: 72.1 | C21: 72.6 | D21: 72.5 | E21: 73.7 | F21: 75.2 | G21: 76.7 | H21: 76.5 | I21: 76.6
A22: Louisville | B22: 74.7 | C22: 74.9 | D22: 75.6 | E22: 74.7 | F22: 74.6 | G22: 77.7 | H22: 76.3 | I22: 76.3
... A139: Sacramento State | B139: 41 | C139: 39.8 | D139: 41.5 | E139: 38.8 | F139: 38.8 | G139: 37 | H139: 36.6 | I139: 35.5

Sheet MW Team ATS
A1: MW Team ATS -- 2026 Season (graded vs. the real market line, not any model)
A3: Team | B3: ATS Record (C-L-P) | C3: Cover %
A4: Air Force | B4: 4-3-0 | C4: 0.571
A5: Hawai'i | B5: 4-4-0 | C5: 0.5
A6: Nevada | B6: 5-2-0 | C6: 0.714
A7: New Mexico | B7: 6-1-0 | C7: 0.857
A8: North Dakota State | B8: 3-5-0 | C8: 0.375
A9: Northern Illinois | B9: 1-6-0 | C9: 0.143
A10: San José State | B10: 4-4-0 | C10: 0.5
A11: UNLV | B11: 4-3-0 | C11: 0.571
A12: UTEP | B12: 1-6-0 | C12: 0.143
A13: Wyoming | B13: 4-4-0 | C13: 0.5
A16: Team | B16: Week | C16: Date | D16: Opponent | E16: Site | F16: Team's Spread | G16: Result (Margin) | H16: ATS Result | I16: Cover Margin
A17: Air Force | B17: 1 | C17: 2026-09-05 | D17: Duquesne | E17: Home | F17: -30 | G17: 34 | H17: Cover | I17: 4
A18: Air Force | B18: 2 | C18: 2026-09-13 | D18: North Dakota State | E18: Home | F18: 1.8 | G18: -6 | H18: No Cover | I18: -4.2
A19: Air Force | B19: 4 | C19: 2026-09-27 | D19: Nevada | E19: Away | F19: -5.2 | G19: 3 | H19: No Cover | I19: -2.2
A20: Air Force | B20: 5 | C20: 2026-10-03 | D20: Navy | E20: Home | F20: -2.8 | G20: 5 | H20: Cover | I20: 2.2
A21: Air Force | B21: 6 | C21: 2026-10-10 | D21: Northern Illinois | E21: Away | F21: -7 | G21: 21 | H21: Cover | I21: 14
A22: Air Force | B22: 7 | C22: 2026-10-17 | D22: UNLV | E22: Home | F22: -0.2 | G22: 10 | H22: Cover | I22: 9.8
A23: Air Force | B23: 8 | C23: 2026-10-24 | D23: Wyoming | E23: Away | F23: -7 | G23: -14 | H23: No Cover | I23: -21
A24: Hawai'i | B24: 1 | C24: 2026-08-29 | D24: Stanford | E24: Away | F24: 4.8 | G24: -10 | H24: No Cover | I24: -5.2
A25: Hawai'i | B25: 1 | C25: 2026-09-06 | D25: UNLV | E25: Home | F25: 2.8 | G25: -15 | H25: No Cover | I25: -12.2
A26: Hawai'i | B26: 2 | C26: 2026-09-13 | D26: New Mexico State | E26: Home | F26: -7.5 | G26: 10 | H26: Cover | I26: 2.5
A27: Hawai'i | B27: 4 | C27: 2026-09-26 | D27: Wyoming | E27: Away | F27: -2.2 | G27: -17 | H27: No Cover | I27: -19.2
A28: Hawai'i | B28: 5 | C28: 2026-10-04 | D28: San José State | E28: Home | F28: -2.8 | G28: -4 | H28: No Cover | I28: -6.8
... A90: Wyoming | B90: 8 | C90: 2026-10-24 | D90: Air Force | E90: Home | F90: 7 | G90: 14 | H90: Cover | I90: 21

Sheet Strength of Record
A1: Strength of Record -- 2026 Season (resets every season -- see column notes below)
A3: SOR = wins above what an exactly-average FBS team would've earned against this exact schedule. Rank Gap = Elo Rank minus SOR Rank -- a big positive number means the Elo rating (no preseason blend, so it's all this season's results) is running ahead of what the resume actually supports.
A5: Team | B5: W-L (FBS) | C5: SOR | D5: SOR Rank | E5: Elo Rating | F5: Elo Rank | G5: Rank Gap (Elo - SOR)
A6: UCLA | B6: 7-0 | C6: 3.7 | D6: 1 | E6: 1629.2 | F6: 38 | G6: 37
A7: Kentucky | B7: 6-1 | C7: 3.56 | D7: 2 | E7: 1634.9 | F7: 36 | G7: 34
A8: Indiana | B8: 6-1 | C8: 3.44 | D8: 3 | E8: 1849.2 | F8: 2 | G8: -1
A9: Miami | B9: 6-0 | C9: 3.38 | D9: 4 | E9: 1824.3 | F9: 3 | G9: -1
A10: UTSA | B10: 6-1 | C10: 3.19 | D10: 5 | E10: 1682.9 | F10: 21 | G10: 16
A11: Utah | B11: 6-0 | C11: 3.11 | D11: 6 | E11: 1774.3 | F11: 6 | G11: 0
A12: Ohio State | B12: 6-1 | C12: 3.03 | D12: 7 | E12: 1855.8 | F12: 1 | G12: -6
A13: Alabama | B13: 6-2 | C13: 3.03 | D13: 8 | E13: 1750.7 | F13: 10 | G13: 2
A14: Wake Forest | B14: 6-1 | C14: 2.99 | D14: 9 | E14: 1658.8 | F14: 27 | G14: 18
A15: Boise State | B15: 5-1 | C15: 2.87 | D15: 10 | E15: 1720 | F15: 15 | G15: 5
A16: BYU | B16: 5-1 | C16: 2.83 | D16: 11 | E16: 1742.3 | F16: 12 | G16: 1
A17: James Madison | B17: 6-1 | C17: 2.79 | D17: 12 | E17: 1764.1 | F17: 8 | G17: -4
... A241: Sacramento State | B241: 0-7 | C241: -3.44 | D241: 236 | E241: 1335.8 | F241: 246 | G241: 10

Sheet National Slate
A1: National Model ATS Record
A2: Metric | B2: Record (W-L-P) | C2: ATS %
A3: Rolling ATS (Season) | B3: 296-263-7 | C3: 0.53
A4: Weekly ATS (Wk 8) | B4: 25-31-0 | C4: 0.446
A5: Model pick W-L, straight-up (Wk 8) | B5: 31-25 | C5: 0.554
A7: Week 9
A8: Week | B8: Date | C8: Home Conf | D8: Away Conf | E8: Away Team | F8: Home Team | G8: Model Line (Home) | H8: Market Line (Home) | I8: Spread Edge (pts) | J8: Ridge Line (Home) | K8: Massey Line (Home) | L8: Model Total | M8: Market Total | N8: Total Edge (pts) | O8: Away Pts | P8: Home Pts | Q8: Model Result (SU) | R8: XGBoost Line (Home) | S8: Gamma ATS | T8: Ridge ATS | U8: XGBoost ATS | V8: Massey ATS
A9: 9 | B9: 2026-10-31 | C9: ACC | D9: ACC | E9: Boston College | F9: Duke | G9: -14.4 | H9: -7 | I9: 7.4 | J9: -11.3 | K9: -9.8 | L9: 51.3 | M9: 49.5 | N9: 1.8 | R9: -12.3
A10: 9 | B10: 2026-10-31 | C10: ACC | D10: ACC | E10: Clemson | F10: Florida State | G10: -4.9 | H10: -6 | I10: -1.1 | J10: 2.2 | K10: -8 | L10: 46 | M10: 49.5 | N10: -3.5 | R10: 0.9
A11: 9 | B11: 2026-10-31 | C11: ACC | D11: ACC | E11: Stanford | F11: Louisville | G11: -19.6 | H11: -22.5 | I11: -2.9 | J11: -14.9 | K11: -23.4 | L11: 56.2 | M11: 61.5 | N11: -5.3 | R11: -18
A12: 9 | B12: 2026-10-31 | C12: ACC | D12: ACC | E12: California | F12: NC State | G12: -11.5 | H12: -8.5 | I12: 3 | J12: -9 | K12: -9.7 | L12: 51.3 | M12: 57.5 | N12: -6.2 | R12: -10.2
A13: 9 | B13: 2026-10-31 | C13: ACC | D13: ACC | E13: Miami | F13: North Carolina | G13: 18.7 | H13: 14.5 | I13: -4.2 | J13: 18 | K13: 15.5 | L13: 48.9 | M13: 52.5 | N13: -3.6 | R13: 16.9
A14: 9 | B14: 2026-10-31 | C14: ACC | D14: ACC | E14: Georgia Tech | F14: Pittsburgh | G14: -11 | H14: -7.5 | I14: 3.5 | J14: -10.6 | K14: -17.8 | L14: 52.8 | M14: 53.5 | N14: -0.7 | R14: -6.9
A15: 9 | B15: 2026-10-31 | C15: ACC | D15: ACC | E15: SMU | F15: Syracuse | G15: 10.5 | H15: 8.5 | I15: -2 | J15: 12.8 | K15: 1.8 | L15: 49.3 | M15: 58.5 | N15: -9.2 | R15: 15.9
A16: 9 | B16: 2026-10-31 | C16: ACC | D16: ACC | E16: Virginia | F16: Wake Forest | G16: -9.5 | H16: -14 | I16: -4.5 | J16: -11.2 | K16: -11 | L16: 51.2 | M16: 49.5 | N16: 1.7 | R16: -9.2
A17: 9 | B17: 2026-10-29 | C17: American Athletic | D17: American Athletic | E17: Florida Atlantic | F17: North Texas | G17: -15.3 | H17: -13.5 | I17: 1.8 | J17: -8.4 | K17: -13.2 | L17: 63.9 | M17: 73.5 | N17: -9.6 | R17: -13.2
A18: 9 | B18: 2026-10-30 | C18: American Athletic | D18: American Athletic | E18: Tulane | F18: Charlotte | G18: 14 | H18: 10.5 | I18: -3.5 | J18: 15.7 | K18: 10.8 | L18: 50.9 | M18: 46.5 | N18: 4.4 | R18: 14.2
A19: 9 | B19: 2026-10-31 | C19: American Athletic | D19: American Athletic | E19: Temple | F19: East Carolina | G19: -9.2 | H19: -5.5 | I19: 3.7 | J19: -11.1 | K19: -3.7 | L19: 51.4 | M19: 50.5 | N19: 0.9 | R19: -8
A20: 9 | B20: 2026-10-31 | C20: American Athletic | D20: FBS Independents | E20: Notre Dame | F20: Navy | G20: 20 | H20: 29.5 | I20: 9.5 | J20: 23.7 | K20: 23.7 | L20: 55.8 | M20: 54.5 | N20: 1.3 | R20: 20.1
... A64: 9 | B64: 2026-10-31 | C64: Sun Belt | D64: Sun Belt | E64: Southern Miss | F64: UL Monroe | G64: 6.3 | H64: 3 | I64: -3.3 | J64: 5.3 | K64: 4.3 | L64: 52.6 | M64: 53.5 | N64: -0.9 | R64: 8
A66: Week 8
A67: Week | B67: Date | C67: Home Conf | D67: Away Conf | E67: Away Team | F67: Home Team | G67: Model Line (Home) | H67: Market Line (Home) | I67: Spread Edge (pts) | J67: Ridge Line (Home) | K67: Massey Line (Home) | L67: Model Total | M67: Market Total | N67: Total Edge (pts) | O67: Away Pts | P67: Home Pts | Q67: Model Result (SU) | R67: XGBoost Line (Home) | S67: Gamma ATS | T67: Ridge ATS | U67: XGBoost ATS | V67: Massey ATS
A68: 8 | B68: 2026-10-23 | C68: ACC | D68: ACC | E68: Duke | F68: Virginia | G68: 1.1 | H68: -2.5 | I68: -3.6 | J68: 4 | K68: -1 | L68: 52 | M68: 46.8 | N68: 5.3 | O68: 19 | P68: 16 | Q68: Win | R68: 5 | S68: Win | T68: Win | U68: Win | V68: Win
A69: 8 | B69: 2026-10-24 | C69: ACC | D69: ACC | E69: Virginia Tech | F69: Clemson | G69: -3.1 | H69: -2.5 | I69: 0.6 | J69: -6 | K69: 2.4 | L69: 45.1 | M69: 49.2 | N69: -4.1 | O69: 20 | P69: 16 | Q69: Loss | R69: -9.1 | S69: Loss | T69: Loss | U69: Loss | V69: Win
A70: 8 | B70: 2026-10-24 | C70: ACC | D70: ACC | E70: Boston College | F70: Georgia Tech | G70: -9.4 | H70: -6 | I70: 3.4 | J70: -5.6 | K70: -3.6 | L70: 50.9 | M70: 50.2 | N70: 0.6 | O70: 49 | P70: 27 | Q70: Loss | R70: -7.1 | S70: Loss | T70: Loss | U70: Loss | V70: Win
A71: 8 | B71: 2026-10-24 | C71: ACC | D71: ACC | E71: Pittsburgh | F71: Miami | G71: -23 | H71: -19.8 | I71: 3.2 | J71: -20.6 | K71: -14.3 | L71: 51.7 | M71: 48.8 | N71: 3 | O71: 23 | P71: 52 | Q71: Win | R71: -15.3 | S71: Win | T71: Win | U71: Loss | V71: Loss
A72: 8 | B72: 2026-10-24 | C72: ACC | D72: ACC | E72: Syracuse | F72: North Carolina | G72: -11.2 | H72: -9.2 | I72: 2 | J72: -8.7 | K72: -6.7 | L72: 44.4 | M72: 47.2 | N72: -2.8 | O72: 31 | P72: 30 | Q72: Loss | R72: -7.6 | S72: Loss | T72: Loss | U72: Win | V72: Win
A73: 8 | B73: 2026-10-24 | C73: ACC | D73: ACC | E73: California | F73: SMU | G73: -20.8 | H73: -19.2 | I73: 1.6 | J73: -19.2 | K73: -12 | L73: 49.5 | M73: 55.2 | N73: -5.8 | O73: 20 | P73: 59 | Q73: Win | R73: -15.8 | S73: Win | T73: Win | U73: Loss | V73: Loss
A74: 8 | B74: 2026-10-24 | C74: ACC | D74: ACC | E74: NC State | F74: Stanford | G74: 0.6 | H74: 7.5 | I74: 6.9 | J74: 4.5 | K74: 10.6 | L74: 55.2 | M74: 55.2 | N74: 0 | O74: 28 | P74: 31 | Q74: Loss | R74: 3.1 | S74: Win | T74: Win | U74: Win | V74: Loss
A75: 8 | B75: 2026-10-22 | C75: American Athletic | D75: American Athletic | E75: East Carolina | F75: Memphis | G75: -5.8 | H75: -10.5 | I75: -4.7 | J75: -7.2 | K75: -12.7 | L75: 49.1 | M75: 55.5 | N75: -6.4 | O75: 34 | P75: 41 | Q75: Win | R75: -5.3 | S75: Win | T75: Win | U75: Win | V75: Loss
A76: 8 | B76: 2026-10-24 | C76: American Athletic | D76: American Athletic | E76: Rice | F76: Florida Atlantic | G76: -9 | H76: -8.5 | I76: 0.5 | J76: -10.1 | K76: -10.5 | L76: 55.2 | M76: 53.8 | N76: 1.5 | O76: 49 | P76: 51 | Q76: Win | R76: -8.9 | S76: Loss | T76: Loss | U76: Loss | V76: Loss
A77: 8 | B77: 2026-10-24 | C77: American Athletic | D77: American Athletic | E77: North Texas | F77: Navy | G77: -5.8 | H77: 3 | I77: 8.8 | J77: 2.2 | K77: 4.7 | L77: 60.7 | M77: 62.2 | N77: -1.6 | O77: 49 | P77: 39 | Q77: Loss | R77: -0.6 | S77: Loss | T77: Win | U77: Loss | V77: Win
A78: 8 | B78: 2026-10-24 | C78: American Athletic | D78: American Athletic | E78: Army | F78: Tulsa | G78: 3.2 | H78: -1.2 | I78: -4.4 | J78: 2.4 | K78: 1.8 | L78: 56.2 | M78: 52.8 | N78: 3.4 | O78: 38 | P78: 35 | Q78: Win | R78: 7.9 | S78: Win | T78: Win | U78: Win | V78: Win
A79: 8 | B79: 2026-10-25 | C79: American Athletic | D79: American Athletic | E79: UTSA | F79: Tulane | G79: -1.4 | H79: 3 | I79: 4.4 | J79: 0.8 | K79: -1.1 | L79: 55.2 | M79: 51.5 | N79: 3.7 | O79: 42 | P79: 19 | Q79: Loss | R79: 0 | S79: Loss | T79: Loss | U79: Loss | V79: Loss
... A123: 8 | B123: 2026-10-24 | C123: Sun Belt | D123: Sun Belt | E123: UL Monroe | F123: Troy | G123: -13.9 | H123: -12.2 | I123: 1.7 | J123: -21.4 | K123: -16.3 | L123: 50.4 | M123: 50.2 | N123: 0.1 | O123: 21 | P123: 14 | Q123: Loss | R123: -16.4 | S123: Loss | T123: Loss | U123: Loss | V123: Loss
A125: Week 7
A126: Week | B126: Date | C126: Home Conf | D126: Away Conf | E126: Away Team | F126: Home Team | G126: Model Line (Home) | H126: Market Line (Home) | I126: Spread Edge (pts) | J126: Ridge Line (Home) | K126: Massey Line (Home) | L126: Model Total | M126: Market Total | N126: Total Edge (pts) | O126: Away Pts | P126: Home Pts | Q126: Model Result (SU) | R126: XGBoost Line (Home) | S126: Gamma ATS | T126: Ridge ATS | U126: XGBoost ATS | V126: Massey ATS
A127: 7 | B127: 2026-10-17 | C127: ACC | D127: ACC | E127: Pittsburgh | F127: Boston College | G127: 7.7 | H127: 6.2 | I127: -1.5 | J127: 10 | K127: 17.1 | L127: 46.8 | M127: 42.5 | N127: 4.3 | O127: 21 | P127: 27 | Q127: Loss | R127: 10.8 | S127: Loss | T127: Loss | U127: Loss | V127: Loss
A128: 7 | B128: 2026-10-17 | C128: ACC | D128: OVC | E128: Charleston Southern | F128: Clemson | G128: -45.1 | J128: -26.8 | K128: -15.6 | L128: 56.5 | O128: 0 | P128: 37 | Q128: Win | R128: -35.9
A129: 7 | B129: 2026-10-17 | C129: ACC | D129: ACC | E129: North Carolina | F129: Duke | G129: -13.1 | H129: -3 | I129: 10.1 | J129: -9.2 | K129: -3 | L129: 50.3 | M129: 47.5 | N129: 2.8 | O129: 24 | P129: 20 | Q129: Loss | R129: -7.1 | S129: Loss | T129: Loss | U129: Loss | V129: Loss
...

Sheet ACC Slate
A1: ACC Model ATS Record
A2: Metric | B2: Record (W-L-P) | C2: ATS %
A3: Rolling ATS (Season) | B3: 45-38-2 | C3: 0.542
A4: Weekly ATS (Wk 8) | B4: 4-3-0 | C4: 0.571
A5: Model pick W-L, straight-up (Wk 8) | B5: 3-4 | C5: 0.429
A7: ACC Standings
A8: Team | B8: Conf W | C8: Conf L | D8: Conf Pct | E8: Overall W | F8: Overall L
A9: Miami | B9: 5 | C9: 0 | D9: 1 | E9: 7 | F9: 0
A10: SMU | B10: 4 | C10: 1 | D10: 0.8 | E10: 6 | F10: 1
A11: Wake Forest | B11: 4 | C11: 1 | D11: 0.8 | E11: 6 | F11: 1
A12: Virginia Tech | B12: 3 | C12: 2 | D12: 0.6 | E12: 6 | F12: 2
A13: Louisville | B13: 3 | C13: 2 | D13: 0.6 | E13: 4 | F13: 3
A14: Duke | B14: 2 | C14: 2 | D14: 0.5 | E14: 5 | F14: 2
A15: Boston College | B15: 2 | C15: 2 | D15: 0.5 | E15: 4 | F15: 3
A16: Clemson | B16: 2 | C16: 2 | D16: 0.5 | E16: 4 | F16: 3
A17: North Carolina | B17: 2 | C17: 2 | D17: 0.5 | E17: 4 | F17: 3
A18: Pittsburgh | B18: 2 | C18: 3 | D18: 0.4 | E18: 5 | F18: 3
A19: Stanford | B19: 2 | C19: 3 | D19: 0.4 | E19: 4 | F19: 4
A20: Virginia | B20: 2 | C20: 3 | D20: 0.4 | E20: 4 | F20: 4
... A25: Syracuse | B25: 1 | C25: 4 | D25: 0.2 | E25: 3 | F25: 4
A27: Week 9
A28: Week | B28: Date | C28: Home Conf | D28: Away Conf | E28: Away Team | F28: Home Team | G28: Model Line (Home) | H28: Market Line (Home) | I28: Spread Edge (pts) | J28: Ridge Line (Home) | K28: Massey Line (Home) | L28: Model Total | M28: Market Total | N28: Total Edge (pts) | O28: Away Pts | P28: Home Pts | Q28: Model Result (SU) | R28: XGBoost Line (Home) | S28: Gamma ATS | T28: Ridge ATS | U28: XGBoost ATS | V28: Massey ATS
A29: 9 | B29: 2026-10-31 | C29: ACC | D29: ACC | E29: Boston College | F29: Duke | G29: -14.4 | H29: -7 | I29: 7.4 | J29: -11.3 | K29: -9.8 | L29: 51.3 | M29: 49.5 | N29: 1.8 | R29: -12.3
A30: 9 | B30: 2026-10-31 | C30: ACC | D30: ACC | E30: Clemson | F30: Florida State | G30: -4.9 | H30: -6 | I30: -1.1 | J30: 2.2 | K30: -8 | L30: 46 | M30: 49.5 | N30: -3.5 | R30: 0.9
A31: 9 | B31: 2026-10-31 | C31: ACC | D31: ACC | E31: Stanford | F31: Louisville | G31: -19.6 | H31: -22.5 | I31: -2.9 | J31: -14.9 | K31: -23.4 | L31: 56.2 | M31: 61.5 | N31: -5.3 | R31: -18
A32: 9 | B32: 2026-10-31 | C32: ACC | D32: ACC | E32: California | F32: NC State | G32: -11.5 | H32: -8.5 | I32: 3 | J32: -9 | K32: -9.7 | L32: 51.3 | M32: 57.5 | N32: -6.2 | R32: -10.2
A33: 9 | B33: 2026-10-31 | C33: ACC | D33: ACC | E33: Miami | F33: North Carolina | G33: 18.7 | H33: 14.5 | I33: -4.2 | J33: 18 | K33: 15.5 | L33: 48.9 | M33: 52.5 | N33: -3.6 | R33: 16.9
A34: 9 | B34: 2026-10-31 | C34: ACC | D34: ACC | E34: Georgia Tech | F34: Pittsburgh | G34: -11 | H34: -7.5 | I34: 3.5 | J34: -10.6 | K34: -17.8 | L34: 52.8 | M34: 53.5 | N34: -0.7 | R34: -6.9
A35: 9 | B35: 2026-10-31 | C35: ACC | D35: ACC | E35: SMU | F35: Syracuse | G35: 10.5 | H35: 8.5 | I35: -2 | J35: 12.8 | K35: 1.8 | L35: 49.3 | M35: 58.5 | N35: -9.2 | R35: 15.9
A36: 9 | B36: 2026-10-31 | C36: ACC | D36: ACC | E36: Virginia | F36: Wake Forest | G36: -9.5 | H36: -14 | I36: -4.5 | J36: -11.2 | K36: -11 | L36: 51.2 | M36: 49.5 | N36: 1.7 | R36: -9.2
A38: Week 8
A39: Week | B39: Date | C39: Home Conf | D39: Away Conf | E39: Away Team | F39: Home Team | G39: Model Line (Home) | H39: Market Line (Home) | I39: Spread Edge (pts) | J39: Ridge Line (Home) | K39: Massey Line (Home) | L39: Model Total | M39: Market Total | N39: Total Edge (pts) | O39: Away Pts | P39: Home Pts | Q39: Model Result (SU) | R39: XGBoost Line (Home) | S39: Gamma ATS | T39: Ridge ATS | U39: XGBoost ATS | V39: Massey ATS
A40: 8 | B40: 2026-10-23 | C40: ACC | D40: ACC | E40: Duke | F40: Virginia | G40: 1.1 | H40: -2.5 | I40: -3.6 | J40: 4 | K40: -1 | L40: 52 | M40: 46.8 | N40: 5.3 | O40: 19 | P40: 16 | Q40: Win | R40: 5 | S40: Win | T40: Win | U40: Win | V40: Win
A41: 8 | B41: 2026-10-24 | C41: ACC | D41: ACC | E41: Virginia Tech | F41: Clemson | G41: -3.1 | H41: -2.5 | I41: 0.6 | J41: -6 | K41: 2.4 | L41: 45.1 | M41: 49.2 | N41: -4.1 | O41: 20 | P41: 16 | Q41: Loss | R41: -9.1 | S41: Loss | T41: Loss | U41: Loss | V41: Win
A42: 8 | B42: 2026-10-24 | C42: ACC | D42: ACC | E42: Boston College | F42: Georgia Tech | G42: -9.4 | H42: -6 | I42: 3.4 | J42: -5.6 | K42: -3.6 | L42: 50.9 | M42: 50.2 | N42: 0.6 | O42: 49 | P42: 27 | Q42: Loss | R42: -7.1 | S42: Loss | T42: Loss | U42: Loss | V42: Win
A43: 8 | B43: 2026-10-24 | C43: ACC | D43: ACC | E43: Pittsburgh | F43: Miami | G43: -23 | H43: -19.8 | I43: 3.2 | J43: -20.6 | K43: -14.3 | L43: 51.7 | M43: 48.8 | N43: 3 | O43: 23 | P43: 52 | Q43: Win | R43: -15.3 | S43: Win | T43: Win | U43: Loss | V43: Loss
A44: 8 | B44: 2026-10-24 | C44: ACC | D44: ACC | E44: Syracuse | F44: North Carolina | G44: -11.2 | H44: -9.2 | I44: 2 | J44: -8.7 | K44: -6.7 | L44: 44.4 | M44: 47.2 | N44: -2.8 | O44: 31 | P44: 30 | Q44: Loss | R44: -7.6 | S44: Loss | T44: Loss | U44: Win | V44: Win
A45: 8 | B45: 2026-10-24 | C45: ACC | D45: ACC | E45: California | F45: SMU | G45: -20.8 | H45: -19.2 | I45: 1.6 | J45: -19.2 | K45: -12 | L45: 49.5 | M45: 55.2 | N45: -5.8 | O45: 20 | P45: 59 | Q45: Win | R45: -15.8 | S45: Win | T45: Win | U45: Loss | V45: Loss
A46: 8 | B46: 2026-10-24 | C46: ACC | D46: ACC | E46: NC State | F46: Stanford | G46: 0.6 | H46: 7.5 | I46: 6.9 | J46: 4.5 | K46: 10.6 | L46: 55.2 | M46: 55.2 | N46: 0 | O46: 28 | P46: 31 | Q46: Loss | R46: 3.1 | S46: Win | T46: Win | U46: Win | V46: Loss
A48: Week 7
...

Sheet American Athletic Slate
A1: American Athletic Model ATS Record
A2: Metric | B2: Record (W-L-P) | C2: ATS %
A3: Rolling ATS (Season) | B3: 38-37-2 | C3: 0.507
A4: Weekly ATS (Wk 8) | B4: 2-3-0 | C4: 0.4
A5: Model pick W-L, straight-up (Wk 8) | B5: 3-2 | C5: 0.6
A7: American Athletic Standings
A8: Team | B8: Conf W | C8: Conf L | D8: Conf Pct | E8: Overall W | F8: Overall L
A9: UTSA | B9: 4 | C9: 0 | D9: 1 | E9: 7 | F9: 1
A10: North Texas | B10: 3 | C10: 0 | D10: 1 | E10: 5 | F10: 2
A11: Army | B11: 4 | C11: 1 | D11: 0.8 | E11: 5 | F11: 2
A12: Memphis | B12: 3 | C12: 1 | D12: 0.75 | E12: 6 | F12: 2
A13: Florida Atlantic | B13: 2 | C13: 1 | D13: 0.667 | E13: 5 | F13: 2
A14: UAB | B14: 2 | C14: 1 | D14: 0.667 | E14: 4 | F14: 3
A15: South Florida | B15: 1 | C15: 2 | D15: 0.333 | E15: 5 | F15: 2
A16: East Carolina | B16: 1 | C16: 2 | D16: 0.333 | E16: 3 | F16: 4
A17: Tulane | B17: 1 | C17: 2 | D17: 0.333 | E17: 3 | F17: 4
A18: Temple | B18: 1 | C18: 2 | D18: 0.333 | E18: 2 | F18: 5
A19: Charlotte | B19: 1 | C19: 2 | D19: 0.333 | E19: 1 | F19: 6
A20: Tulsa | B20: 1 | C20: 3 | D20: 0.25 | E20: 4 | F20: 4
... A22: Rice | B22: 0 | C22: 4 | D22: 0 | E22: 1 | F22: 7
A24: Week 9
A25: Week | B25: Date | C25: Home Conf | D25: Away Conf | E25: Away Team | F25: Home Team | G25: Model Line (Home) | H25: Market Line (Home) | I25: Spread Edge (pts) | J25: Ridge Line (Home) | K25: Massey Line (Home) | L25: Model Total | M25: Market Total | N25: Total Edge (pts) | O25: Away Pts | P25: Home Pts | Q25: Model Result (SU) | R25: XGBoost Line (Home) | S25: Gamma ATS | T25: Ridge ATS | U25: XGBoost ATS | V25: Massey ATS
A26: 9 | B26: 2026-10-29 | C26: American Athletic | D26: American Athletic | E26: Florida Atlantic | F26: North Texas | G26: -15.3 | H26: -13.5 | I26: 1.8 | J26: -8.4 | K26: -13.2 | L26: 63.9 | M26: 73.5 | N26: -9.6 | R26: -13.2
A27: 9 | B27: 2026-10-30 | C27: American Athletic | D27: American Athletic | E27: Tulane | F27: Charlotte | G27: 14 | H27: 10.5 | I27: -3.5 | J27: 15.7 | K27: 10.8 | L27: 50.9 | M27: 46.5 | N27: 4.4 | R27: 14.2
A28: 9 | B28: 2026-10-31 | C28: American Athletic | D28: American Athletic | E28: Temple | F28: East Carolina | G28: -9.2 | H28: -5.5 | I28: 3.7 | J28: -11.1 | K28: -3.7 | L28: 51.4 | M28: 50.5 | N28: 0.9 | R28: -8
A29: 9 | B29: 2026-10-31 | C29: American Athletic | D29: FBS Independents | E29: Notre Dame | F29: Navy | G29: 20 | H29: 29.5 | I29: 9.5 | J29: 23.7 | K29: 23.7 | L29: 55.8 | M29: 54.5 | N29: 1.3 | R29: 20.1
A30: 9 | B30: 2026-10-31 | C30: American Athletic | D30: American Athletic | E30: UAB | F30: South Florida | G30: -13.7 | H30: -7.5 | I30: 6.2 | J30: -8.3 | K30: -10.4 | L30: 50.9 | M30: 41.5 | N30: 9.4 | R30: -8.1
A31: 9 | B31: 2026-11-01 | C31: American Athletic | D31: American Athletic | E31: Army | F31: Memphis | G31: -4.6 | H31: -6.5 | I31: -1.9 | J31: -7 | K31: -1.1 | L31: 57.6 | M31: 58.5 | N31: -0.9 | R31: -5.6
A33: Week 8
A34: Week | B34: Date | C34: Home Conf | D34: Away Conf | E34: Away Team | F34: Home Team | G34: Model Line (Home) | H34: Market Line (Home) | I34: Spread Edge (pts) | J34: Ridge Line (Home) | K34: Massey Line (Home) | L34: Model Total | M34: Market Total | N34: Total Edge (pts) | O34: Away Pts | P34: Home Pts | Q34: Model Result (SU) | R34: XGBoost Line (Home) | S34: Gamma ATS | T34: Ridge ATS | U34: XGBoost ATS | V34: Massey ATS
A35: 8 | B35: 2026-10-22 | C35: American Athletic | D35: American Athletic | E35: East Carolina | F35: Memphis | G35: -5.8 | H35: -10.5 | I35: -4.7 | J35: -7.2 | K35: -12.7 | L35: 49.1 | M35: 55.5 | N35: -6.4 | O35: 34 | P35: 41 | Q35: Win | R35: -5.3 | S35: Win | T35: Win | U35: Win | V35: Loss
A36: 8 | B36: 2026-10-24 | C36: American Athletic | D36: American Athletic | E36: Rice | F36: Florida Atlantic | G36: -9 | H36: -8.5 | I36: 0.5 | J36: -10.1 | K36: -10.5 | L36: 55.2 | M36: 53.8 | N36: 1.5 | O36: 49 | P36: 51 | Q36: Win | R36: -8.9 | S36: Loss | T36: Loss | U36: Loss | V36: Loss
A37: 8 | B37: 2026-10-24 | C37: American Athletic | D37: American Athletic | E37: North Texas | F37: Navy | G37: -5.8 | H37: 3 | I37: 8.8 | J37: 2.2 | K37: 4.7 | L37: 60.7 | M37: 62.2 | N37: -1.6 | O37: 49 | P37: 39 | Q37: Loss | R37: -0.6 | S37: Loss | T37: Win | U37: Loss | V37: Win
A38: 8 | B38: 2026-10-24 | C38: American Athletic | D38: American Athletic | E38: Army | F38: Tulsa | G38: 3.2 | H38: -1.2 | I38: -4.4 | J38: 2.4 | K38: 1.8 | L38: 56.2 | M38: 52.8 | N38: 3.4 | O38: 38 | P38: 35 | Q38: Win | R38: 7.9 | S38: Win | T38: Win | U38: Win | V38: Win
A39: 8 | B39: 2026-10-25 | C39: American Athletic | D39: American Athletic | E39: UTSA | F39: Tulane | G39: -1.4 | H39: 3 | I39: 4.4 | J39: 0.8 | K39: -1.1 | L39: 55.2 | M39: 51.5 | N39: 3.7 | O39: 42 | P39: 19 | Q39: Loss | R39: 0 | S39: Loss | T39: Loss | U39: Loss | V39: Loss
A41: Week 7
A42: Week | B42: Date | C42: Home Conf | D42: Away Conf | E42: Away Team | F42: Home Team | G42: Model Line (Home) | H42: Market Line (Home) | I42: Spread Edge (pts) | J42: Ridge Line (Home) | K42: Massey Line (Home) | L42: Model Total | M42: Market Total | N42: Total Edge (pts) | O42: Away Pts | P42: Home Pts | Q42: Model Result (SU) | R42: XGBoost Line (Home) | S42: Gamma ATS | T42: Ridge ATS | U42: XGBoost ATS | V42: Massey ATS
A43: 7 | B43: 2026-10-15 | C43: American Athletic | D43: American Athletic | E43: East Carolina | F43: UAB | G43: 9.1 | H43: 5.5 | I43: -3.6 | J43: 5.1 | K43: 1.9 | L43: 47.2 | M43: 48.2 | N43: -1.1 | O43: 17 | P43: 30 | Q43: Loss | R43: 6.3 | S43: Loss | T43: Loss | U43: Loss | V43: Win
A44: 7 | B44: 2026-10-16 | C44: American Athletic | D44: American Athletic | E44: Memphis | F44: Tulane | G44: 2.3 | H44: 7 | I44: 4.7 | J44: -0.2 | K44: 8.2 | L44: 56.4 | M44: 55.5 | N44: 0.9 | O44: 17 | P44: 31 | Q44: Loss | R44: -2.8 | S44: Win | T44: Win | U44: Win | V44: Loss
A45: 7 | B45: 2026-10-17 | C45: American Athletic | D45: American Athletic | E45: Florida Atlantic | F45: Army | G45: -9.5 | H45: -2.8 | I45: 6.7 | J45: -2.9 | K45: -6 | L45: 59.7 | M45: 54.8 | N45: 5 | O45: 24 | P45: 56 | Q45: Win | R45: -12.1 | S45: Win | T45: Win | U45: Win | V45: Win
...

Sheet Big 12 Slate
A1: Big 12 Model ATS Record
A2: Metric | B2: Record (W-L-P) | C2: ATS %
A3: Rolling ATS (Season) | B3: 42-38-1 | C3: 0.525
A4: Weekly ATS (Wk 8) | B4: 3-5-0 | C4: 0.375
A5: Model pick W-L, straight-up (Wk 8) | B5: 3-5 | C5: 0.375
A7: Big 12 Standings
A8: Team | B8: Conf W | C8: Conf L | D8: Conf Pct | E8: Overall W | F8: Overall L
A9: Utah | B9: 4 | C9: 0 | D9: 1 | E9: 7 | F9: 0
A10: Arizona | B10: 3 | C10: 1 | D10: 0.75 | E10: 6 | F10: 1
A11: BYU | B11: 3 | C11: 1 | D11: 0.75 | E11: 6 | F11: 1
A12: Texas Tech | B12: 3 | C12: 1 | D12: 0.75 | E12: 6 | F12: 1
A13: Oklahoma State | B13: 3 | C13: 1 | D13: 0.75 | E13: 5 | F13: 2
A14: Houston | B14: 3 | C14: 2 | D14: 0.6 | E14: 6 | F14: 2
A15: Cincinnati | B15: 2 | C15: 2 | D15: 0.5 | E15: 5 | F15: 2
A16: Arizona State | B16: 2 | C16: 2 | D16: 0.5 | E16: 4 | F16: 3
A17: Baylor | B17: 2 | C17: 2 | D17: 0.5 | E17: 4 | F17: 3
A18: UCF | B18: 2 | C18: 2 | D18: 0.5 | E18: 4 | F18: 3
A19: West Virginia | B19: 2 | C19: 3 | D19: 0.4 | E19: 5 | F19: 3
A20: Kansas State | B20: 1 | C20: 3 | D20: 0.25 | E20: 4 | F20: 3
... A24: Colorado | B24: 0 | C24: 4 | D24: 0 | E24: 2 | F24: 5
A26: Week 9
A27: Week | B27: Date | C27: Home Conf | D27: Away Conf | E27: Away Team | F27: Home Team | G27: Model Line (Home) | H27: Market Line (Home) | I27: Spread Edge (pts) | J27: Ridge Line (Home) | K27: Massey Line (Home) | L27: Model Total | M27: Market Total | N27: Total Edge (pts) | O27: Away Pts | P27: Home Pts | Q27: Model Result (SU) | R27: XGBoost Line (Home) | S27: Gamma ATS | T27: Ridge ATS | U27: XGBoost ATS | V27: Massey ATS
A28: 9 | B28: 2026-10-30 | C28: Big 12 | D28: Big 12 | E28: Baylor | F28: UCF | G28: 1.1 | H28: -2.5 | I28: -3.6 | J28: 3 | K28: -4.2 | L28: 47.7 | M28: 47.5 | N28: 0.2 | R28: 3.1
A29: 9 | B29: 2026-10-31 | C29: Big 12 | D29: Big 12 | E29: Arizona State | F29: BYU | G29: -14.5 | H29: -15.5 | I29: -1 | J29: -16.9 | K29: -16.3 | L29: 50.2 | M29: 49.5 | N29: 0.7 | R29: -16.1
A30: 9 | B30: 2026-10-31 | C30: Big 12 | D30: Big 12 | E30: Utah | F30: Cincinnati | G30: 8.9 | H30: 6.5 | I30: -2.4 | J30: 14.6 | K30: 6.6 | L30: 57.2 | M30: 57.5 | N30: -0.3 | R30: 11
A31: 9 | B31: 2026-10-31 | C31: Big 12 | D31: Big 12 | E31: Kansas State | F31: Colorado | G31: 4.7 | H31: 2.5 | I31: -2.2 | J31: 10.4 | K31: 6.4 | L31: 49.6 | M31: 48.5 | N31: 1.1 | R31: 11.1
A32: 9 | B32: 2026-10-31 | C32: Big 12 | D32: Big 12 | E32: Oklahoma State | F32: Iowa State | G32: -6 | H32: 10 | I32: 16 | J32: -5.6 | K32: 7.4 | L32: 49 | M32: 57.5 | N32: -8.5 | R32: -11
A33: 9 | B33: 2026-10-31 | C33: Big 12 | D33: Big 12 | E33: Kansas | F33: TCU | G33: -6 | H33: -5.5 | I33: 0.5 | J33: -9.7 | K33: -5.5 | L33: 48.7 | M33: 46.5 | N33: 2.2 | R33: -9.6
A34: 9 | B34: 2026-10-31 | C34: Big 12 | D34: Big 12 | E34: Arizona | F34: Texas Tech | G34: -4.6 | H34: -3.5 | I34: 1.1 | J34: -3.6 | K34: -1.8 | L34: 49.3 | M34: 54.5 | N34: -5.2 | R34: -6.1
A36: Week 8
A37: Week | B37: Date | C37: Home Conf | D37: Away Conf | E37: Away Team | F37: Home Team | G37: Model Line (Home) | H37: Market Line (Home) | I37: Spread Edge (pts) | J37: Ridge Line (Home) | K37: Massey Line (Home) | L37: Model Total | M37: Market Total | N37: Total Edge (pts) | O37: Away Pts | P37: Home Pts | Q37: Model Result (SU) | R37: XGBoost Line (Home) | S37: Gamma ATS | T37: Ridge ATS | U37: XGBoost ATS | V37: Massey ATS
A38: 8 | B38: 2026-10-24 | C38: Big 12 | D38: Big 12 | E38: Iowa State | F38: Arizona | G38: -7.5 | H38: -9.8 | I38: -2.3 | J38: -13.3 | K38: -6.2 | L38: 48.9 | M38: 51.5 | N38: -2.6 | O38: 3 | P38: 39 | Q38: Win | R38: -13.2 | S38: Loss | T38: Win | U38: Win | V38: Loss
A39: 8 | B39: 2026-10-24 | C39: Big 12 | D39: Big 12 | E39: Kansas State | F39: Arizona State | G39: 0.4 | H39: 2.5 | I39: 2.1 | J39: 2.1 | K39: 6.3 | L39: 52 | M39: 55.2 | N39: -3.2 | O39: 17 | P39: 28 | Q39: Loss | R39: 1.5 | S39: Win | T39: Loss | U39: Win | V39: Loss
A40: 8 | B40: 2026-10-24 | C40: Big 12 | D40: Big 12 | E40: Texas Tech | F40: Cincinnati | G40: 13.7 | H40: 11.5 | I40: -2.2 | J40: 16.9 | K40: 8.4 | L40: 55 | M40: 56.8 | N40: -1.7 | O40: 24 | P40: 37 | Q40: Loss | R40: 14.8 | S40: Loss | T40: Loss | U40: Loss | V40: Win
A41: 8 | B41: 2026-10-24 | C41: Big 12 | D41: Big 12 | E41: Baylor | F41: Kansas | G41: 3.1 | H41: 1.2 | I41: -1.9 | J41: 4.7 | K41: 2.2 | L41: 51.5 | M41: 53.5 | N41: -2 | O41: 24 | P41: 25 | Q41: Loss | R41: 6.2 | S41: Loss | T41: Loss | U41: Loss | V41: Loss
A42: 8 | B42: 2026-10-24 | C42: Big 12 | D42: Big 12 | E42: Colorado | F42: Oklahoma State | G42: -1.5 | H42: -13.5 | I42: -12 | J42: -5.1 | K42: -16 | L42: 46.4 | M42: 56.2 | N42: -9.9 | O42: 24 | P42: 57 | Q42: Win | R42: -3.4 | S42: Loss | T42: Loss | U42: Loss | V42: Win
A43: 8 | B43: 2026-10-24 | C43: Big 12 | D43: Big 12 | E43: West Virginia | F43: TCU | G43: -15 | H43: -10.2 | I43: 4.8 | J43: -10.6 | K43: -10.5 | L43: 51.4 | M43: 57.5 | N43: -6.1 | O43: 24 | P43: 20 | Q43: Loss | R43: -8.9 | S43: Loss | T43: Loss | U43: Win | V43: Loss
A44: 8 | B44: 2026-10-24 | C44: Big 12 | D44: Big 12 | E44: BYU | F44: UCF | G44: 10.6 | H44: 7.5 | I44: -3.1 | J44: 22.3 | K44: 1.8 | L44: 48.9 | M44: 43.5 | N44: 5.4 | O44: 31 | P44: 39 | Q44: Loss | R44: 18 | S44: Loss | T44: Loss | U44: Loss | V44: Win
A45: 8 | B45: 2026-10-25 | C45: Big 12 | D45: Big 12 | E45: Houston | F45: Utah | G45: -14.1 | H45: -6.5 | I45: 7.6 | J45: -7.6 | K45: -1.6 | L45: 57 | M45: 56.8 | N45: 0.2 | O45: 13 | P45: 21 | Q45: Win | R45: -7.4 | S45: Win | T45: Win | U45: Win | V45: Loss
A47: Week 7
...

Sheet Big Ten Slate
A1: Big Ten Model ATS Record
A2: Metric | B2: Record (W-L-P) | C2: ATS %
A3: Rolling ATS (Season) | B3: 44-46-1 | C3: 0.489
A4: Weekly ATS (Wk 8) | B4: 2-4-0 | C4: 0.333
A5: Model pick W-L, straight-up (Wk 8) | B5: 3-3 | C5: 0.5
A7: Big Ten Standings
A8: Team | B8: Conf W | C8: Conf L | D8: Conf Pct | E8: Overall W | F8: Overall L
A9: UCLA | B9: 5 | C9: 0 | D9: 1 | E9: 7 | F9: 0
A10: Ohio State | B10: 4 | C10: 0 | D10: 1 | E10: 6 | F10: 1
A11: Indiana | B11: 4 | C11: 1 | D11: 0.8 | E11: 7 | F11: 1
A12: Northwestern | B12: 3 | C12: 1 | D12: 0.75 | E12: 6 | F12: 1
A13: Minnesota | B13: 3 | C13: 1 | D13: 0.75 | E13: 5 | F13: 2
A14: Wisconsin | B14: 3 | C14: 1 | D14: 0.75 | E14: 5 | F14: 2
A15: USC | B15: 3 | C15: 2 | D15: 0.6 | E15: 6 | F15: 2
A16: Iowa | B16: 2 | C16: 2 | D16: 0.5 | E16: 5 | F16: 2
A17: Nebraska | B17: 2 | C17: 2 | D17: 0.5 | E17: 5 | F17: 2
A18: Illinois | B18: 2 | C18: 2 | D18: 0.5 | E18: 4 | F18: 3
A19: Oregon | B19: 2 | C19: 2 | D19: 0.5 | E19: 4 | F19: 3
A20: Purdue | B20: 2 | C20: 2 | D20: 0.5 | E20: 3 | F20: 4
... A26: Michigan State | B26: 0 | C26: 5 | D26: 0 | E26: 2 | F26: 6
A28: Week 9
A29: Week | B29: Date | C29: Home Conf | D29: Away Conf | E29: Away Team | F29: Home Team | G29: Model Line (Home) | H29: Market Line (Home) | I29: Spread Edge (pts) | J29: Ridge Line (Home) | K29: Massey Line (Home) | L29: Model Total | M29: Market Total | N29: Total Edge (pts) | O29: Away Pts | P29: Home Pts | Q29: Model Result (SU) | R29: XGBoost Line (Home) | S29: Gamma ATS | T29: Ridge ATS | U29: XGBoost ATS | V29: Massey ATS
A30: 9 | B30: 2026-10-31 | C30: Big Ten | D30: Big Ten | E30: Minnesota | F30: Indiana | G30: -22.2 | H30: -19.5 | I30: 2.7 | J30: -16.3 | K30: -18.7 | L30: 46.9 | M30: 42.5 | N30: 4.4 | R30: -14.7
A31: 9 | B31: 2026-10-31 | C31: Big Ten | D31: Big Ten | E31: Wisconsin | F31: Iowa | G31: -10.3 | H31: -3.5 | I31: 6.8 | J31: -10.2 | K31: 0.1 | L31: 42.5 | M31: 36.5 | N31: 6 | R31: -11
A32: 9 | B32: 2026-10-31 | C32: Big Ten | D32: Big Ten | E32: Illinois | F32: Maryland | G32: 8 | H32: 2.5 | I32: -5.5 | J32: 11.3 | K32: 3.6 | L32: 52.9 | M32: 52.5 | N32: 0.4 | R32: 6.1
A33: 9 | B33: 2026-10-31 | C33: Big Ten | D33: Big Ten | E33: Northwestern | F33: Oregon | G33: -8.4 | H33: -3.5 | I33: 4.9 | J33: -11.5 | K33: -2.6 | L33: 48.3 | M33: 49.5 | N33: -1.2 | R33: -10.3
A34: 9 | B34: 2026-10-31 | C34: Big Ten | D34: Big Ten | E34: Purdue | F34: Penn State | G34: -14.9 | H34: -7.5 | I34: 7.4 | J34: -10.9 | K34: -7.9 | L34: 52.9 | M34: 53.5 | N34: -0.6 | R34: -11.9
A35: 9 | B35: 2026-10-31 | C35: Big Ten | D35: Big Ten | E35: Michigan | F35: Rutgers | G35: 8.3 | H35: 14 | I35: 5.7 | J35: 12.4 | K35: 5.1 | L35: 48.6 | M35: 47.5 | N35: 1.1 | R35: 12.6
A36: 9 | B36: 2026-10-31 | C36: Big Ten | D36: Mountain West | E36: Nevada | F36: UCLA | G36: -21.2 | H36: -22.5 | I36: -1.3 | J36: -23.3 | K36: -19.5 | L36: 43.5 | M36: 44.5 | N36: -1 | R36: -20.6
A37: 9 | B37: 2026-10-31 | C37: Big Ten | D37: Big Ten | E37: Ohio State | F37: USC | G37: 12.6 | H37: 7 | I37: -5.6 | J37: 9.8 | K37: 10.7 | L37: 53 | M37: 51.5 | N37: 1.5 | R37: 9.9
