Workbook

Sheet Read Me
A1: Mountain West Handicapping Tracker
A2: 2026 Season
A4: How this workbook is meant to be used
A5: This workbook is the review/tracking cockpit -- the model itself runs in Python (see the
A6: attack plan and the src/ scripts). Each week, paste that week's model output into the blue
A7: cells on the Weekly Slate tab; everything else on that tab recalculates automatically.
A9: Color legend
A10: Blue text = cells you fill in by hand (model output, market lines, bet results)
A11: Black text = formulas -- don't type over these, they recalculate from the blue cells
A12: Yellow fill = key assumptions on the Settings tab (edit these once, not weekly)
A14: Tabs
A15: Settings = bankroll, edge thresholds, and other assumptions used across the workbook
... A22: paper-trading and bankroll discipline before staking real money.

Sheet Settings
A1: Settings & Assumptions
A3: Assumption | B3: Value | C3: Notes
A4: Starting bankroll (units) | B4: 50 | C4: Example: 100 units. 1 unit = whatever flat stake you choose in real currency.
A5: Spread edge threshold (pts) | B5: 2 | C5: Minimum |model line - market line| before a spread is flagged as a lean.
A6: Total edge threshold (pts) | B6: 2 | C6: Minimum |model total - market total| before a total is flagged as a lean.
A7: Standard vig odds (American) | B7: -110 | C7: Reference only -- breakeven win rate at -110 is 52.4%.

Sheet Weekly Slate
A1: Week | B1: Date | C1: Away Team | D1: Home Team | E1: Model Line (Home) | F1: Market Line (Home) | G1: Spread Edge (pts) | H1: Spread Lean | I1: Model Total | J1: Market Total | K1: Total Edge (pts) | L1: Total Lean | M1: Suggested Bet (Spread) | N1: Suggested Bet (Total) | O1: Qualitative Notes | P1: Final Decision | R1: MW WEST Teams
A2: 5 | B2: 2026-10-03 | C2: Navy | D2: Air Force | E2: 3.2 | F2: -3.2 | G2: =F2-E2 | H2: =IF(G2=0,"Pick'em",IF(G2>0,"Home","Away")) | I2: 54.9 | J2: 45.5 | K2: =I2-J2 | L2: =IF(K2=0,"Push",IF(K2>0,"Over","Under")) | M2: =IF(ABS(G2)>=Settings!$B$5,H2,IF(F2=0,"Pick'em",IF(F2<0,"Home (auto)","Away (auto)"))) | N2: =IF(ABS(K2)>=Settings!$B$6,L2,IF(K2=0,"Push",L2&" (auto)"))
A3: 5 | B3: 2026-10-03 | C3: Wyoming | D3: North Dakota State | E3: -30.3 | F3: -17.2 | G3: =F3-E3 | H3: =IF(G3=0,"Pick'em",IF(G3>0,"Home","Away")) | I3: 46.8 | J3: 44.5 | K3: =I3-J3 | L3: =IF(K3=0,"Push",IF(K3>0,"Over","Under")) | M3: =IF(ABS(G3)>=Settings!$B$5,H3,IF(F3=0,"Pick'em",IF(F3<0,"Home (auto)","Away (auto)"))) | N3: =IF(ABS(K3)>=Settings!$B$6,L3,IF(K3=0,"Push",L3&" (auto)"))
A4: 5 | B4: 2026-10-03 | C4: California | D4: UNLV | E4: -5.3 | F4: -2.8 | G4: =F4-E4 | H4: =IF(G4=0,"Pick'em",IF(G4>0,"Home","Away")) | I4: 45.5 | J4: 53.5 | K4: =I4-J4 | L4: =IF(K4=0,"Push",IF(K4>0,"Over","Under")) | M4: =IF(ABS(G4)>=Settings!$B$5,H4,IF(F4=0,"Pick'em",IF(F4<0,"Home (auto)","Away (auto)"))) | N4: =IF(ABS(K4)>=Settings!$B$6,L4,IF(K4=0,"Push",L4&" (auto)"))
A5: 5 | B5: 2026-10-03 | C5: UTEP | D5: New Mexico | E5: -31.8 | F5: -22.5 | G5: =F5-E5 | H5: =IF(G5=0,"Pick'em",IF(G5>0,"Home","Away")) | I5: 43.7 | J5: 47.8 | K5: =I5-J5 | L5: =IF(K5=0,"Push",IF(K5>0,"Over","Under")) | M5: =IF(ABS(G5)>=Settings!$B$5,H5,IF(F5=0,"Pick'em",IF(F5<0,"Home (auto)","Away (auto)"))) | N5: =IF(ABS(K5)>=Settings!$B$6,L5,IF(K5=0,"Push",L5&" (auto)")) | R5: Air Force
A6: 5 | B6: 2026-10-04 | C6: San José State | D6: Hawai'i | E6: -6.8 | F6: -3 | G6: =F6-E6 | H6: =IF(G6=0,"Pick'em",IF(G6>0,"Home","Away")) | I6: 48.5 | J6: 50.5 | K6: =I6-J6 | L6: =IF(K6=0,"Push",IF(K6>0,"Over","Under")) | M6: =IF(ABS(G6)>=Settings!$B$5,H6,IF(F6=0,"Pick'em",IF(F6<0,"Home (auto)","Away (auto)"))) | N6: =IF(ABS(K6)>=Settings!$B$6,L6,IF(K6=0,"Push",L6&" (auto)")) | R6: Hawai'i
G7: =F7-E7 | H7: =IF(G7=0,"Pick'em",IF(G7>0,"Home","Away")) | K7: =I7-J7 | L7: =IF(K7=0,"Push",IF(K7>0,"Over","Under")) | M7: =IF(ABS(G7)>=Settings!$B$5,H7,IF(F7=0,"Pick'em",IF(F7<0,"Home (auto)","Away (auto)"))) | N7: =IF(ABS(K7)>=Settings!$B$6,L7,IF(K7=0,"Push",L7&" (auto)")) | R7: Nevada
G8: =F8-E8 | H8: =IF(G8=0,"Pick'em",IF(G8>0,"Home","Away")) | K8: =I8-J8 | L8: =IF(K8=0,"Push",IF(K8>0,"Over","Under")) | M8: =IF(ABS(G8)>=Settings!$B$5,H8,IF(F8=0,"Pick'em",IF(F8<0,"Home (auto)","Away (auto)"))) | N8: =IF(ABS(K8)>=Settings!$B$6,L8,IF(K8=0,"Push",L8&" (auto)")) | R8: New Mexico
G9: =F9-E9 | H9: =IF(G9=0,"Pick'em",IF(G9>0,"Home","Away")) | K9: =I9-J9 | L9: =IF(K9=0,"Push",IF(K9>0,"Over","Under")) | M9: =IF(ABS(G9)>=Settings!$B$5,H9,IF(F9=0,"Pick'em",IF(F9<0,"Home (auto)","Away (auto)"))) | N9: =IF(ABS(K9)>=Settings!$B$6,L9,IF(K9=0,"Push",L9&" (auto)")) | R9: North Dakota State
G10: =F10-E10 | H10: =IF(G10=0,"Pick'em",IF(G10>0,"Home","Away")) | K10: =I10-J10 | L10: =IF(K10=0,"Push",IF(K10>0,"Over","Under")) | M10: =IF(ABS(G10)>=Settings!$B$5,H10,IF(F10=0,"Pick'em",IF(F10<0,"Home (auto)","Away (auto)"))) | N10: =IF(ABS(K10)>=Settings!$B$6,L10,IF(K10=0,"Push",L10&" (auto)")) | R10: Northern Illinois
G11: =F11-E11 | H11: =IF(G11=0,"Pick'em",IF(G11>0,"Home","Away")) | K11: =I11-J11 | L11: =IF(K11=0,"Push",IF(K11>0,"Over","Under")) | M11: =IF(ABS(G11)>=Settings!$B$5,H11,IF(F11=0,"Pick'em",IF(F11<0,"Home (auto)","Away (auto)"))) | N11: =IF(ABS(K11)>=Settings!$B$6,L11,IF(K11=0,"Push",L11&" (auto)")) | R11: San José State
G12: =F12-E12 | H12: =IF(G12=0,"Pick'em",IF(G12>0,"Home","Away")) | K12: =I12-J12 | L12: =IF(K12=0,"Push",IF(K12>0,"Over","Under")) | M12: =IF(ABS(G12)>=Settings!$B$5,H12,IF(F12=0,"Pick'em",IF(F12<0,"Home (auto)","Away (auto)"))) | N12: =IF(ABS(K12)>=Settings!$B$6,L12,IF(K12=0,"Push",L12&" (auto)")) | R12: UNLV
G13: =F13-E13 | H13: =IF(G13=0,"Pick'em",IF(G13>0,"Home","Away")) | K13: =I13-J13 | L13: =IF(K13=0,"Push",IF(K13>0,"Over","Under")) | M13: =IF(ABS(G13)>=Settings!$B$5,H13,IF(F13=0,"Pick'em",IF(F13<0,"Home (auto)","Away (auto)"))) | N13: =IF(ABS(K13)>=Settings!$B$6,L13,IF(K13=0,"Push",L13&" (auto)"))
G14: =F14-E14 | H14: =IF(G14=0,"Pick'em",IF(G14>0,"Home","Away")) | K14: =I14-J14 | L14: =IF(K14=0,"Push",IF(K14>0,"Over","Under")) | M14: =IF(ABS(G14)>=Settings!$B$5,H14,IF(F14=0,"Pick'em",IF(F14<0,"Home (auto)","Away (auto)"))) | N14: =IF(ABS(K14)>=Settings!$B$6,L14,IF(K14=0,"Push",L14&" (auto)"))

Sheet Bet Log
A1: Date | B1: Week | C1: Matchup | D1: Bet Type | E1: Side | F1: Line Taken | G1: Odds (American) | H1: Stake (units) | I1: Closing Line | J1: CLV (pts) | K1: Result | L1: Units Won/Lost | M1: Running Bankroll
A2: 2026-08-29 | B2: 1 | C2: Jacksonville State @ North Dakota State | D2: Spread | E2: North Dakota State | F2: -7.5 | G2: 100 | H2: 1 | I2: -7 | J2: =IF(I2="","",I2-F2) | K2: W | L2: =IF(K2="W",IF(G2<0,H2*100/ABS(G2),H2*G2/100),IF(K2="L",-H2,0)) | M2: =Settings!$B$4+SUM(L$2:L2)
A3: 2026-08-29 | B3: 1 | C3: Jacksonville State @ North Dakota State | D3: Moneyline | E3: North Dakota State | G3: -285 | H3: 5 | J3: =IF(I3="","",I3-F3) | K3: W | L3: =IF(K3="W",IF(G3<0,H3*100/ABS(G3),H3*G3/100),IF(K3="L",-H3,0)) | M3: =Settings!$B$4+SUM(L$2:L3)
A4: 2026-08-29 | B4: 1 | C4: Memphis @ UNLV | D4: Moneyline | E4: UNLV | G4: -178 | H4: 5 | J4: =IF(I4="","",I4-F4) | K4: L | L4: =IF(K4="W",IF(G4<0,H4*100/ABS(G4),H4*G4/100),IF(K4="L",-H4,0)) | M4: =Settings!$B$4+SUM(L$2:L4)
A5: 2026-08-29 | B5: 1 | C5: Jacksonville State @ North Dakota State,Memphis @ UNLV | D5: ML Parlay | E5: North Dakota State / UNLV | G5: 110 | H5: 3 | J5: =IF(I5="","",I5-F5) | K5: L | L5: =IF(K5="W",IF(G5<0,H5*100/ABS(G5),H5*G5/100),IF(K5="L",-H5,0)) | M5: =Settings!$B$4+SUM(L$2:L5)
A6: 2026-09-04 | B6: 1 | C6: San José State @ Eastern Michigan | D6: Spread | E6: Eastern Michigan | F6: -3.5 | G6: -110 | H6: 2 | J6: =IF(I6="","",I6-F6) | K6: L | L6: =IF(K6="W",IF(G6<0,H6*100/ABS(G6),H6*G6/100),IF(K6="L",-H6,0)) | M6: =Settings!$B$4+SUM(L$2:L6)
A7: 2026-09-05 | B7: 1 | C7: San José State @ Eastern Michigan, Wyoming at Colorado State | D7: ML Parlay | E7: Eastern Michigan, Colorado State | G7: 149 | H7: 2 | J7: =IF(I7="","",I7-F7) | K7: L | L7: =IF(K7="W",IF(G7<0,H7*100/ABS(G7),H7*G7/100),IF(K7="L",-H7,0)) | M7: =Settings!$B$4+SUM(L$2:L7)
A8: 2026-09-05 | B8: 1 | C8: Wyoming @ Colorado State | D8: Spread | E8: Colorado State | F8: -2.5 | G8: -110 | H8: 2 | I8: -3 | J8: =IF(I8="","",I8-F8) | K8: W | L8: =IF(K8="W",IF(G8<0,H8*100/ABS(G8),H8*G8/100),IF(K8="L",-H8,0)) | M8: =Settings!$B$4+SUM(L$2:L8)
A9: 2026-09-05 | B9: 1 | C9: Wyoming @ Colorado State | D9: Moneyline | E9: Colorado State | G9: -145 | H9: 2 | J9: =IF(I9="","",I9-F9) | K9: W | L9: =IF(K9="W",IF(G9<0,H9*100/ABS(G9),H9*G9/100),IF(K9="L",-H9,0)) | M9: =Settings!$B$4+SUM(L$2:L9)
A10: 2026-09-05 | B10: 1 | C10: Central Michigan @ New Mexico | D10: Spread | E10: New Mexico | F10: -12.5 | G10: -110 | H10: 5 | I10: -10 | J10: =IF(I10="","",I10-F10) | K10: W | L10: =IF(K10="W",IF(G10<0,H10*100/ABS(G10),H10*G10/100),IF(K10="L",-H10,0)) | M10: =Settings!$B$4+SUM(L$2:L10)
A11: 2026-09-07 | B11: 1 | C11: SMU @ Florida State | D11: Spread | E11: SMU | F11: -2.5 | G11: -122 | H11: 2 | J11: =IF(I11="","",I11-F11) | K11: W | L11: =IF(K11="W",IF(G11<0,H11*100/ABS(G11),H11*G11/100),IF(K11="L",-H11,0)) | M11: =Settings!$B$4+SUM(L$2:L11)
A12: 2026-09-07 | B12: 1 | C12: SMU @ Florida State | D12: Spread | E12: Florida State | F12: 10.5 | G12: -118 | H12: 3 | J12: =IF(I12="","",I12-F12) | K12: W | L12: =IF(K12="W",IF(G12<0,H12*100/ABS(G12),H12*G12/100),IF(K12="L",-H12,0)) | M12: =Settings!$B$4+SUM(L$2:L12)
A13: 2026-09-07 | B13: 1 | C13: SMU @ Florida State | D13: Moneyline | E13: Florida State | G13: 265 | H13: 1 | J13: =IF(I13="","",I13-F13) | K13: L | L13: =IF(K13="W",IF(G13<0,H13*100/ABS(G13),H13*G13/100),IF(K13="L",-H13,0)) | M13: =Settings!$B$4+SUM(L$2:L13)
A14: 2026-09-06 | B14: 1 | C14: Louisville @ Ole Miss | D14: Spread | E14: Louisville | F14: 6.5 | G14: -108 | H14: 3 | J14: =IF(I14="","",I14-F14) | K14: W | L14: =IF(K14="W",IF(G14<0,H14*100/ABS(G14),H14*G14/100),IF(K14="L",-H14,0)) | M14: =Settings!$B$4+SUM(L$2:L14)
A15: 2026-09-06 | B15: 1 | C15: Louisville @ Ole Miss | D15: Spread | E15: Louisville | F15: 7.5 | G15: 114 | H15: 3 | J15: =IF(I15="","",I15-F15) | K15: W | L15: =IF(K15="W",IF(G15<0,H15*100/ABS(G15),H15*G15/100),IF(K15="L",-H15,0)) | M15: =Settings!$B$4+SUM(L$2:L15)
A16: 2026-09-06 | B16: 1 | C16: Wisconsin @ Notre Dame | D16: Spread | E16: Wisconsin | F16: 14.5 | G16: -132 | H16: 3 | J16: =IF(I16="","",I16-F16) | K16: L | L16: =IF(K16="W",IF(G16<0,H16*100/ABS(G16),H16*G16/100),IF(K16="L",-H16,0)) | M16: =Settings!$B$4+SUM(L$2:L16)
A17: 2026-09-05 | B17: 1 | C17: Clemson @ LSU | D17: Spread | E17: Clemson | F17: 28.5 | G17: -138 | H17: 7.5 | J17: =IF(I17="","",I17-F17) | K17: L | L17: =IF(K17="W",IF(G17<0,H17*100/ABS(G17),H17*G17/100),IF(K17="L",-H17,0)) | M17: =Settings!$B$4+SUM(L$2:L17)
A18: 2026-09-05 | B18: 1 | C18: Clemson @ LSU | D18: Spread | E18: Clemson | F18: 10.5 | G18: -118 | H18: 2.5 | J18: =IF(I18="","",I18-F18) | K18: L | L18: =IF(K18="W",IF(G18<0,H18*100/ABS(G18),H18*G18/100),IF(K18="L",-H18,0)) | M18: =Settings!$B$4+SUM(L$2:L18)
A19: 2026-09-05 | B19: 1 | C19: Western Michigan @ Michigan | D19: Moneyline | E19: Michigan | G19: 146 | H19: 11.5 | J19: =IF(I19="","",I19-F19) | K19: W | L19: =IF(K19="W",IF(G19<0,H19*100/ABS(G19),H19*G19/100),IF(K19="L",-H19,0)) | M19: =Settings!$B$4+SUM(L$2:L19)
A20: 2026-09-05 | B20: 1 | C20: Boise State @ Oregon | D20: Spread | E20: Boise State | F20: 6.5 | G20: 108 | H20: 3 | J20: =IF(I20="","",I20-F20) | K20: L | L20: =IF(K20="W",IF(G20<0,H20*100/ABS(G20),H20*G20/100),IF(K20="L",-H20,0)) | M20: =Settings!$B$4+SUM(L$2:L20)
A21: 2026-09-05 | B21: 1 | C21: Tarleton State @ Bowling Green | D21: Moneyline | E21: Bowling Green | G21: 200 | H21: 3 | J21: =IF(I21="","",I21-F21) | K21: L | L21: =IF(K21="W",IF(G21<0,H21*100/ABS(G21),H21*G21/100),IF(K21="L",-H21,0)) | M21: =Settings!$B$4+SUM(L$2:L21)
A22: 2026-09-04 | B22: 1 | C22: Miami @ Stanford | D22: Spread | E22: Miami | F22: -36.5 | G22: 100 | H22: 2.5 | J22: =IF(I22="","",I22-F22) | K22: W | L22: =IF(K22="W",IF(G22<0,H22*100/ABS(G22),H22*G22/100),IF(K22="L",-H22,0)) | M22: =Settings!$B$4+SUM(L$2:L22)
A23: 2026-09-04 | B23: 1 | C23: Fresno State @ USC | D23: Total | F23: 39.5 | G23: -102 | H23: 5 | J23: =IF(I23="","",I23-F23) | K23: L | L23: =IF(K23="W",IF(G23<0,H23*100/ABS(G23),H23*G23/100),IF(K23="L",-H23,0)) | M23: =Settings!$B$4+SUM(L$2:L23)
A24: 2026-09-04 | B24: 1 | C24: Toledo @ MSU | D24: Spread | E24: Michigan | F24: -12.5 | G24: -114 | H24: 3.5 | J24: =IF(I24="","",I24-F24) | K24: L | L24: =IF(K24="W",IF(G24<0,H24*100/ABS(G24),H24*G24/100),IF(K24="L",-H24,0)) | M24: =Settings!$B$4+SUM(L$2:L24)
A25: 2026-09-04 | B25: 1 | C25: UTEP @ Oklahoma | D25: Total | F25: 51.5 | G25: -128 | H25: 2.5 | J25: =IF(I25="","",I25-F25) | K25: L | L25: =IF(K25="W",IF(G25<0,H25*100/ABS(G25),H25*G25/100),IF(K25="L",-H25,0)) | M25: =Settings!$B$4+SUM(L$2:L25)
A26: 2026-09-04 | B26: 1 | C26: San Jose State @ Eastern Michigan | D26: Moneyline | E26: Eastern Michigan | G26: -146 | H26: 2 | J26: =IF(I26="","",I26-F26) | K26: L | L26: =IF(K26="W",IF(G26<0,H26*100/ABS(G26),H26*G26/100),IF(K26="L",-H26,0)) | M26: =Settings!$B$4+SUM(L$2:L26)
A27: 2026-09-04 | B27: 1 | C27: UAB @ Illinois | D27: Spread | E27: UAB | F27: 17.5 | G27: -106 | H27: 2.75 | J27: =IF(I27="","",I27-F27) | K27: L | L27: =IF(K27="W",IF(G27<0,H27*100/ABS(G27),H27*G27/100),IF(K27="L",-H27,0)) | M27: =Settings!$B$4+SUM(L$2:L27)
A28: 2026-09-04 | B28: 1 | C28: UAB @ Illinois | D28: Spread | E28: UAB | F28: 25.5 | G28: 320 | H28: 2 | J28: =IF(I28="","",I28-F28) | K28: W | L28: =IF(K28="W",IF(G28<0,H28*100/ABS(G28),H28*G28/100),IF(K28="L",-H28,0)) | M28: =Settings!$B$4+SUM(L$2:L28)
A29: 2026-09-12 | B29: 2 | C29: UNLV @ North Texas | D29: Spread | E29: North Texas | F29: 3.5 | G29: -114 | H29: 1 | I29: 3.5 | J29: =IF(I29="","",I29-F29) | K29: W | L29: =IF(K29="W",IF(G29<0,H29*100/ABS(G29),H29*G29/100),IF(K29="L",-H29,0)) | M29: =Settings!$B$4+SUM(L$2:L29)
A30: 2026-09-13 | B30: 2 | C30: North Dakota State @ Airforce | D30: Spread | E30: North Dakota State | F30: -2.5 | G30: -112 | H30: 2.5 | I30: 2.5 | J30: =IF(I30="","",I30-F30) | K30: W | L30: =IF(K30="W",IF(G30<0,H30*100/ABS(G30),H30*G30/100),IF(K30="L",-H30,0)) | M30: =Settings!$B$4+SUM(L$2:L30)
A31: 2026-09-13 | B31: 2 | C31: North Dakota State @ Airforce | D31: Moneyline | E31: North Dakota State | G31: -134 | H31: 2.5 | J31: =IF(I31="","",I31-F31) | K31: W | L31: =IF(K31="W",IF(G31<0,H31*100/ABS(G31),H31*G31/100),IF(K31="L",-H31,0)) | M31: =Settings!$B$4+SUM(L$2:L31)
A32: 2026-09-13 | B32: 2 | C32: New Mexico State @ Hawaii | D32: Moneyline | E32: Hawaii | G32: -330 | H32: 1 | J32: =IF(I32="","",I32-F32) | K32: W | L32: =IF(K32="W",IF(G32<0,H32*100/ABS(G32),H32*G32/100),IF(K32="L",-H32,0)) | M32: =Settings!$B$4+SUM(L$2:L32)
A33: 2026-09-12 | B33: 2 | C33: Maryland @ Uconn | D33: Spread | E33: Uconn | F33: 12.5 | G33: -110 | H33: 1 | I33: 13.5 | J33: =IF(I33="","",I33-F33) | K33: L | L33: =IF(K33="W",IF(G33<0,H33*100/ABS(G33),H33*G33/100),IF(K33="L",-H33,0)) | M33: =Settings!$B$4+SUM(L$2:L33)
A34: 2026-09-12 | B34: 2 | C34: Ohio State @ Texas | D34: Moneyline | E34: Texas | G34: 500 | H34: 40 | J34: =IF(I34="","",I34-F34) | K34: W | L34: =IF(K34="W",IF(G34<0,H34*100/ABS(G34),H34*G34/100),IF(K34="L",-H34,0)) | M34: =Settings!$B$4+SUM(L$2:L34)
A35: 2026-09-19 | B35: 3 | C35: Wyoming @ Central Michigan | D35: Spread | E35: Central Michigan | F35: -1.5 | G35: -110 | H35: 1 | I35: -2.5 | J35: =IF(I35="","",I35-F35) | K35: W | L35: =IF(K35="W",IF(G35<0,H35*100/ABS(G35),H35*G35/100),IF(K35="L",-H35,0)) | M35: =Settings!$B$4+SUM(L$2:L35)
A36: 2026-09-19 | B36: 3 | C36: Wyoming @ Central Michigan | D36: Moneyline | E36: Central Michigan | F36: -0.5 | G36: -114 | H36: 1 | J36: =IF(I36="","",I36-F36) | K36: W | L36: =IF(K36="W",IF(G36<0,H36*100/ABS(G36),H36*G36/100),IF(K36="L",-H36,0)) | M36: =Settings!$B$4+SUM(L$2:L36)
A37: 2026-09-19 | B37: 3 | C37: Sacramento State @ North Dakota State | D37: Spread | E37: North Dakota State | F37: -27.5 | G37: -115 | H37: 2 | I37: -27.5 | J37: =IF(I37="","",I37-F37) | K37: L | L37: =IF(K37="W",IF(G37<0,H37*100/ABS(G37),H37*G37/100),IF(K37="L",-H37,0)) | M37: =Settings!$B$4+SUM(L$2:L37)
A38: 2026-09-19 | B38: 3 | C38: SMU @ Louisville | D38: Moneyline | E38: SMU | G38: 134 | H38: 1 | J38: =IF(I38="","",I38-F38) | K38: L | L38: =IF(K38="W",IF(G38<0,H38*100/ABS(G38),H38*G38/100),IF(K38="L",-H38,0)) | M38: =Settings!$B$4+SUM(L$2:L38)
A39: 2026-09-19 | B39: 3 | C39: LSU @ Ole Miss | D39: Moneyline | E39: LSU | G39: 350 | H39: 36 | J39: =IF(I39="","",I39-F39) | K39: L | L39: =IF(K39="W",IF(G39<0,H39*100/ABS(G39),H39*G39/100),IF(K39="L",-H39,0)) | M39: =Settings!$B$4+SUM(L$2:L39)
A40: 2026-09-19 | B40: 3 | C40: Wyoming @ Central Michigan | D40: Spread | E40: Central Michigan | F40: -1.5 | G40: -114 | H40: 2.6 | I40: -2.5 | J40: =IF(I40="","",I40-F40) | K40: W | L40: =IF(K40="W",IF(G40<0,H40*100/ABS(G40),H40*G40/100),IF(K40="L",-H40,0)) | M40: =Settings!$B$4+SUM(L$2:L40)
...

Sheet Team Profiles
A1: Team | B1: Prior Conference | C1: Joined 2026 | D1: Model Power Rating | E1: SP+ Rating | F1: Off PPA | G1: Def PPA | H1: Talent Rank | I1: Notes
A2: North Dakota State | B2: FCS (Missouri Valley Football Conference) | C2: Y | D2: 1760.7 | E2: 7.8 | F2: 0.15682461 | G2: -0.15609768 | H2: 117 | I2: Full MW history available. Option offense; home elevation ~6,621 ft.
A3: UNLV | B3: Mountain West | C3: N | D3: 1606.6 | E3: -2.4 | F3: 0.052913569 | G3: 0.075709927 | H3: 63 | I3: Full history. Travel distance/time-zone is a real situational factor for every road game.
A4: New Mexico | B4: Mountain West | C4: N | D4: 1597.5 | E4: 7.7 | F4: 0.16251459 | G4: -0.14581787 | H4: 87 | I4: Full history available.
A5: Hawai'i | B5: Mountain West | C5: N | D5: 1474.3 | E5: -12.2 | F5: 0.041625594 | G5: 0.21269612 | H5: 124 | I5: Full history. Home elevation ~5,000+ ft.
A6: Air Force | B6: Mountain West | C6: N | D6: 1521.6 | E6: -3.4 | F6: 0.29746619 | G6: 0.0044006019 | H6: 141 | I6: Zero FBS history — historically dominant FCS program. Pull its FCS-era schedule separately (see pull_ndsu_games() in pull_games.py) since a plain division='fbs' query will not surface it before 2026. Likely market-mispricing candidate in year one since books/public have thin FBS-level reference data on it.
A7: Wyoming | B7: Mountain West | C7: N | D7: 1431 | E7: -12.7 | F7: 0.15620288 | G7: 0.12337511 | H7: 114 | I7: No MW history; bring its full MAC-era game log (already FBS, so it's in a plain division='fbs' pull).
A8: Northern Illinois | B8: MAC | C8: Y | D8: 1363.9 | E8: -23.9 | F8: -0.12065418 | G8: 0.15856389 | H8: 82 | I8: Full history available. Watch for 'San Jose State' (no accent) in some sources — same team.
A9: San José State | B9: Mountain West | C9: N | D9: 1428.8 | E9: -15.1 | F9: 0.082208844 | G9: 0.066097431 | H9: 129 | I9: Full history available.
A10: Nevada | B10: Mountain West | C10: N | D10: 1381.4 | E10: -6.5 | F10: 0.093463395 | G10: 0.14912308 | H10: 98 | I10: No MW history; bring its full C-USA-era game log (already FBS).
A11: UTEP | B11: Conference USA | C11: Y | D11: 1341 | E11: -24 | F11: -0.17895299 | G11: 0.25195323 | H11: 92 | I11: Full history. Home elevation ~7,220 ft — coldest, highest venue in the league.

Sheet Power Ratings
A1: Team | B1: Week 1 | C1: Week 2 | D1: Week 3 | E1: Week 4 | F1: Week 5 | V1: Matchup Spread Calculator
A2: Indiana | B2: 97 | C2: 97 | D2: 96.5 | E2: 94.9 | F2: 94.6
A3: Ohio State | B3: 93.4 | C3: 92.4 | D3: 93.8 | E3: 94 | F3: 94 | V3: Home Team | W3: Delaware
A4: Miami | B4: 89.9 | C4: 91.7 | D4: 89 | E4: 90.4 | F4: 90.4 | V4: Away Team | W4: Liberty
A5: Georgia | B5: 83.5 | C5: 85.8 | D5: 86.9 | E5: 89 | F5: 89.9 | V5: Neutral Site? (Y/N) | W5: N
A6: Oregon | B6: 86.9 | C6: 83.2 | D6: 87.8 | E6: 88 | F6: 88
A7: Notre Dame | B7: 88.5 | C7: 89.5 | D7: 89 | E7: 89.4 | F7: 87.7 | V7: HFA (model constant) | W7: 4
A8: Alabama | B8: 80.9 | C8: 82.4 | D8: 82.4 | E8: 83.9 | F8: 85.8
A9: Texas | B9: 85.1 | C9: 86 | D9: 86.4 | E9: 85.6 | F9: 85.6 | V9: Predicted Spread (Home) | W9: =IF(OR(W3="",W4=""),"",INDEX($F$2:$F$139,MATCH(W4,$A$2:$A$139,0))-INDEX($F$2:$F$139,MATCH(W3,$A$2:$A$139,0))-IF(UPPER(W5)="Y",0,W7))
A10: Utah | B10: 81.6 | C10: 83.5 | D10: 84.2 | E10: 84.3 | F10: 84.3 | V10: (negative = home team favored, e.g. "Home -6.5")
A11: Texas Tech | B11: 87.3 | C11: 85.1 | D11: 84.7 | E11: 84.3 | F11: 84.3
A12: LSU | B12: 79.1 | C12: 80.1 | D12: 79.7 | E12: 82.5 | F12: 82.5
A13: Iowa | B13: 81.2 | C13: 80.2 | D13: 81.7 | E13: 81.3 | F13: 81.4
A14: Ole Miss | B14: 84.9 | C14: 84 | D14: 84.5 | E14: 81.1 | F14: 81.1
A15: Tennessee | B15: 76.8 | C15: 77.8 | D15: 78.9 | E15: 79.7 | F15: 79.7
A16: Florida | B16: 75.2 | C16: 76.6 | D16: 76.3 | E16: 79.5 | F16: 79.6
A17: Virginia | B17: 79.2 | C17: 81.1 | D17: 77.6 | E17: 79.5 | F17: 79.5
A18: Texas A&M | B18: 82.8 | C18: 84.3 | D18: 81.7 | E18: 78.9 | F18: 78.9
A19: BYU | B19: 78.3 | C19: 79 | D19: 78.2 | E19: 78.2 | F19: 78.2
A20: Duke | B20: 75 | C20: 74.8 | D20: 76.2 | E20: 78.1 | F20: 78.2
A21: Wake Forest | B21: 71 | C21: 69.8 | D21: 72.4 | E21: 72.9 | F21: 78
A22: Penn State | B22: 80.9 | C22: 80.3 | D22: 81.2 | E22: 80.2 | F22: 77.8
... A139: Sacramento State | B139: 41 | C139: 37.9 | D139: 39.8 | E139: 37.3 | F139: 37.2

Sheet MW Team ATS
A1: MW Team ATS -- 2026 Season (graded vs. the real market line, not any model)
A3: Team | B3: ATS Record (C-L-P) | C3: Cover %
A4: Air Force | B4: 2-2-0 | C4: 0.5
A5: Hawai'i | B5: 1-3-0 | C5: 0.25
A6: Nevada | B6: 2-2-0 | C6: 0.5
A7: New Mexico | B7: 4-0-0 | C7: 1
A8: North Dakota State | B8: 2-2-0 | C8: 0.5
A9: Northern Illinois | B9: 1-3-0 | C9: 0.25
A10: San José State | B10: 2-2-0 | C10: 0.5
A11: UNLV | B11: 2-2-0 | C11: 0.5
A12: UTEP | B12: 1-3-0 | C12: 0.25
A13: Wyoming | B13: 1-3-0 | C13: 0.25
A16: Team | B16: Week | C16: Date | D16: Opponent | E16: Site | F16: Team's Spread | G16: Result (Margin) | H16: ATS Result | I16: Cover Margin
A17: Air Force | B17: 1 | C17: 2026-09-05 | D17: Duquesne | E17: Home | F17: -30 | G17: 34 | H17: Cover | I17: 4
A18: Air Force | B18: 2 | C18: 2026-09-13 | D18: North Dakota State | E18: Home | F18: 1.8 | G18: -6 | H18: No Cover | I18: -4.2
A19: Air Force | B19: 4 | C19: 2026-09-27 | D19: Nevada | E19: Away | F19: -5.2 | G19: 3 | H19: No Cover | I19: -2.2
A20: Air Force | B20: 5 | C20: 2026-10-03 | D20: Navy | E20: Home | F20: -3.2 | G20: 5 | H20: Cover | I20: 1.8
A21: Hawai'i | B21: 1 | C21: 2026-08-29 | D21: Stanford | E21: Away | F21: 4.8 | G21: -10 | H21: No Cover | I21: -5.2
A22: Hawai'i | B22: 1 | C22: 2026-09-06 | D22: UNLV | E22: Home | F22: 2.8 | G22: -15 | H22: No Cover | I22: -12.2
A23: Hawai'i | B23: 2 | C23: 2026-09-13 | D23: New Mexico State | E23: Home | F23: -7.5 | G23: 10 | H23: Cover | I23: 2.5
A24: Hawai'i | B24: 4 | C24: 2026-09-26 | D24: Wyoming | E24: Away | F24: -2.2 | G24: -17 | H24: No Cover | I24: -19.2
A25: Nevada | B25: 1 | C25: 2026-09-06 | D25: Western Kentucky | E25: Home | F25: 0.2 | G25: 35 | H25: Cover | I25: 35.2
A26: Nevada | B26: 2 | C26: 2026-09-13 | D26: Montana State | E26: Home | F26: 5 | G26: -13 | H26: No Cover | I26: -8
A27: Nevada | B27: 3 | C27: 2026-09-19 | D27: Middle Tennessee | E27: Away | F27: -3.8 | G27: -7 | H27: No Cover | I27: -10.8
A28: Nevada | B28: 4 | C28: 2026-09-27 | D28: Air Force | E28: Home | F28: 5.2 | G28: -3 | H28: Cover | I28: 2.2
... A56: Wyoming | B56: 4 | C56: 2026-09-26 | D56: Hawai'i | E56: Home | F56: 2.2 | G56: 17 | H56: Cover | I56: 19.2

Sheet Strength of Record
A1: Strength of Record -- 2026 Season (resets every season -- see column notes below)
A3: SOR = wins above what an exactly-average FBS team would've earned against this exact schedule. Rank Gap = Elo Rank minus SOR Rank -- a big positive number means the Elo rating (no preseason blend, so it's all this season's results) is running ahead of what the resume actually supports.
A5: Team | B5: W-L (FBS) | C5: SOR | D5: SOR Rank | E5: Elo Rating | F5: Elo Rank | G5: Rank Gap (Elo - SOR)
A6: Alabama | B6: 5-0 | C6: 2.77 | D6: 1 | E6: 1780.3 | F6: 7 | G6: 6
A7: Texas | B7: 4-0 | C7: 2.69 | D7: 2 | E7: 1777.8 | F7: 8 | G7: 6
A8: Notre Dame | B8: 5-0 | C8: 2.3 | D8: 3 | E8: 1816.6 | F8: 3 | G8: 0
A9: Georgia | B9: 4-0 | C9: 2.26 | D9: 4 | E9: 1829 | F9: 2 | G9: -2
A10: Mississippi State | B10: 4-1 | C10: 2.06 | D10: 5 | E10: 1553.8 | F10: 72 | G10: 67
A11: UCLA | B11: 4-0 | C11: 1.98 | D11: 6 | E11: 1586.1 | F11: 61 | G11: 55
A12: Pittsburgh | B12: 4-0 | C12: 1.92 | D12: 7 | E12: 1645.2 | F12: 29 | G12: 22
A13: Florida | B13: 3-0 | C13: 1.73 | D13: 8 | E13: 1637.9 | F13: 35 | G13: 27
A14: James Madison | B14: 3-0 | C14: 1.72 | D14: 9 | E14: 1760.5 | F14: 10 | G14: 1
A15: Wake Forest | B15: 4-1 | C15: 1.69 | D15: 10 | E15: 1594.7 | F15: 55 | G15: 45
A16: Iowa | B16: 3-0 | C16: 1.69 | D16: 11 | E16: 1711 | F16: 15 | G16: 4
A17: Duke | B17: 3-0 | C17: 1.68 | D17: 12 | E17: 1686.3 | F17: 17 | G17: 5
... A238: Sacramento State | B238: 0-4 | C238: -1.85 | D238: 233 | E238: 1404.9 | F238: 213 | G238: -20

Sheet Model Comparison
A1: Dub Gamma vs. Ridge vs. XGBoost vs. Massey -- Model Comparison
A2: Informational only. The Dub Gamma Model (Sonny-Moore-seeded) is the live model everywhere else in this workbook and on the website -- Ridge, XGBoost, and Massey are candidates being evaluated here, not replacements. Gamma has no rating (and so no prediction) for any season before it was seeded -- its columns read "n/a" for older games. Massey (a simultaneous-solve rating method, see src/massey_model.py) needs no seed, so it's graded across every season here; it can still read "n/a" for a game in the live Upcoming Games table below in one specific case -- not enough completed games yet this season to solve its rating system from (typically just week 1).
A4: All-Time (every season in the backtest)
A5: Model | B5: Games Graded | C5: Picks Graded | D5: Wins | E5: Losses | F5: Pushes | G5: ATS Win % | H5: ROI (flat stake) | I5: Real Edge Bets | J5: Real Edge Win % | K5: Tightest Of The Four (CLV) | L5: CLV Pts (cum.)
A6: Dub Gamma Model (live model) -- all FBS | B6: 8764 | C6: 327 | D6: 180 | E6: 147 | F6: 4 | G6: 55.0% | H6: +5.1% | I6: 266 | J6: 54.2% | K6: 120/331 (36%) | L6: +712.3
A7: Dub Gamma Model (live model) -- MW-involved | B7: 991 | C7: 35 | D7: 23 | E7: 12 | F7: 0 | G7: 65.7% | H7: +25.4% | I7: 29 | J7: 65.5% | K7: 10/35 (29%) | L7: +112.9
A8: Ridge (candidate) -- all FBS | B8: 8764 | C8: 8692 | D8: 4349 | E8: 4343 | F8: 72 | G8: 50.0% | H8: -4.5% | I8: 6879 | J8: 49.8% | K8: 2696/8764 (31%) | L8: +5421.1
A9: Ridge (candidate) -- MW-involved | B9: 991 | C9: 979 | D9: 500 | E9: 479 | F9: 12 | G9: 51.1% | H9: -2.5% | I9: 794 | J9: 49.5% | K9: 305/991 (31%) | L9: +641.6
A10: XGBoost (candidate) -- all FBS | B10: 8764 | C10: 8692 | D10: 4384 | E10: 4308 | F10: 72 | G10: 50.4% | H10: -3.7% | I10: 6811 | J10: 50.2% | K10: 3111/8764 (36%) | L10: +26.8
A11: XGBoost (candidate) -- MW-involved | B11: 991 | C11: 979 | D11: 501 | E11: 478 | F11: 12 | G11: 51.2% | H11: -2.3% | I11: 768 | J11: 50.8% | K11: 339/991 (34%) | L11: +905.5
A12: Massey (candidate) -- all FBS | B12: 8764 | C12: 7513 | D12: 3796 | E12: 3717 | F12: 62 | G12: 50.5% | H12: -3.5% | I12: 5744 | J12: 50.6% | K12: 2837/7575 (37%) | L12: -11168.2
A13: Massey (candidate) -- MW-involved | B13: 991 | C13: 838 | D13: 425 | E13: 413 | F13: 10 | G13: 50.7% | H13: -3.2% | I13: 638 | J13: 50.5% | K13: 337/848 (40%) | L13: -152.3
A15: 2026 Season Only
A16: Model | B16: Games Graded | C16: Picks Graded | D16: Wins | E16: Losses | F16: Pushes | G16: ATS Win % | H16: ROI (flat stake) | I16: Real Edge Bets | J16: Real Edge Win % | K16: Tightest Of The Four (CLV) | L16: CLV Pts (cum.)
A17: Dub Gamma Model (live model) -- all FBS | B17: 331 | C17: 327 | D17: 180 | E17: 147 | F17: 4 | G17: 55.0% | H17: +5.1% | I17: 266 | J17: 54.2% | K17: 120/331 (36%) | L17: +712.3
A18: Dub Gamma Model (live model) -- MW-involved | B18: 35 | C18: 35 | D18: 23 | E18: 12 | F18: 0 | G18: 65.7% | H18: +25.4% | I18: 29 | J18: 65.5% | K18: 10/35 (29%) | L18: +112.9
A19: Ridge (candidate) -- all FBS | B19: 331 | C19: 327 | D19: 154 | E19: 173 | F19: 4 | G19: 47.1% | H19: -10.1% | I19: 283 | J19: 47.3% | K19: 80/331 (24%) | L19: -673.8
A20: Ridge (candidate) -- MW-involved | B20: 35 | C20: 35 | D20: 19 | E20: 16 | F20: 0 | G20: 54.3% | H20: +3.6% | I20: 29 | J20: 48.3% | K20: 8/35 (23%) | L20: +51.9
A21: XGBoost (candidate) -- all FBS | B21: 331 | C21: 327 | D21: 154 | E21: 173 | F21: 4 | G21: 47.1% | H21: -10.1% | I21: 260 | J21: 46.5% | K21: 103/331 (31%) | L21: -655.2
A22: XGBoost (candidate) -- MW-involved | B22: 35 | C22: 35 | D22: 16 | E22: 19 | F22: 0 | G22: 45.7% | H22: -12.7% | I22: 25 | J22: 40.0% | K22: 13/35 (37%) | L22: +8.8
A23: Massey (candidate) -- all FBS | B23: 331 | C23: 230 | D23: 101 | E23: 129 | F23: 2 | G23: 43.9% | H23: -16.2% | I23: 212 | J23: 44.8% | K23: 28/232 (12%) | L23: -2334.3
A24: Massey (candidate) -- MW-involved | B24: 35 | C24: 22 | D24: 13 | E24: 9 | F24: 0 | G24: 59.1% | H24: +12.8% | I24: 20 | J24: 55.0% | K24: 4/22 (18%) | L24: -73.1
A26: Ridge and XGBoost (the two candidates) agree with each other in 76.9% of all graded games. Ridge agrees with the live model (Gamma) in 55.9% of games it has a rating for. XGBoost agrees with the live model (Gamma) in 62.5% of games it has a rating for. Massey agrees with the live model (Gamma) in 50.0% of games it has a rating for.
A28: Upcoming Games -- Ridge vs. XGBoost vs. Massey vs. Dub Gamma (Not Yet Graded)
A29: Week | B29: Matchup | C29: Market Line (Home) | D29: Ridge Line | E29: XGBoost Line | F29: Gamma Line | G29: Massey Line | H29: Ridge Lean | I29: XGBoost Lean | J29: Gamma Lean | K29: Massey Lean | L29: Ridge/XGBoost Agree? | M29: Tightest (Live)*
A30: 5 | B30: Navy @ Air Force | C30: -2.8 | D30: -8.5 | E30: -1.8 | F30: +5.4 | G30: -7.7 | H30: Home | I30: Away (auto) | J30: Away | K30: Home | L30: No | M30: XGBoost
A31: 5 | B31: Wyoming @ North Dakota State | C31: -19.5 | D31: -22.0 | E31: -19.8 | F31: -31.5 | G31: -20.8 | H31: Home | I31: Home (auto) | J31: Home | K31: Home (auto) | L31: Yes | M31: XGBoost
A32: 5 | B32: California @ UNLV | C32: -2.2 | D32: -15.5 | E32: -7.4 | F32: -5.4 | G32: -3.1 | H32: Home | I32: Home | J32: Home | K32: Home (auto) | L32: Yes | M32: Massey
A33: 5 | B33: UTEP @ New Mexico | C33: -22.5 | D33: -22.1 | E33: -21.2 | F33: -31.6 | G33: -28.2 | H33: Away (auto) | I33: Away (auto) | J33: Home | K33: Home | L33: Yes | M33: Ridge
A34: 5 | B34: San José State @ Hawai'i | C34: -3.0 | D34: -6.7 | E34: -7.0 | F34: -7.7 | G34: +2.1 | H34: Home | I34: Home | J34: Home | K34: Away | L34: Yes | M34: Ridge
A35: * Tightest (Live) compares each model's line to TODAY's still-moving market line, not a final closing line -- it will keep changing until kickoff. See the graded Game-by-Game table below for the real, closing-line version of this comparison.
A38: 2026 Mountain West Games -- Game by Game
A39: Week | B39: Matchup | C39: Final Score | D39: Vegas Spread (Home) | E39: Actual Margin (Home) | F39: Ridge Line | G39: Ridge Edge | H39: Ridge Lean | I39: Ridge Result | J39: XGBoost Line | K39: XGBoost Edge | L39: XGBoost Lean | M39: XGBoost Result | N39: Gamma Line | O39: Gamma Edge | P39: Gamma Lean | Q39: Gamma Result | R39: Massey Line | S39: Massey Edge | T39: Massey Lean | U39: Massey Result | V39: Ridge/XGBoost Agree? | W39: Ridge Agrees (w/ Live Model)? | X39: Tightest CLV Line | Y39: Ridge CLV Pts (Cum.) | Z39: XGBoost CLV Pts (Cum.) | AA39: Gamma CLV Pts (Cum.) | AB39: Massey CLV Pts (Cum.)
A40: 1 | B40: Duquesne @ Air Force | C40: 0-34 | D40: -30.0 | E40: +34.0 | F40: -17.0 | G40: -13.0 | H40: Away | I40: Loss | J40: -28.3 | K40: -1.7 | L40: Away | M40: Loss (no real edge) | N40: -36.5 | O40: +6.5 | P40: Home | Q40: Win (seed week) | R40: -- | S40: -- | T40: n/a | U40: n/a | V40: Yes | W40: No | X40: XGBoost | Y40: -13.0 | Z40: -1.7 | AA40: +6.5 | AB40: +0.0
A41: 1 | B41: Wyoming @ Colorado State | C41: 13-35 | D41: -2.8 | E41: +22.0 | F41: -7.8 | G41: +5.1 | H41: Home | I41: Win | J41: -3.3 | K41: +0.6 | L41: Home | M41: Win (no real edge) | N41: -6.4 | O41: +3.7 | P41: Home | Q41: Win (seed week) | R41: -- | S41: -- | T41: n/a | U41: n/a | V41: Yes | W41: Yes | X41: XGBoost | Y41: -7.9 | Z41: -1.1 | AA41: +10.2 | AB41: +0.0
A42: 1 | B42: San José State @ Eastern Michigan | C42: 27-21 | D42: -1.5 | E42: -6.0 | F42: -15.8 | G42: +14.3 | H42: Home | I42: Loss | J42: -10.9 | K42: +9.4 | L42: Home | M42: Loss | N42: +0.5 | O42: -2.0 | P42: Away | Q42: Win (seed week) | R42: -- | S42: -- | T42: n/a | U42: n/a | V42: Yes | W42: No | X42: Gamma | Y42: +6.4 | Z42: +8.3 | AA42: +8.2 | AB42: +0.0
A43: 1 | B43: UNLV @ Hawai'i | C43: 21-6 | D43: +2.8 | E43: -15.0 | F43: +2.9 | G43: -0.1 | H43: Away | I43: Win (no real edge) | J43: -2.3 | K43: +5.0 | L43: Home | M43: Loss | N43: +4.4 | O43: -1.6 | P43: Away | Q43: Win (no real edge) (seed week) | R43: -- | S43: -- | T43: n/a | U43: n/a | V43: No | W43: Yes | X43: Ridge | Y43: +6.2 | Z43: +13.3 | AA43: +6.5 | AB43: +0.0
A44: 1 | B44: Northern Illinois @ Iowa | C44: 0-40 | D44: -31.8 | E44: +40.0 | F44: -28.3 | G44: -3.5 | H44: Away | I44: Loss | J44: -24.5 | K44: -7.2 | L44: Away | M44: Loss | N44: -41.0 | O44: +9.2 | P44: Home | Q44: Win (seed week) | R44: -- | S44: -- | T44: n/a | U44: n/a | V44: Yes | W44: No | X44: Ridge | Y44: +2.8 | Z44: +6.1 | AA44: +15.8 | AB44: +0.0
A45: 1 | B45: Western Kentucky @ Nevada | C45: 14-49 | D45: +0.2 | E45: +35.0 | F45: +3.3 | G45: -3.0 | H45: Away | I45: Loss | J45: +7.9 | K45: -7.6 | L45: Away | M45: Loss | N45: -2.5 | O45: +2.7 | P45: Home | Q45: Win (seed week) | R45: -- | S45: -- | T45: n/a | U45: n/a | V45: Yes | W45: No | X45: Gamma | Y45: -0.3 | Z45: -1.5 | AA45: +18.5 | AB45: +0.0
A46: 1 | B46: Central Michigan @ New Mexico | C46: 7-38 | D46: -11.2 | E46: +31.0 | F46: -17.5 | G46: +6.2 | H46: Home | I46: Win | J46: -11.2 | K46: -0.1 | L46: Away | M46: Loss (no real edge) | N46: -15.6 | O46: +4.3 | P46: Home | Q46: Win (seed week) | R46: -- | S46: -- | T46: n/a | U46: n/a | V46: No | W46: Yes | X46: XGBoost | Y46: +5.9 | Z46: -1.6 | AA46: +22.9 | AB46: +0.0
...

Sheet National Slate
A1: Week | B1: Date | C1: Home Conf | D1: Away Conf | E1: Away Team | F1: Home Team | G1: Model Line (Home) | H1: Market Line (Home) | I1: Spread Edge (pts) | J1: Ridge Line (Home) | K1: Massey Line (Home) | L1: Model Total | M1: Market Total | N1: Total Edge (pts) | O1: Away Pts | P1: Home Pts | Q1: Model Result
A2: 5 | B2: 2026-10-02 | C2: ACC | D2: ACC | E2: Pittsburgh | F2: Virginia Tech | G2: 4.1 | H2: -2.5 | I2: -6.6 | J2: -1.3 | K2: 1 | L2: 51.2 | M2: 54.5 | N2: -3.3 | O2: 35 | P2: 33 | Q2: Win
A3: 5 | B3: 2026-10-03 | C3: ACC | D3: ACC | E3: Miami | F3: Clemson | G3: 17.6 | H3: 16.5 | I3: -1.1 | J3: 8.2 | K3: 17.3 | L3: 47.3 | M3: 47.5 | N3: -0.2
A4: 5 | B4: 2026-10-03 | C4: ACC | D4: ACC | E4: Virginia | F4: Florida State | G4: 8.3 | H4: 2.5 | I4: -5.8 | J4: -0.7 | K4: 7.4 | L4: 51.6 | M4: 51.5 | N4: 0.1
A5: 5 | B5: 2026-10-03 | C5: ACC | D5: ACC | E5: Louisville | F5: NC State | G5: 2.5 | H5: 3.5 | I5: 1 | J5: 1.4 | K5: -6.3 | L5: 57.3 | M5: 58.2 | N5: -1
A6: 5 | B6: 2026-10-03 | C6: ACC | D6: FBS Independents | E6: Notre Dame | F6: North Carolina | G6: 19.5 | H6: 21.5 | I6: 2 | J6: 11.2 | K6: 12.6 | L6: 48.4 | M6: 46.5 | N6: 1.9 | O6: 37 | P6: 26 | Q6: Win
A7: 5 | B7: 2026-10-03 | C7: ACC | D7: ACC | E7: Boston College | F7: SMU | G7: -21.8 | H7: -21.5 | I7: 0.3 | J7: -19.4 | K7: -12 | L7: 48.3 | M7: 55.5 | N7: -7.2 | O7: 16 | P7: 25 | Q7: Win
A8: 5 | B8: 2026-10-03 | C8: ACC | D8: ACC | E8: Stanford | F8: Wake Forest | G8: -25.8 | H8: -14 | I8: 11.8 | J8: -7.7 | K8: -15.2 | L8: 56.1 | M8: 53.5 | N8: 2.6 | O8: 3 | P8: 57 | Q8: Win
A9: 5 | B9: 2026-10-02 | C9: American Athletic | D9: American Athletic | E9: North Texas | F9: Tulsa | G9: 4.9 | H9: 2 | I9: -2.9 | J9: 4.5 | K9: -4.5 | L9: 56.4 | M9: 56.8 | N9: -0.3 | O9: 45 | P9: 44 | Q9: Win
A10: 5 | B10: 2026-10-03 | C10: American Athletic | D10: American Athletic | E10: Memphis | F10: Charlotte | G10: 23.9 | H10: 20.5 | I10: -3.4 | J10: 17.5 | K10: 8.6 | L10: 54.4 | M10: 52.2 | N10: 2.2 | O10: 59 | P10: 8 | Q10: Win
A11: 5 | B11: 2026-10-03 | C11: American Athletic | D11: SWAC | E11: Texas Southern | F11: Florida Atlantic | G11: -31.2 | H11: -44.2 | I11: -13.1 | J11: -18.2 | K11: -21.1 | L11: 56.5 | M11: 61.2 | N11: -4.8
A12: 5 | B12: 2026-10-03 | C12: American Athletic | D12: American Athletic | E12: UTSA | F12: Rice | G12: 13.4 | H12: 12.5 | I12: -0.9 | J12: 10.3 | K12: 8.4 | L12: 55.1 | M12: 55.8 | N12: -0.7
A13: 5 | B13: 2026-10-03 | C13: American Athletic | D13: American Athletic | E13: Temple | F13: South Florida | G13: -13.2 | H13: -6 | I13: 7.2 | J13: -14.2 | K13: -8.8 | L13: 58.3 | M13: 48.5 | N13: 9.8
A14: 5 | B14: 2026-10-03 | C14: American Athletic | D14: Southern | E14: Samford | F14: UAB | G14: -32.3 | H14: -30.5 | I14: 1.8 | J14: -19.3 | K14: -2 | L14: 57.5 | M14: 52.8 | N14: 4.7
A15: 5 | B15: 2026-10-03 | C15: Big 12 | D15: Big 12 | E15: Texas Tech | F15: Colorado | G15: 18.1 | H15: 13.5 | I15: -4.6 | J15: 18.9 | K15: 9.2 | L15: 49 | M15: 50.5 | N15: -1.5
A16: 5 | B16: 2026-10-03 | C16: Big 12 | D16: Big 12 | E16: UCF | F16: Houston | G16: -12.8 | H16: -11.2 | I16: 1.5 | J16: -12 | K16: -4 | L16: 53.9 | M16: 50.8 | N16: 3.1 | O16: 17 | P16: 27 | Q16: Win
A17: 5 | B17: 2026-10-03 | C17: Big 12 | D17: Big 12 | E17: West Virginia | F17: Iowa State | G17: -13.4 | H17: -3 | I17: 10.4 | J17: -5.6 | K17: -6.3 | L17: 49 | M17: 53.2 | N17: -4.2 | O17: 42 | P17: 45 | Q17: Win
A18: 5 | B18: 2026-10-03 | C18: Big 12 | D18: Conference USA | E18: Middle Tennessee | F18: Kansas | G18: -29.9 | H18: -19.8 | I18: 10.2 | J18: -19.6 | K18: -7.1 | L18: 54.2 | M18: 50.5 | N18: 3.7 | O18: 0 | P18: 55 | Q18: Win
A19: 5 | B19: 2026-10-03 | C19: Big 12 | D19: Big 12 | E19: BYU | F19: TCU | G19: 2.4 | H19: 6.2 | I19: 3.9 | J19: 8.8 | K19: 0 | L19: 52.4 | M19: 47.8 | N19: 4.6
A20: 5 | B20: 2026-10-04 | C20: Big 12 | D20: Big 12 | E20: Cincinnati | F20: Arizona | G20: -5.9 | H20: -6.5 | I20: -0.6 | J20: -11 | K20: -2 | L20: 55.7 | M20: 55.5 | N20: 0.2
A21: 5 | B21: 2026-10-04 | C21: Big 12 | D21: Big 12 | E21: Baylor | F21: Arizona State | G21: -2.3 | H21: -3.8 | I21: -1.5 | J21: -4 | K21: -0.9 | L21: 46.8 | M21: 49.2 | N21: -2.5
A22: 5 | B22: 2026-10-03 | C22: Big Ten | D22: Big Ten | E22: Purdue | F22: Illinois | G22: -19.2 | H22: -10 | I22: 9.2 | J22: -16.6 | K22: -10.9 | L22: 60.4 | M22: 62.5 | N22: -2.1
A23: 5 | B23: 2026-10-03 | C23: Big Ten | D23: Big Ten | E23: Ohio State | F23: Iowa | G23: 8.6 | H23: 14.2 | I23: 5.6 | J23: 7.1 | K23: 2.6 | L23: 45.9 | M23: 45.5 | N23: 0.4
A24: 5 | B24: 2026-10-03 | C24: Big Ten | D24: Big Ten | E24: Michigan | F24: Minnesota | G24: -1.8 | H24: 5.8 | I24: 7.5 | J24: 5 | K24: -6.4 | L24: 43.9 | M24: 43.5 | N24: 0.4 | O24: 14 | P24: 20 | Q24: Win
A25: 5 | B25: 2026-10-03 | C25: Big Ten | D25: Big Ten | E25: Maryland | F25: Nebraska | G25: -19.1 | H25: -14.5 | I25: 4.6 | J25: -13 | K25: -14.9 | L25: 52.2 | M25: 52.5 | N25: -0.3
A26: 5 | B26: 2026-10-03 | C26: Big Ten | D26: Big Ten | E26: Penn State | F26: Northwestern | G26: -1.4 | H26: 2.5 | I26: 3.9 | J26: 0.7 | K26: 0.3 | L26: 49.9 | M26: 45.8 | N26: 4.2 | O26: 13 | P26: 34 | Q26: Win
A27: 5 | B27: 2026-10-03 | C27: Big Ten | D27: Big Ten | E27: Washington | F27: USC | G27: -4.6 | H27: -8.8 | I27: -4.1 | J27: -5.4 | K27: -11.6 | L27: 51.5 | M27: 58.2 | N27: -6.8
A28: 5 | B28: 2026-10-03 | C28: Big Ten | D28: Big Ten | E28: Michigan State | F28: Wisconsin | G28: -10.2 | H28: -9.5 | I28: 0.7 | J28: -9.5 | K28: -9.4 | L28: 44.8 | M28: 43.2 | N28: 1.6 | O28: 3 | P28: 31 | Q28: Win
A29: 5 | B29: 2026-10-04 | C29: Big Ten | D29: Big Ten | E29: Indiana | F29: Rutgers | G29: 26.2 | H29: 24.5 | I29: -1.7 | J29: 18.8 | K29: 11.1 | L29: 53.8 | M29: 56.8 | N29: -2.9
A30: 5 | B30: 2026-10-02 | C30: Conference USA | D30: Conference USA | E30: Liberty | F30: Delaware | G30: 1.8 | H30: 6.8 | I30: 5 | J30: -0.4 | K30: 4.3 | L30: 51 | M30: 49.8 | N30: 1.2 | O30: 30 | P30: 14 | Q30: Win
A31: 5 | B31: 2026-10-02 | C31: Conference USA | D31: Conference USA | E31: Western Kentucky | F31: New Mexico State | G31: -2 | H31: -1.5 | I31: 0.5 | J31: 9.7 | K31: -8 | L31: 55.5 | M31: 55.8 | N31: -0.2 | O31: 13 | P31: 34 | Q31: Win
A32: 5 | B32: 2026-10-03 | C32: FBS Independents | D32: ACC | E32: Syracuse | F32: UConn | G32: -1.6 | H32: 7 | I32: 8.6 | J32: -9.8 | K32: -1.9 | L32: 48 | M32: 50.5 | N32: -2.5 | O32: 42 | P32: 41 | Q32: Loss
A33: 5 | B33: 2026-10-03 | C33: Mid-American | D33: Mid-American | E33: Toledo | F33: Ball State | G33: 21.2 | H33: 20.5 | I33: -0.7 | J33: 12 | K33: 15.6 | L33: 52.4 | M33: 52.5 | N33: -0.1
A34: 5 | B34: 2026-10-03 | C34: Mid-American | D34: Mid-American | E34: Western Michigan | F34: Buffalo | G34: 9.9 | H34: 13.8 | I34: 3.9 | J34: 10.2 | K34: 7.3 | L34: 45.4 | M34: 46.2 | N34: -0.9 | O34: 20 | P34: 17 | Q34: Win
A35: 5 | B35: 2026-10-03 | C35: Mid-American | D35: Mid-American | E35: Akron | F35: Central Michigan | G35: -9.8 | H35: -6.5 | I35: 3.3 | J35: -6.3 | K35: -6.4 | L35: 47 | M35: 47.2 | N35: -0.2
A36: 5 | B36: 2026-10-03 | C36: Mid-American | D36: Mid-American | E36: Ohio | F36: Kent State | G36: 9.1 | H36: 3.5 | I36: -5.6 | J36: 11 | K36: 9.4 | L36: 53.3 | M36: 50.8 | N36: 2.6
A37: 5 | B37: 2026-10-03 | C37: Mid-American | D37: Mid-American | E37: Eastern Michigan | F37: Massachusetts | G37: -2.9 | H37: -5.8 | I37: -2.8 | J37: 1.3 | K37: -24.6 | L37: 48.4 | M37: 48.8 | N37: -0.4
A38: 5 | B38: 2026-10-03 | C38: Mid-American | D38: Mid-American | E38: Bowling Green | F38: Miami (OH) | G38: -20.1 | H38: -13.5 | I38: 6.6 | J38: -13.7 | K38: -19.9 | L38: 48.6 | M38: 43.5 | N38: 5.1
A39: 5 | B39: 2026-10-03 | C39: Mountain West | D39: American Athletic | E39: Navy | F39: Air Force | G39: 3.2 | H39: -3.2 | I39: -6.4 | J39: -8.6 | K39: -7.7 | L39: 54.9 | M39: 45.5 | N39: 9.4 | O39: 9 | P39: 14 | Q39: Loss
A40: 5 | B40: 2026-10-03 | C40: Mountain West | D40: Mountain West | E40: UTEP | F40: New Mexico | G40: -31.8 | H40: -22.5 | I40: 9.3 | J40: -22.1 | K40: -28.2 | L40: 43.7 | M40: 47.8 | N40: -4.1
...

Sheet ACC Slate
A1: ACC Standings
A2: Team | B2: Conf W | C2: Conf L | D2: Conf Pct | E2: Overall W | F2: Overall L
A3: Miami | B3: 2 | C3: 0 | D3: 1 | E3: 4 | F3: 0
A4: Pittsburgh | B4: 2 | C4: 0 | D4: 1 | E4: 5 | F4: 0
A5: Clemson | B5: 2 | C5: 0 | D5: 1 | E5: 3 | F5: 1
A6: Duke | B6: 1 | C6: 0 | D6: 1 | E6: 4 | F6: 0
A7: Virginia | B7: 1 | C7: 0 | D7: 1 | E7: 3 | F7: 1
A8: SMU | B8: 2 | C8: 1 | D8: 0.667 | E8: 4 | F8: 1
A9: Wake Forest | B9: 2 | C9: 1 | D9: 0.667 | E9: 4 | F9: 1
A10: Virginia Tech | B10: 1 | C10: 1 | D10: 0.5 | E10: 4 | F10: 1
A11: California | B11: 1 | C11: 1 | D11: 0.5 | E11: 2 | F11: 2
A12: Louisville | B12: 1 | C12: 1 | D12: 0.5 | E12: 2 | F12: 2
A13: Stanford | B13: 1 | C13: 3 | D13: 0.25 | E13: 2 | F13: 3
A14: Florida State | B14: 0 | C14: 1 | D14: 0 | E14: 2 | F14: 2
... A19: Georgia Tech | B19: 0 | C19: 1 | D19: 0 | E19: 1 | F19: 3
A21: Week | B21: Date | C21: Home Conf | D21: Away Conf | E21: Away Team | F21: Home Team | G21: Model Line (Home) | H21: Market Line (Home) | I21: Spread Edge (pts) | J21: Ridge Line (Home) | K21: Massey Line (Home) | L21: Model Total | M21: Market Total | N21: Total Edge (pts) | O21: Away Pts | P21: Home Pts | Q21: Model Result
A22: 5 | B22: 2026-10-02 | C22: ACC | D22: ACC | E22: Pittsburgh | F22: Virginia Tech | G22: 4.1 | H22: -2.5 | I22: -6.6 | J22: -1.3 | K22: 1 | L22: 51.2 | M22: 54.5 | N22: -3.3 | O22: 35 | P22: 33 | Q22: Win
A23: 5 | B23: 2026-10-03 | C23: ACC | D23: ACC | E23: Miami | F23: Clemson | G23: 17.6 | H23: 16.5 | I23: -1.1 | J23: 8.2 | K23: 17.3 | L23: 47.3 | M23: 47.5 | N23: -0.2
A24: 5 | B24: 2026-10-03 | C24: ACC | D24: ACC | E24: Virginia | F24: Florida State | G24: 8.3 | H24: 2.5 | I24: -5.8 | J24: -0.7 | K24: 7.4 | L24: 51.6 | M24: 51.5 | N24: 0.1
A25: 5 | B25: 2026-10-03 | C25: ACC | D25: ACC | E25: Louisville | F25: NC State | G25: 2.5 | H25: 3.5 | I25: 1 | J25: 1.4 | K25: -6.3 | L25: 57.3 | M25: 58.2 | N25: -1
A26: 5 | B26: 2026-10-03 | C26: ACC | D26: FBS Independents | E26: Notre Dame | F26: North Carolina | G26: 19.5 | H26: 21.5 | I26: 2 | J26: 11.2 | K26: 12.6 | L26: 48.4 | M26: 46.5 | N26: 1.9 | O26: 37 | P26: 26 | Q26: Win
A27: 5 | B27: 2026-10-03 | C27: ACC | D27: ACC | E27: Boston College | F27: SMU | G27: -21.8 | H27: -21.5 | I27: 0.3 | J27: -19.4 | K27: -12 | L27: 48.3 | M27: 55.5 | N27: -7.2 | O27: 16 | P27: 25 | Q27: Win
A28: 5 | B28: 2026-10-03 | C28: ACC | D28: ACC | E28: Stanford | F28: Wake Forest | G28: -25.8 | H28: -14 | I28: 11.8 | J28: -7.7 | K28: -15.2 | L28: 56.1 | M28: 53.5 | N28: 2.6 | O28: 3 | P28: 57 | Q28: Win
A29: 5 | B29: 2026-10-03 | C29: FBS Independents | D29: ACC | E29: Syracuse | F29: UConn | G29: -1.6 | H29: 7 | I29: 8.6 | J29: -9.8 | K29: -1.9 | L29: 48 | M29: 50.5 | N29: -2.5 | O29: 42 | P29: 41 | Q29: Loss
A30: 5 | B30: 2026-10-03 | C30: Mountain West | D30: ACC | E30: California | F30: UNLV | G30: -5.3 | H30: -2.8 | I30: 2.6 | J30: -15.5 | K30: -3.1 | L30: 45.5 | M30: 53.5 | N30: -8

Sheet American Athletic Slate
A1: American Athletic Standings
A2: Team | B2: Conf W | C2: Conf L | D2: Conf Pct | E2: Overall W | F2: Overall L
A3: South Florida | B3: 1 | C3: 0 | D3: 1 | E3: 4 | F3: 0
A4: Memphis | B4: 1 | C4: 0 | D4: 1 | E4: 4 | F4: 1
A5: Florida Atlantic | B5: 1 | C5: 0 | D5: 1 | E5: 3 | F5: 1
A6: North Texas | B6: 1 | C6: 0 | D6: 1 | E6: 3 | F6: 2
A7: UAB | B7: 1 | C7: 0 | D7: 1 | E7: 2 | F7: 2
A8: Army | B8: 1 | C8: 1 | D8: 0.5 | E8: 2 | F8: 1
A9: UTSA | B9: 0 | C9: 0 | E9: 3 | F9: 1
A10: Tulsa | B10: 0 | C10: 1 | D10: 0 | E10: 3 | F10: 2
A11: East Carolina | B11: 0 | C11: 0 | E11: 2 | F11: 2
A12: Tulane | B12: 0 | C12: 0 | E12: 2 | F12: 2
A13: Navy | B13: 0 | C13: 2 | D13: 0 | E13: 1 | F13: 3
A14: Rice | B14: 0 | C14: 0 | E14: 1 | F14: 3
A15: Temple | B15: 0 | C15: 1 | D15: 0 | E15: 1 | F15: 3
A16: Charlotte | B16: 0 | C16: 1 | D16: 0 | E16: 0 | F16: 5
A18: Week | B18: Date | C18: Home Conf | D18: Away Conf | E18: Away Team | F18: Home Team | G18: Model Line (Home) | H18: Market Line (Home) | I18: Spread Edge (pts) | J18: Ridge Line (Home) | K18: Massey Line (Home) | L18: Model Total | M18: Market Total | N18: Total Edge (pts) | O18: Away Pts | P18: Home Pts | Q18: Model Result
A19: 5 | B19: 2026-10-02 | C19: American Athletic | D19: American Athletic | E19: North Texas | F19: Tulsa | G19: 4.9 | H19: 2 | I19: -2.9 | J19: 4.5 | K19: -4.5 | L19: 56.4 | M19: 56.8 | N19: -0.3 | O19: 45 | P19: 44 | Q19: Win
A20: 5 | B20: 2026-10-03 | C20: American Athletic | D20: American Athletic | E20: Memphis | F20: Charlotte | G20: 23.9 | H20: 20.5 | I20: -3.4 | J20: 17.5 | K20: 8.6 | L20: 54.4 | M20: 52.2 | N20: 2.2 | O20: 59 | P20: 8 | Q20: Win
A21: 5 | B21: 2026-10-03 | C21: American Athletic | D21: SWAC | E21: Texas Southern | F21: Florida Atlantic | G21: -31.2 | H21: -44.2 | I21: -13.1 | J21: -18.2 | K21: -21.1 | L21: 56.5 | M21: 61.2 | N21: -4.8
A22: 5 | B22: 2026-10-03 | C22: American Athletic | D22: American Athletic | E22: UTSA | F22: Rice | G22: 13.4 | H22: 12.5 | I22: -0.9 | J22: 10.3 | K22: 8.4 | L22: 55.1 | M22: 55.8 | N22: -0.7
A23: 5 | B23: 2026-10-03 | C23: American Athletic | D23: American Athletic | E23: Temple | F23: South Florida | G23: -13.2 | H23: -6 | I23: 7.2 | J23: -14.2 | K23: -8.8 | L23: 58.3 | M23: 48.5 | N23: 9.8
A24: 5 | B24: 2026-10-03 | C24: American Athletic | D24: Southern | E24: Samford | F24: UAB | G24: -32.3 | H24: -30.5 | I24: 1.8 | J24: -19.3 | K24: -2 | L24: 57.5 | M24: 52.8 | N24: 4.7
A25: 5 | B25: 2026-10-03 | C25: Mountain West | D25: American Athletic | E25: Navy | F25: Air Force | G25: 3.2 | H25: -3.2 | I25: -6.4 | J25: -8.6 | K25: -7.7 | L25: 54.9 | M25: 45.5 | N25: 9.4 | O25: 9 | P25: 14 | Q25: Loss
A26: 5 | B26: 2026-10-03 | C26: Sun Belt | D26: American Athletic | E26: Army | F26: Louisiana Tech | G26: 3.5 | H26: 1.5 | I26: -2 | J26: -8.1 | K26: -1.8 | L26: 53.3 | M26: 47.5 | N26: 5.8

Sheet Big 12 Slate
A1: Big 12 Standings
A2: Team | B2: Conf W | C2: Conf L | D2: Conf Pct | E2: Overall W | F2: Overall L
A3: BYU | B3: 1 | C3: 0 | D3: 1 | E3: 3 | F3: 0
A4: Cincinnati | B4: 1 | C4: 0 | D4: 1 | E4: 4 | F4: 0
A5: Texas Tech | B5: 1 | C5: 0 | D5: 1 | E5: 4 | F5: 0
A6: Utah | B6: 1 | C6: 0 | D6: 1 | E6: 4 | F6: 0
A7: Baylor | B7: 1 | C7: 0 | D7: 1 | E7: 3 | F7: 1
A8: Oklahoma State | B8: 1 | C8: 0 | D8: 1 | E8: 3 | F8: 1
A9: Arizona State | B9: 1 | C9: 0 | D9: 1 | E9: 2 | F9: 1
A10: Houston | B10: 1 | C10: 1 | D10: 0.5 | E10: 4 | F10: 1
A11: Iowa State | B11: 1 | C11: 1 | D11: 0.5 | E11: 3 | F11: 2
A12: UCF | B12: 1 | C12: 1 | D12: 0.5 | E12: 3 | F12: 2
A13: Arizona | B13: 0 | C13: 1 | D13: 0 | E13: 3 | F13: 1
A14: Kansas State | B14: 0 | C14: 1 | D14: 0 | E14: 3 | F14: 1
... A18: TCU | B18: 0 | C18: 1 | D18: 0 | E18: 2 | F18: 2
A20: Week | B20: Date | C20: Home Conf | D20: Away Conf | E20: Away Team | F20: Home Team | G20: Model Line (Home) | H20: Market Line (Home) | I20: Spread Edge (pts) | J20: Ridge Line (Home) | K20: Massey Line (Home) | L20: Model Total | M20: Market Total | N20: Total Edge (pts) | O20: Away Pts | P20: Home Pts | Q20: Model Result
A21: 5 | B21: 2026-10-03 | C21: Big 12 | D21: Big 12 | E21: Texas Tech | F21: Colorado | G21: 18.1 | H21: 13.5 | I21: -4.6 | J21: 18.9 | K21: 9.2 | L21: 49 | M21: 50.5 | N21: -1.5
A22: 5 | B22: 2026-10-03 | C22: Big 12 | D22: Big 12 | E22: UCF | F22: Houston | G22: -12.8 | H22: -11.2 | I22: 1.5 | J22: -12 | K22: -4 | L22: 53.9 | M22: 50.8 | N22: 3.1 | O22: 17 | P22: 27 | Q22: Win
A23: 5 | B23: 2026-10-03 | C23: Big 12 | D23: Big 12 | E23: West Virginia | F23: Iowa State | G23: -13.4 | H23: -3 | I23: 10.4 | J23: -5.6 | K23: -6.3 | L23: 49 | M23: 53.2 | N23: -4.2 | O23: 42 | P23: 45 | Q23: Win
A24: 5 | B24: 2026-10-03 | C24: Big 12 | D24: Conference USA | E24: Middle Tennessee | F24: Kansas | G24: -29.9 | H24: -19.8 | I24: 10.2 | J24: -19.6 | K24: -7.1 | L24: 54.2 | M24: 50.5 | N24: 3.7 | O24: 0 | P24: 55 | Q24: Win
A25: 5 | B25: 2026-10-03 | C25: Big 12 | D25: Big 12 | E25: BYU | F25: TCU | G25: 2.4 | H25: 6.2 | I25: 3.9 | J25: 8.8 | K25: 0 | L25: 52.4 | M25: 47.8 | N25: 4.6
A26: 5 | B26: 2026-10-04 | C26: Big 12 | D26: Big 12 | E26: Cincinnati | F26: Arizona | G26: -5.9 | H26: -6.5 | I26: -0.6 | J26: -11 | K26: -2 | L26: 55.7 | M26: 55.5 | N26: 0.2
A27: 5 | B27: 2026-10-04 | C27: Big 12 | D27: Big 12 | E27: Baylor | F27: Arizona State | G27: -2.3 | H27: -3.8 | I27: -1.5 | J27: -4 | K27: -0.9 | L27: 46.8 | M27: 49.2 | N27: -2.5

Sheet Big Ten Slate
A1: Big Ten Standings
A2: Team | B2: Conf W | C2: Conf L | D2: Conf Pct | E2: Overall W | F2: Overall L
A3: UCLA | B3: 2 | C3: 0 | D3: 1 | E3: 4 | F3: 0
A4: Minnesota | B4: 2 | C4: 0 | D4: 1 | E4: 4 | F4: 1
A5: Wisconsin | B5: 2 | C5: 0 | D5: 1 | E5: 4 | F5: 1
A6: Indiana | B6: 1 | C6: 0 | D6: 1 | E6: 4 | F6: 0
A7: Iowa | B7: 1 | C7: 0 | D7: 1 | E7: 4 | F7: 0
A8: Nebraska | B8: 1 | C8: 0 | D8: 1 | E8: 4 | F8: 0
A9: Ohio State | B9: 1 | C9: 0 | D9: 1 | E9: 3 | F9: 1
A10: Oregon | B10: 1 | C10: 0 | D10: 1 | E10: 3 | F10: 1
A11: USC | B11: 1 | C11: 1 | D11: 0.5 | E11: 4 | F11: 1
A12: Northwestern | B12: 1 | C12: 1 | D12: 0.5 | E12: 3 | F12: 1
A13: Washington | B13: 0 | C13: 1 | D13: 0 | E13: 3 | F13: 1
A14: Michigan | B14: 0 | C14: 2 | D14: 0 | E14: 3 | F14: 2
... A20: Rutgers | B20: 0 | C20: 1 | D20: 0 | E20: 1 | F20: 3
A22: Week | B22: Date | C22: Home Conf | D22: Away Conf | E22: Away Team | F22: Home Team | G22: Model Line (Home) | H22: Market Line (Home) | I22: Spread Edge (pts) | J22: Ridge Line (Home) | K22: Massey Line (Home) | L22: Model Total | M22: Market Total | N22: Total Edge (pts) | O22: Away Pts | P22: Home Pts | Q22: Model Result
A23: 5 | B23: 2026-10-03 | C23: Big Ten | D23: Big Ten | E23: Purdue | F23: Illinois | G23: -19.2 | H23: -10 | I23: 9.2 | J23: -16.6 | K23: -10.9 | L23: 60.4 | M23: 62.5 | N23: -2.1
A24: 5 | B24: 2026-10-03 | C24: Big Ten | D24: Big Ten | E24: Ohio State | F24: Iowa | G24: 8.6 | H24: 14.2 | I24: 5.6 | J24: 7.1 | K24: 2.6 | L24: 45.9 | M24: 45.5 | N24: 0.4
A25: 5 | B25: 2026-10-03 | C25: Big Ten | D25: Big Ten | E25: Michigan | F25: Minnesota | G25: -1.8 | H25: 5.8 | I25: 7.5 | J25: 5 | K25: -6.4 | L25: 43.9 | M25: 43.5 | N25: 0.4 | O25: 14 | P25: 20 | Q25: Win
A26: 5 | B26: 2026-10-03 | C26: Big Ten | D26: Big Ten | E26: Maryland | F26: Nebraska | G26: -19.1 | H26: -14.5 | I26: 4.6 | J26: -13 | K26: -14.9 | L26: 52.2 | M26: 52.5 | N26: -0.3
A27: 5 | B27: 2026-10-03 | C27: Big Ten | D27: Big Ten | E27: Penn State | F27: Northwestern | G27: -1.4 | H27: 2.5 | I27: 3.9 | J27: 0.7 | K27: 0.3 | L27: 49.9 | M27: 45.8 | N27: 4.2 | O27: 13 | P27: 34 | Q27: Win
A28: 5 | B28: 2026-10-03 | C28: Big Ten | D28: Big Ten | E28: Washington | F28: USC | G28: -4.6 | H28: -8.8 | I28: -4.1 | J28: -5.4 | K28: -11.6 | L28: 51.5 | M28: 58.2 | N28: -6.8
A29: 5 | B29: 2026-10-03 | C29: Big Ten | D29: Big Ten | E29: Michigan State | F29: Wisconsin | G29: -10.2 | H29: -9.5 | I29: 0.7 | J29: -9.5 | K29: -9.4 | L29: 44.8 | M29: 43.2 | N29: 1.6 | O29: 3 | P29: 31 | Q29: Win
A30: 5 | B30: 2026-10-04 | C30: Big Ten | D30: Big Ten | E30: Indiana | F30: Rutgers | G30: 26.2 | H30: 24.5 | I30: -1.7 | J30: 18.8 | K30: 11.1 | L30: 53.8 | M30: 56.8 | N30: -2.9

Sheet Conference USA Slate
A1: Conference USA Standings
A2: Team | B2: Conf W | C2: Conf L | D2: Conf Pct | E2: Overall W | F2: Overall L
A3: Liberty | B3: 1 | C3: 0 | D3: 1 | E3: 4 | F3: 1
A4: Jacksonville State | B4: 1 | C4: 0 | D4: 1 | E4: 3 | F4: 2
A5: New Mexico State | B5: 1 | C5: 0 | D5: 1 | E5: 2 | F5: 3
A6: Florida International | B6: 0 | C6: 0 | E6: 2 | F6: 2
A7: Delaware | B7: 0 | C7: 1 | D7: 0 | E7: 2 | F7: 3
A8: Middle Tennessee | B8: 0 | C8: 1 | D8: 0 | E8: 2 | F8: 3
A9: Kennesaw State | B9: 0 | C9: 0 | E9: 1 | F9: 3
A10: Missouri State | B10: 0 | C10: 0 | E10: 1 | F10: 3
A11: Sam Houston | B11: 0 | C11: 0 | E11: 1 | F11: 3
A12: Western Kentucky | B12: 0 | C12: 1 | D12: 0 | E12: 1 | F12: 4
A14: Week | B14: Date | C14: Home Conf | D14: Away Conf | E14: Away Team | F14: Home Team | G14: Model Line (Home) | H14: Market Line (Home) | I14: Spread Edge (pts) | J14: Ridge Line (Home) | K14: Massey Line (Home) | L14: Model Total | M14: Market Total | N14: Total Edge (pts) | O14: Away Pts | P14: Home Pts | Q14: Model Result
A15: 5 | B15: 2026-10-03 | C15: Big 12 | D15: Conference USA | E15: Middle Tennessee | F15: Kansas | G15: -29.9 | H15: -19.8 | I15: 10.2 | J15: -19.6 | K15: -7.1 | L15: 54.2 | M15: 50.5 | N15: 3.7 | O15: 0 | P15: 55 | Q15: Win
A16: 5 | B16: 2026-10-02 | C16: Conference USA | D16: Conference USA | E16: Liberty | F16: Delaware | G16: 1.8 | H16: 6.8 | I16: 5 | J16: -0.4 | K16: 4.3 | L16: 51 | M16: 49.8 | N16: 1.2 | O16: 30 | P16: 14 | Q16: Win
A17: 5 | B17: 2026-10-02 | C17: Conference USA | D17: Conference USA | E17: Western Kentucky | F17: New Mexico State | G17: -2 | H17: -1.5 | I17: 0.5 | J17: 9.7 | K17: -8 | L17: 55.5 | M17: 55.8 | N17: -0.2 | O17: 13 | P17: 34 | Q17: Win

Sheet FBS Independents Slate
A1: FBS Independents Standings
A2: Team | B2: Conf W | C2: Conf L | D2: Conf Pct | E2: Overall W | F2: Overall L
A3: Notre Dame | B3: 0 | C3: 0 | E3: 5 | F3: 0
A4: UConn | B4: 0 | C4: 0 | E4: 2 | F4: 3
A6: Week | B6: Date | C6: Home Conf | D6: Away Conf | E6: Away Team | F6: Home Team | G6: Model Line (Home) | H6: Market Line (Home) | I6: Spread Edge (pts) | J6: Ridge Line (Home) | K6: Massey Line (Home) | L6: Model Total | M6: Market Total | N6: Total Edge (pts) | O6: Away Pts | P6: Home Pts | Q6: Model Result
A7: 5 | B7: 2026-10-03 | C7: ACC | D7: FBS Independents | E7: Notre Dame | F7: North Carolina | G7: 19.5 | H7: 21.5 | I7: 2 | J7: 11.2 | K7: 12.6 | L7: 48.4 | M7: 46.5 | N7: 1.9 | O7: 37 | P7: 26 | Q7: Win
A8: 5 | B8: 2026-10-03 | C8: FBS Independents | D8: ACC | E8: Syracuse | F8: UConn | G8: -1.6 | H8: 7 | I8: 8.6 | J8: -9.8 | K8: -1.9 | L8: 48 | M8: 50.5 | N8: -2.5 | O8: 42 | P8: 41 | Q8: Loss

Sheet Mid-American Slate
A1: Mid-American Standings
A2: Team | B2: Conf W | C2: Conf L | D2: Conf Pct | E2: Overall W | F2: Overall L
A3: Massachusetts | B3: 1 | C3: 0 | D3: 1 | E3: 4 | F3: 0
A4: Western Michigan | B4: 1 | C4: 0 | D4: 1 | E4: 3 | F4: 2
A5: Kent State | B5: 1 | C5: 0 | D5: 1 | E5: 2 | F5: 2
A6: Eastern Michigan | B6: 1 | C6: 0 | D6: 1 | E6: 2 | F6: 3
A7: Toledo | B7: 0 | C7: 0 | E7: 3 | F7: 1
A8: Central Michigan | B8: 0 | C8: 0 | E8: 2 | F8: 2
A9: Miami (OH) | B9: 0 | C9: 0 | E9: 2 | F9: 2
A10: Ohio | B10: 0 | C10: 0 | E10: 2 | F10: 2
A11: Buffalo | B11: 0 | C11: 1 | D11: 0 | E11: 2 | F11: 3
A12: Akron | B12: 0 | C12: 0 | E12: 1 | F12: 3
A13: Ball State | B13: 0 | C13: 1 | D13: 0 | E13: 1 | F13: 3
A14: Sacramento State | B14: 0 | C14: 2 | D14: 0 | E14: 1 | F14: 4
A15: Bowling Green | B15: 0 | C15: 0 | E15: 0 | F15: 4
A17: Week | B17: Date | C17: Home Conf | D17: Away Conf | E17: Away Team | F17: Home Team | G17: Model Line (Home) | H17: Market Line (Home) | I17: Spread Edge (pts) | J17: Ridge Line (Home) | K17: Massey Line (Home) | L17: Model Total | M17: Market Total | N17: Total Edge (pts) | O17: Away Pts | P17: Home Pts | Q17: Model Result
A18: 5 | B18: 2026-10-03 | C18: Mid-American | D18: Mid-American | E18: Toledo | F18: Ball State | G18: 21.2 | H18: 20.5 | I18: -0.7 | J18: 12 | K18: 15.6 | L18: 52.4 | M18: 52.5 | N18: -0.1
A19: 5 | B19: 2026-10-03 | C19: Mid-American | D19: Mid-American | E19: Western Michigan | F19: Buffalo | G19: 9.9 | H19: 13.8 | I19: 3.9 | J19: 10.2 | K19: 7.3 | L19: 45.4 | M19: 46.2 | N19: -0.9 | O19: 20 | P19: 17 | Q19: Win
A20: 5 | B20: 2026-10-03 | C20: Mid-American | D20: Mid-American | E20: Akron | F20: Central Michigan | G20: -9.8 | H20: -6.5 | I20: 3.3 | J20: -6.3 | K20: -6.4 | L20: 47 | M20: 47.2 | N20: -0.2
A21: 5 | B21: 2026-10-03 | C21: Mid-American | D21: Mid-American | E21: Ohio | F21: Kent State | G21: 9.1 | H21: 3.5 | I21: -5.6 | J21: 11 | K21: 9.4 | L21: 53.3 | M21: 50.8 | N21: 2.6
A22: 5 | B22: 2026-10-03 | C22: Mid-American | D22: Mid-American | E22: Eastern Michigan | F22: Massachusetts | G22: -2.9 | H22: -5.8 | I22: -2.8 | J22: 1.3 | K22: -24.6 | L22: 48.4 | M22: 48.8 | N22: -0.4
A23: 5 | B23: 2026-10-03 | C23: Mid-American | D23: Mid-American | E23: Bowling Green | F23: Miami (OH) | G23: -20.1 | H23: -13.5 | I23: 6.6 | J23: -13.7 | K23: -19.9 | L23: 48.6 | M23: 43.5 | N23: 5.1

Sheet Mountain West Slate
A1: Mountain West Standings
A2: Team | B2: Conf W | C2: Conf L | D2: Conf Pct | E2: Overall W | F2: Overall L
A3: North Dakota State | B3: 1 | C3: 0 | D3: 1 | E3: 4 | F3: 0
A4: UNLV | B4: 1 | C4: 0 | D4: 1 | E4: 2 | F4: 2
A5: Wyoming | B5: 1 | C5: 0 | D5: 1 | E5: 2 | F5: 2
A6: Air Force | B6: 1 | C6: 1 | D6: 0.5 | E6: 3 | F6: 1
A7: New Mexico | B7: 0 | C7: 0 | E7: 3 | F7: 1
A8: San José State | B8: 0 | C8: 0 | E8: 2 | F8: 2
A9: Hawai'i | B9: 0 | C9: 2 | D9: 0 | E9: 1 | F9: 3
A10: Nevada | B10: 0 | C10: 1 | D10: 0 | E10: 1 | F10: 3
A11: UTEP | B11: 0 | C11: 0 | E11: 1 | F11: 3
A12: Northern Illinois | B12: 0 | C12: 0 | E12: 0 | F12: 4
A14: Week | B14: Date | C14: Home Conf | D14: Away Conf | E14: Away Team | F14: Home Team | G14: Model Line (Home) | H14: Market Line (Home) | I14: Spread Edge (pts) | J14: Ridge Line (Home) | K14: Massey Line (Home) | L14: Model Total | M14: Market Total | N14: Total Edge (pts) | O14: Away Pts | P14: Home Pts | Q14: Model Result
A15: 5 | B15: 2026-10-03 | C15: Mountain West | D15: American Athletic | E15: Navy | F15: Air Force | G15: 3.2 | H15: -3.2 | I15: -6.4 | J15: -8.6 | K15: -7.7 | L15: 54.9 | M15: 45.5 | N15: 9.4 | O15: 9 | P15: 14 | Q15: Loss
A16: 5 | B16: 2026-10-03 | C16: Mountain West | D16: Mountain West | E16: UTEP | F16: New Mexico | G16: -31.8 | H16: -22.5 | I16: 9.3 | J16: -22.1 | K16: -28.2 | L16: 43.7 | M16: 47.8 | N16: -4.1
A17: 5 | B17: 2026-10-03 | C17: Mountain West | D17: Mountain West | E17: Wyoming | F17: North Dakota State | G17: -30.3 | H17: -17.2 | I17: 13.1 | J17: -22 | K17: -20.8 | L17: 46.8 | M17: 44.5 | N17: 2.3
